Workbook

Sheet CB_DATA_
A1: Crystal Ball Data
A3: Workbook Variables | B3: Last Var Column | C3: 0
A4: Name:
A5: Value:
A7: Worksheet Data | B7: Last Data Column Used
B8: 3
A10: Sheet Ref
A11: =cb_data_!#ref! | B11: ='input sheet'!#ref! | C11: ='valuation output'!#ref!
A13: Sheet Guid
A14: 271d6a2b-7a93-4e27-808c-aa1aada6a76d | B14: eb12ad88-c3be-4256-b53f-793e1373a468 | C14: faa3ee01-9bfb-4333-b742-7cca748c6e20
A16: Deleted sheet count
A19: Last row used
A20: 28 | B20: 31 | C20: 31
A25: Data blocks
A26: CB_Block_0 | B26: CB_Block_7.0.0.0:1 | C26: CB_Block_7.0.0.0:1
A27: 㜸〱敤㕣㕢㙣ㅣ㔷ㄹ摥㌳摥㕤敦慣敤搸㡤搳㑢㑡㘹㑤㑢㈹搴挱㡤搳㠶㔲㈰〴㕦㥡挴挵㠹摤搸㐹㡢〰㙤挶扢㘷攲㘹㜶㘶摣㤹㔹㈷㉥㤵㕡㐱换㐵㕣㔵㉥愲㔰㉥慡㄰ㄲ㉦㕣㕥㠰㐲ㅦ㐰㈰㠱㔰㤱㜸㠰〷㈴ㅥち㐲昰〰㐲㤱㜸〱〹〹扥敦捣捣敥捣慥㜷散㙥㕢㜰㤱㑦扡扦捦㥣摢㥣㜳晥敢昹晦㌳捤㠹㕣㉥昷㙦㈴晥㘵捡㌳㜳摤搲㠶ㅦ㐸㝢㘲挶慤搷㘵㌵戰㕣挷㥦㤸昲㍣㘳㘳摥昲㠳㍥㌴㈸㔶㉣搴晢㠵㡡㙦㍤㈴㑢㤵㜵改昹㘸㔴挸攵㑡㈵㕤㐳㍤〷攱㙦㈴㝥搰搹㙢㌰て戰㍣㌳扤戰昲〰㐶㕤ち㕣㑦ㅥㄸ㍢ㅢ昶㍤㌲㌹㌹㌱㌹㜱挷㥤㤳㙦㥡㌸㜸㘰㙣愶㔱てㅡ㥥㍣攲挸㐶攰ㄹ昵〳㘳㡢㡤㤵扡㔵㝤愷摣㔸㜶㉦㐸攷㠸㕣㌹㜸晢㡡㜱挷㥢㈷敦㌸㝣搸扣敢慥㌷て攲搵戹㔳㌳搳㡢㥥㌴晤㤷㘸捣〲愷㝣挷慣慣㕡㕣㥢㤴㥥攵㥣㥦㤸㤹挶㝦㠹昹攳改捥㠹愵㔵㈹〳扥㕡㝡搲愹㑡㕦㐷挷〱㝢捡昷ㅢ昶ㅡ㌷㑦户㡦㘱愹㔵挳てち昶㡣慣搷㜵㍢ㅥ戵㘴㉦㘰敦敡挶挶愰扤㈴ㅤ摦ち慣㜵㉢搸㈸摡换ㄸ愸㌶㘴㥦昱攵㘹挳㌹㉦㑦ㄹ戶㉣搸挷ㅢ㔶㉤ㅦ愶㕣摦㉤昱㄰挹㠹愹攵㑦㑣昹昶捣慡攱愹ㄹ昹摣㤸㡣戶挷扣㙡扡敤㑤摤挷攵搴搵ㅢ㌸收捤摤摢愱收慣攱㌵㕢㡥㜷㙦ㄹ㉤㍥㍤㠳摢扡户㑦散㔱扡捦ㅢ扡昷㔱㕢㤹㙥㉤〶㈲晡㔶㍢㡡挵攸㐵㠲㝥㠲ㄲ〱ㄱ愸㤷〹〶〸〶〱㐴晥敦攰㤲㘴㐷㔶㘹ㄵ㐳慢慣㘸㤵慡㔶愹㘹ㄵ愹㔵㑣慤㜲㕥慢慣㙡ㄵ㑢慢㍣愰㔵㉥愰㑤㥣㑡晤晤㕡㤴搶晥昹㤳㘷摥昷散晤挷㍦昵挸㙤㍦扡攲捦㜳㙢㠳㝢搰攸摥㘸㔲戳㥥㜱ㄱ愴搶愲攲㐳ㄳ〷昹㙦㙢慥〰㔳㤸㠷捤㍢捤挹挹摡攱㠳挶敤㐶㠱换捡㐰㝥㡡㔰㐶搰㜶搰扣捦㜲㙡敥㐵㠵扢敢愶つ㕦戶㌶㙥㍣慡㥢㜶ㅢ㑥捤㝦搵收㤵㑢㠱ㄱ挸㙢摢敢㕡㠳㜴㜴㕢〲㕢㐹㕦扤敦晡昶㙥㘷㡤㝡㐳㑥㕤戲挲敡㔷户㔵摢㡢㥥扢搲扤昶㤸㈷ㅦ㙣搶㜶捣㘸ち㐲㙤㕤㡤摤戱捡戰㉡㥣搷搸捣慡敢㑢㐷㑤㙦摣㕥戴慡ㄷ愴户㈴㈹ㄲ㘵㑤㉤昵㑡㔶㐵㕣㍦扥攰㘰愱攰搶摡㡤挹㔲昳敥㑢〱㤸㔹搶㌰摦㌵改〵ㅢ换挶㑡㕤㕥㤵㙡ㄲ扥ㄳㄵ晢㔳挵挷摣㙡挳㥦㜱㥤挰㜳敢改㥡愹摡扡〱㐹㔳㍢改搶㘴㍥㥦㔳㐲〱〲户慦㑦㠸摣慤摤㜹㐱㈱㈲㠱㘲㌲昲㌵㘹戲㥢㌸㡤搵㘱ㄵ㜵㐹㥡搴㕥扢挵㘰㥣慦㤲㌱ㄹㅣ㤸㔸ㄳ昵〷㕦晡晡㉤㠶㙤㘲敥攵㙤慣㘹愳搱敡敦㕥㤷㑥㜰挲㜰㙡㜵改㘵㙡㍦挱ㄹ改挳〰㠵换㄰〸㕤㜷㡦慡㑥㕣ㄲㅢ㠵㡢㔶㉤㔸㉤慥㑡敢晣㙡㠰㌲㘸挸㔲㠹㕢摢㤱昴㉢㔰愴敦㈵ㄸ〵㈸㤷㜳挵㝤㙣㔴㉣㈳攵ち㤴㑥ㄹ扣㥣ㄲ攴散㤷攲攵㐱昳㤸㔵て㘴㈸㤴㠷㑤㘰㈴搴㙡ち㝤㐳㈴㔱捦愸㠶ち㘳㥦㌹〳㉡㌵㉣㈷搸㘸昱㙤〷㤷㠴㐴戴㉢ぢ㜶㥣㉣愰㈸㐸换㠳っ㕥〳搱戴㐹㠳散挶〹㈲㈲ㅢ㘴㘸㜶㡣㥣㈶㌲戶捦㤰ㄱ㘸㥦㈴㐲戶㍥搸㕤㐶㤰搸㍢㠹㤴㥤扡昲攳慥㌴摢捣㤶て愵搹㤵搸㌸晤㉡㠲慢〹慥㈱搸て㈰晥〴〹㐷㈹㠷㝣㍡改慦挲戳㝥ㅤ挱慢〱㈰㥦㜴捡㥣㐸㔴搱㠶摡㡥ㅤ挹㜶㐳戰㤳㤵㔱ㅣ㡡㈲㕡挶㑤㍢㜳挸㔶㠸㡥慣捥㥤愱㙢昳㑡挷扥慥㍢㙤㈶㤷㐳㡡捣㘸㥡㕣敢ㄶ㑤㤳ㅢ挱愶㍤敡慤ㅢ搰㔵ㅦ㈳㜸つ㐰㔹扦㤱㄰捡㠵〶敦昶㉣㝡㥡㤴慦〸戳㈸㌴㠶㝡㔴昰ㄱ㈱昳〸㤰㈱攴㍡㡥㉦扢㌶㌴捤挱㜱昳ㄵ㙦㐳ㅦ攸捥摦ㄱ搲摢昴收慥摥愱扦攸〵㕡搱㌷㠱扤挴敦扡敡㤸㥢㔱慤扦㡥攰ㄶ㠰㌶ㅤ挳搳昷ぢ昵ㄴ㈸戳搸㑥㘰㙥㉦扤㉥捡捡㕤摥㔸㤳㑡〳つ㥡换㠶㜷㕥〶昰㘰捣捤挲ㄶ㜶㍤㑦搶㜱愸慤愹〲㥥㕦慥㑥ㄷ晡挷㍣搷㘶昹慥㡤散扦㈲ㄴ㐳㍥慦昵攵摡㙣攴っ㕢㌳攱㜳㑡㔰づ㜵昰敤摤㠵㐴愲㔳㥡扣搸㉦晢㝣戹㉢㐹㝡㤰㈴㙦挰戶敡户〲㐰㑡㠸摦㜴㤵㈸〷搸散㡤慡㔹摡㘲愵㠷㉦攳㜴搲收㐳散㤰㈳〳愱挳㜶ㅡ晥〳㝦挸㕥戲散愶戰ㄸ戰ㄷ愵㔷㠵㙦挱慡换㜲攸㤶愵愸搹㤵ㄵ慦㄰㔹搱搷搷㜱㥥捥昰慦㈹㍡㘹㤳ㄲ㤹摣㥥㔹㤹㜱ㄶ㙦ㄱㄵ摤㤰ㄴ㉡ㄹ慥愱愶〴㈲攵戱敤慥㠸改㐱挴摣㠶㡤搳てㄲ㑣ㄲㅣ〲㈸晣ㄲ㤲㘶扢ㅢ捦㜰㔸晦㍡㕤摡㤵㑡慥㐴㌴㈸ㄷ攱㜳㕤㠵搵㘱扥收㑤〴㜷〲戴㤹㍦㜴㐰㘶㄰愲㐲㜹㠲㄰㔵ㄸ挳㍣㙢挹㡢愴㠱㍤㈶〲㑢㌳つ㍦㜰㙤㐶㤶㠶捣㔹昷㤴ㅢ捣㕡晥ㅡ㈲㔱愳㘶㤴戹㙦㔵㍡愰㉥て戶㑦㕢㤹扢戶㈶㙢扡戹攴㌶㈰摡收㘶㜷挲挱ㅣ摢〱㕢㔲㥤捤㌵㠱搴摢昹ㄸ㐳〸散戴昲户搲ㅢ扢㉤敦㌷て㝤挳慤ㅤ㕤戶㠲扡ㅣ㌰㐳愶㘳扥㘴㘲ㄷㄱ㌹愸昵㥢换慢㥥㤴戳㐳收㜱捦慡搵㉤㐷ㄲㄹ戰㌱ㄹ慣㥢㤷攷ㄱ㈵㔸㜴ㄹ〳㜴㥤㈱㜳搹㌳ㅣ㝦捤㘰㐰㜱㘳㙦敡㐹㠵㐵ち收戴攵昸㜸㡤挲㈲昳挳收搲慡㝢ㄱㄱ摢㠶敤ㅣ㌷搶晣ㅤ㠱ㄵㄲ㝤㤸ㄴ㙡㠴㈶㌴㑤㤴戴㔲慦昸攱㠱㍣㤷㈳敦攵〹ㄴ慥㜲〵晡捣㌳戴㌷敤晡㈸㐶㐳㍢㥤㜳ㅡ㐴昴愸㔹搸㤷㈹㠵挹愹晡㕤散昳ㄶ㠰㝢㡥㥦㤹㙢㐵收㕥㔴捣扡㐰㉦㝦㠶㡣㔷㘴搱っ㠴搰㐷户㈷㈴ㄵ㤶㤱㜲挰㠱挰㌸㥦摡挹慦㙣慡㌶愴扥㍤慤散㌱㐴㤲〶捤㜹㘳㐵搶ㄱ㡦戶㡤㘰㑦昸㐰㌳搶㌶敡㝥㔴㌷攳摡戶㐱搲㈲㔹㉥㔵つ㔲昰㔴㈳㜰㑦㕡㡥㙥〲㈸晡㡢㡡㡣㑢㈸㌲㉥愹愲㐱昳㌴㐳㠳㉡捦戱摣昳㠶㘷〵慢戶㔵㉤昱㠱攱扢ㅤ㐱㤳㘰㜲㑡摥㌸挵㌲㘳慣捤㥡㍦〳㤳捤㥦〰扡㈷㈰㐷戹㜵㐴㍦㈸㔷ㄳ㐵晣ㄳ㍤㍡㤶㈰㘰㤴愷㔴㝦ㅢ㐶㉢愸摢ㄱ㄰㌹㉡㕤㡥敦㘰㕣㝥〴㈵愱㄰㈲搶㌳㐸〴㕥挱㠴㤰愷㡢扢㘸㥥㜱慣〰搸㈳挶㡥㔹挱慣て㤴〳㈰慢㡥户搷㉡慣㈶㍡㡤㌷戵挲つ㥤㔵㈹㌵㜱㝤㘷㝤㔲㙦扣㜶㤳敡㔰愳㈴ㄴ挹㔶㡤㤴㘶搹㘴㡥㍢㐹搵〸愵戸㘳㙤㈳戲摣愶慤㝤愷ㄴ㜹ㄱ㡡㐹搱㑣㑥㝦扢㈲ㄴ〴㝡㈳ㅤ㐵㥦㝤㌶㜹㈴㈲㌶戴〱捡搴㔳㘱搹㔰ㄴㄲ㥣挳戵㤳㥡㉣㐷㑦攰敦㍤㔱㜶愱ㄱ愴㙡㡣㑢愳㔱捤㔴扤扥攰挰㑡愸ㅡ㕥㙤㠷戰㌴搶ㄶ㙡ㄸ挵㥤扤㙡晦㜰㝢ㄳ㡣ㄸ戱㈱挳㈲ㄹ㝥㘰戰㈱㤸㉢ㄱ㔱愵㜵㌶挴慤㙥ㄶ㤷昸㜴㔲ㅡ㡥挲挰㔲㔰㥢㤵敢捡っ㙢㔹昲愳慡㐳昳戴愸攴愸㙥㑥慤昸㔰改〱攵㜸㤴㔳っ慥㥢愷改㤶挲㈵〶㠸摤㈸户㔸つ㄰摡㙤づ挰㤳挱捥挱づ㜶㈴っ㥤搰㍡愳〴㉤㘶㄰㙥㝡ㄱ攴㥤ㅥ㌱ち㐱㙡慡昴户愳攲ぢ㑦㌲㝤攳㘸㉥捥㐴㑣挴㜰㔷㠶昵〰攴㈶㈳㤳攴愲搱㌸㘰ㅥ㑡㌶㈵戴〶攳㌲㥡ㄸ㐳㌴昹扣〰户㜸ㄸ换ㅡ㈶摢搴㜱捦㉤戰愰㑤敢ㅢ㝢捣㌹愷㕡㙦搴愴㔲挵戱慣㔶ㅡ㜹㐷攰㑢㕤〱っ戹㈹㘳㕦愲㑤㤹挳㔱㡡㑢㈶㤲㝡户扢昵愳攸慥㠴ㅣ挶〸㔵ㅦ〳㤰ㄹ㙥㌹ㄵ㄰敢戸愷㐰晢㜰㙦敢〲㠳扡㍣〷㤱搶㔱㐴㔹㌶㡦晢㜸捤㈸戲攲戶㐴戳㜹㜷摥愵捤㥥㈸㍡㘱㠵㐵㍢〲㐷㔸㘷㈸昰㡡㐵ㄸ㈳㍤㜲〷〷挹㕤㡥愲扢㤷ㅦ㔱㡦戹换㐰㠵挲㠰㘰㡣㤷愷愰ㅣ㜶ㄵ㡣㐴㠳㕢㙢㔹摤㠲搱㕦㕡摥晡ㄴ㠰㘰ㄸ㤸〶㉤㕡㠶〶捥っ昲㕢ㅢ㌸㌷愰㔵㐶㠴㌴ㄹ㑣㘵㡣㜲ㄴづ㝢㈰つ摣挴㠳昴戲ぢ㈵ㄴ散㔳ㄷ挳攲扢㠹攳㌶㡥㐰慥㜷㔵㕢攱愲ㄱ攰晡㡢戳扦慤㜸慡㔶愳戹ぢ晦摣㡥挰㉡慥㙥㠴收攸扥戶㑢㔹㙡㑤戴敦㙥㙡慢㠸㉥ぢㅥ㥡㥤㌸㘱〴搵搵愵㘰㈳扣戸搵㉢㐹ㄴ㥥㠵㍦㘲搳户搳㘶捥㍢扣㠸扡捥扤㉦㕦㜰摣㡢㡥㥡㔷挱攷慤㍦㔰〸慥㔰昶㜳㤲攵摣扦昱㑦㈵㉤㔷昸㈱㐶摣捥戴㌹㐰换㐱挲㜱㔴ち愵挱ㄸ昲ㄹ㜴〲摢扤㜹㙢㠰㜴戲慦㡤㑥㤴㈰搸㈵ㄴ攷晣㑢㐶㈸攲〷㐰㉢㠹㈵㍣㤲㘳捦扦づ搶ㄷ捦愰㠴〸挷㜳㈴㐶ち慦㐱㉥〳㜵㑡㤰㐷㔷㍣㜸㈱攴晦〷㑢㌱㌷㙦捡㑥晦〵㘶ㄶ摦㙦㐷搱昵㐴搱昷㍡㔰㈴㜸つ㐴昱敦㍤挸挴愹挰昰散ぢち㠴㜳㑤扢〷搰㤷晤挲敦晦昰〰㍡ㅦㄱ㠷戲搱㄰㙡扢ㄹ捦㑤ㄳ愱慦挳㐴㘰昰㕥㤹〸㈷㤱ㄱ㡣攲㠷㈶㐲攴〳㔹㐰挱搶㈶〲㘳㝢ㄹ㠶㘰㈲搴㥡㜰㙢昰〴㜶㤵㑤晦搸〹㕣扣㤵㍥攲昹㔰㕡晥っ㍣㔲㔷㜷ㄶ㉦ㅡ㥥㘱敦㔷攵挷㍤〹㘵收㉤攳㈶户敡挲ㅥ搷㙥㕡愳㍡㙤攲慢㠸扤散扢晥㤴敤摤㕦〷愶挲ㄴ扡敦㐵㐹ㄴ㕦㠴愷㐴昰摣㤰㝢摦扥㙦ㅥ晦晤㐳㡦ㅤ攵㙤戵㠸㔶ぢ户㈲摦㑢挸㥥昶〴㠲扡㠹㡢㈲㔷昲挳㥣㤳昸㐴挹㕡慢换㘹挳㔳㔶㤰慦摢㜱㌶㈴扣〴㘱㠶挴户ㄳ㑣㑣摣㝢〸㑤捣㠹㌶㜷愷晡戰㐹戹〸㈷ㄲㄳ㔷㍥扤㌸㙣㈸扡㉡戲ㅥ慤捤挲户愱㡡㕥攰㐴搲㔶㈲㑦㥤㑣㐲㝣慢㕤搷ㅤ愶慥ぢて㌲っ晢挷㔲ち昱〷㔲㐸昲㈰挳ぢ〱㑡㑡㥤㐶愶㜰ㅢ㐰㐶㘴慤㍤挴㑢㝦挰慥㄰㤰捤㑢㝦㍤㝥挴㠲㕤〴ㄶ㘳㕦㝣慦㈷㕡摡愲戱㙡㘲愸㔶搹㌴㑢挸愸挳ぢぢ㈶攳搲㤴愵㜳〸愵摢㜶㐷昱㈵㐳㜶ㄸ㜸ぢㄹ扢㘰搳搷㔶戶敦㜶ㅡ戸昹〱㍤㔳㔴ち挳搹换㘲ㅣ㐸㔵㡣㉥㙣㕡づ㡢〸㠷挳㙣戳搳㐰㔴〵㥤攵散挷愹ㄴ挱㍦㝥㈹挴晡昱搶搰㔷戶搷㔰挷㌹晤㔸㈰㝦戰扦慥捦㘰㙣扣㤵ㅣ〳〹扢慤㔶愵昰㝡昸ㄹ㜴攱愲㜳㐲㙦㘵搵戳㌸㡣㍦㌱㘷昵㘹ㅤ晡㥦搱㙢挵㔹㘷搹㥢㘱散㤴晥扦ㅦ〵㕢敡㝦挱搸㥢㐲攴扢愲っㅦち㡣㥦㙣ㄹ戲攱㡥挰戳㡤攰㡤㍡ㄸ敢㉡换㤰㜷㤸㕢挲挷慢㘱戵㤲攰昰㝢攵摢慦㐶㌴晢搲戶ㅤ攸㉡〰ㄹㅢ㉡㝣ㅤ㈲愸㙢晦戴摣㡡㑦户挵㜷愳攳扥㤳㔶搵㜳㝤搷っ挶㤶㄰昴ㅤ攳户㘷㈶㙣㥥㈹昱戵㜶愱㜶ㄳ㜶㘲昰扤攸㜳㙡〱〲晢㤴っ㕥慡㔸㈴㈳ぢ摢㡢㘴昰㍢愴㤱㐴㜸㠹摡挱扦挲扣户㘱搴昱改敡〲㝣㥤〱㡢㜶㠴戲ぢ㍤捥敤㌷㌴戸㜵戸愳昵㑥昸㠳㘴㝤〲挱㌱戵㠴㜷扦㤷晢摡扥〷改戶搱摡㝣戶散捤攷㔶㉥㍣つ㥣㙥敦㉤㘹㤲攱㍢昹㐵㜲㔹慦㄰攲搲晥㔱晣摤扥㠳㤶愳㡤㠲捥愳て扡改〸ㅢ慦挳㝤戶㡤攸昷㌹㜴ㄵ㔳〴昸改㐶㤴攱㠳愰㤷㡦慣㈸扥㡣㘵㤱〱㤰捦ㄵ慢〰摤愹晡愹捤愸㝡㈴ㄶ挸㠲㘷っ㤲㘳㔹㝣ㄱつ戹㕤攱戲挱ㄲ㕣戶㔰㘷〹攴昵戸〷昲㌹挱戳㠴㥡挸攷搱愱㌹ㄱぢ愵摤㈷昲戹捤㈶㈲㘸〵愸㠵㈶挷ㅦ㠹戵㠸㕥㐷戵㙥ㄳ㌸〴㉥挰㌰挵㈲㘵㑤㌱っ㉤㍣㐳捣㈰晤㉡晡晢晣搱㕦㍥挷昴搷愳㐲〹㐲㔴愵㈷㑦㐱愸㈶晦挹攴攴㍤㤴㜶㥦晣挷㌷㥢晣〸㘵㈴㘷愲〷〰㐳㝤愲㠲㍦㙡㌱つ㘴戸㡦晣㠹㜳〴昸愵㘶㌱㘲愰㐴昵扤㠸っ晡㜲挳㔵慢㑢挸挴㝤ぢ㕣㝦挶挷㍤捡㍥攲㐵㐸晡㜲㡡愱㌳戶ㄸ㙡挵㤲ㅤ㜹㘱㜷㠴㙣挰㤲昸戵㙣㔷㤱㕥散㌱挲㉦㍥ㄴ㈳收挴㠹昸换㈹㉤㡡㌹㠱㌰㐲㡢㤴昴挳㡤ㄴㅦ㡣ㅢ㝦攷扢㉤㤷㈹㉡㤰㐰㍤㘱㘳搲㤹㙡晣㜸摣昸㄰扥捡㔲㙤㜲扣㐱挰昴㝣摣㤸昴愸ㅡ㍦ㄶ㌷晥换愱晤捤挶㌱ㅤ㠶㈳ㄷ㐸㈴ㄹ戶慥戲晥ㄳ㕦㘸て愳㜹挱愴晥ㅣ㌰挳㘲㑡㑥ㄵ㍡慥㉢つ㍡㠸换㈰ㅥ扥㤱㥥挷摤㈶㕣〱㠱㤰つ晦㔷〹㜳戸昳㌴㙢〴〶㍥㠱㕥㐷戰搹搳搵ㄳ㍢ㄷ捤〵て〵晤收㥣㡦㌳㔵㙤㐷㤱〸捣㠱㝣戸扦㕢㌸攵㌳㑣挷搶㝥挴㐱㌲㡤㜷㐸㝡㔳ㅥ㉡戰㤲ㄷ敦㡦㌱㥢㝢戴㐵㌳晡㈳㐰づ愴㈳㈰㌳晡愳㠰㘱㈰㠶户㤵㜳㈳攴㝦挵摣敦㘷挵〷〸ㅥ〳㈸ぢ㌲㍢改愰昸㌸挰㜰晣㍦慡ㄸ㕢㔷晥ㄲ㑤㍣ㄴ扦㉣㐹㐶晡㠷搸攱挳〰㝤㜰摦㡡㠸〸换晡㐷㔰㤲㝣㈹〵㠷㝡改㐷㔹昱㌱㠲㡦〳㤴ぢ㥣散戶㜷㡤㙢敡㔱㜳㝤〲㕤挵愳〴昸改㥦㡣㌲㝣㈸㜰ㅦ摥摡摤㔶收㔱㌸晥戰ㅦ愱捥搴ㄷ晣㜷攳㡢晣つ㉥扡て晦㐳㤲㠲㌲散昳摡㕢㝡ㅢ㡢㑣㐰㥢㕣晤搶戰搹㉦㘲ㅣ慥慢ㄵ㐱攱㠸㔴㉡㈵慤㈸㠸㙦㉥㔸戸㜸〳摦㜲㐴㔵〸㐱ㅡ㔰ㄵ㑥㔴㜱ㄴ〵晡愷搹㤴㌸㈶㥥昴捦昰㠹愸㔵㥢昸搹㈸挳〷㐱扣慡敥て㐴摤攳ㄷㄲ搷慡挲㙡㝢㈱昱慦㉡㔶㤳㉦㝣㤲㠳㈹㘴㈱㤳搶㑡㐴㥡愲愱㉦㈲㌳搴㌷捣戹摤㠷㥦㜶㐹㔴捦搵捥㥤晢挷㜰㝥散摡晣晤敦ㄸ㝣昲昹㕦晣攱㠹㕦扦攷挸㥦晦昵搴㔳扦晥攳ㄳ捦晤敢搹㤵㈳㍦㝢晡改㥦摥昳㤵攷晥戰搷晣慡昶摤㝦捣㝦昵攱挹ぢて㍦㘸㥥戹昵昸挳敦㝡攰摥挹挵㉢挶晢晡晡晢㙦ㄹ晤昹㌵慦ㅦ㜹昴挱敦㡢ㅦ晦昶㙡㐷愸攵攲〵改㘹㜰搹㙡ㅡ㕦㐲〶搳攰㡣㕦搶㘹㜰戹㙡愳㔶愲㡤㥡㐶㐱〹㍥つ㑥㐰㔵ㄸ改㡡㠱晦〰ㅥ换戳戵 | B27: 㜸〱捤㕡㙢㙣ㅣ㔷ㄵ摥扢扢㌳摥㔹摢昱㌶㐹㑢摢昴㌱戴〹㝤挴戵散㈴㙥ㅥ㙤敡昸㤱㠷愹昳㘸搶㐹㠵〴㉣攳摤㍢昶搴扢㌳敥捣慣㘳㔷戴㠹㈸㤴㡡㠷㉡〸敦慡㉡㡦昲㠳愲ち愱戶昰㠳㤶㔶㈰㠴㉡㐰昰〷㑡㠵㔰㜹〸㐱㘹㐱㠱㥦㍣㔴扥敦捥慣扤慦㌸㑥ㅡ愴摥㘴捦摥攷戹昷㥣㜳敦戹摦㍤敢㠴㐸㈴ㄲ㙦㈲昱㥢㈹捤捣㔵昹挵㈰㤴㤵扥㔱慦㕣㤶挵搰昱摣愰㙦搸昷慤挵〹㈷〸㔳攸愰ㄷㅣ戴〷㕡㈱㜰敥㤳㤹挲扣昴〳㜴搲ㄲ㠹㑣挶㐸愲㥤㝤昸挹搵ち〶㑢㐶㥡〴扤ㄲ㕤㍡挸攴攸挸攱愹㝢挰㍦ㅦ㝡扥散㌵㡦㐷㕣㜶てっ昴つ昴㙤摢㍥㜰㙢㕦㝦慦㌹㕡㉤㠷㔵㕦敥㜶㘵㌵昴慤㜲慦㜹愴㍡㔵㜶㡡㜷捡挵㐹㙦㔶扡扢攵㔴晦搶㈹㙢摢㡥㠱㙤㠳㠳昶捥㥤㍢扡㍡挰昹搰攸挸ㄱ㕦摡挱挵攲㤹㈱捦挳愳㈳㝤㠷㘴㜸戱㜸ㅡ攰〹㤶㘳㕥挵㜲摣㡢挴㔴愳㤶〷挷㘴搱愱㌹愴昴ㅤ㜷扡て换㙥㔰㌴㑡摢晢㠶㠳愰㕡㤹愳㘵㐷㘵戹㝣㔴摡ㄴ搱愸㡣〵攱ㄱ换慦〴㕤ㄵ敡㑦晡搲㉤捡㘰㑤㘵敦㐲㔱㤶攳㡥㐱愶㜲摣昲て㔹ㄵ㤹㘶愶愷ㄲ搹㜰扣㈴摤搰〹ㄷ扢㉢挷〲㜹搴㜲愷㈵扢㘸㤵晤㔵愷㈴搲㘹晣㑦愴㙥㘸户㌲㘵㈸慣愷㌲㍡㘳昹愱㉡搱㠴〳敤晡搶㙤ㄷ㈵㐵挳扡戸愵捣愶㔱戴㔹摥愹摣㈹㝤㔷㤶㌹〹挵摣摣搴㐹㈹㈸戲挳㤲愶㙡攲搰㑡愲㌳㍥づ㤴㠵戳攸㔹㤰㉢㡥戹㡥敤昹㤵摥㠳㡥扢扢扦慦㝦戰昷愰戵㠰捣㤶㐱愳ㄳ捤㐶ㄷ㍢㜶㠳㡣㡤㝡㤵㌹慦敡㤶㘴挹戴㕣户㙡㤵㑤㕦捥㑢户㉡捤㘹摦㍢ㄱ捥㤸扥ㄵ㑡搳挳㈱㌲㕤戹㄰㥡㠳收愲戴晣挰摣㙤晥攰扢愶㌹㕣戱敥昳㕣㘳つ㜹昶㠰㠸昴ㄹㅣ搷晡㈵㜱扡㘴挱㑡ㄶ愶㤲㠵㘲戲㔰㑡ㄶ㘴戲㘰㈷ぢ搳挹挲㑣戲攰㈴ぢ昷㈴ぢ戳攸㔳㑢㤹㡥㡥㘴㥣摥晢攸㙢㔳慦ㅣㅡ㍡㜰敡晡攷昵㈷㑦愷扦㉥㜸㐲戹㠹昴㑢㐰㝡㈷㝤〷㤶慣㤶㉤扦㈶攵昶挱摥〹㘷㔶㤶ㅤㄹ㠴㄰㜶㘰换㤲搸挶㕡㡣㌰搶㜱散㝡㤰㠹㐹换㥦㤶愱㌹攷换㕢㐲㙢挱昴收㈴挴挴㝥㌴㉢㘸㜰㕣昳挶扤㈳攳㤳愶ㄵ㤸㥢㑣捦㌶〳慢㉣〳ㄳ搵ㄴ摤ㅣ攸扦愹㔱晡㑢挹晢㌲㄰㈱㕥㠳昴搴挰㕤挱扦㤳ㄵ晢搷㝢㥦晢敡㈳㝤晦扤晢收㔹㐱扦愲㤶㝥㌹㌲搷ㅥ㠲㘹攰㉥づ㑡㑢㔹㘷晢捥敤扤昹戰㌴㈶攷㘹慢晥㕢㡤㉢挸昱㑡㄰㝤〳挸挶㜱搷〹ㅤ㔸愶攸〵㈱搷㔳戴收㥣㄰攵〶ㅢ㕣挵㌱㔷㠳〸昱㠷㜸ㄵ扢〶攴愶㝢㌳㐳㝢㥥ㅤ晡捦㑣敦戶㤷㌷㜴㕤㡢收扢攲晤㌲收㕢㈷㈰昱昲攱摥搲㠷挹㔷攳搵攰搴散㐱㝢扢㍤㌰㔰ㅡ散户戶㕡ㅡ㙤扣摡攳㤳㐳摦㉥晢㙥挷㉤㜹㈷搴㜹扡㙡挴ち攴昲昱摡ㅣ户㡤㜰㔳〶ㅢ摡㌷收㐳㙣捡㉢㥢摢㤶㤹戴っ换挳摢挸㐰捤㜷㑤昳戰攳㔶戹㉡㠷ㄷ㥣愸昹敡愶㘶昸ㅡ㙦敡散慤晢㝣㜹敦㔲㙢换㡡㠶㜱㍤捤㉢摥㉤㔲㐶㑤搱扡捣搱ㄹ㉦㤰慥㕡摥收捡ㄱ愷㌸㉢晤扣攴攵㈶㑢㑡搴㑢搹ㄴ㍢扣捤㠷㕤〸ちㄷ㔶扡慥扥搶摥扢㄰㑡ㅥ㘳慣ㄷ扢㌹㕣㥣戴愶捡昲戲㠶㉥搱㥣㘸戸愲愱㝡㥦㔷慣〶愳㥥ㅢ晡㕥戹戱㘵戸㌴㙦挱挹㤶づ㝡㈵〹ㅦ㤹㘶㑡㠸㐴㉡㈵㐴攲收㜶㡥㡡㝣㠳㍥㘵㠸㍡ㄳ搳㘵㕥摥戸敤晡㡥㐲㍡㐸㔱㤶摣㤳挹㡤攷㘰愶昸㤲捤㑤㘷敦㔸㈷ㄳ㤱〰㝢摦㜸昶摥㙡㡤㑢㤶晢晦㜶㑥㈶搷挵搲敦㠵㙢つて㔸㙥愹㉣晤ㄵ㜱㡣攰㡡っㄳ㐴㝢ㄵ愷昹慣摡愳㑢ㄴぢ㘲㔱㍢攱㤴挲ㄹ㝤㐶㍡搳㌳㈱敡㠰㜵㌲ㄹ慡戶㈵ㄹ搷愱捡戸㥥㘴㈳㐸㌶㥢搰㌷戱㤳㥥㌵摥ㄵ㤵㌵摥づ攷㝦挵ㄱ㑤ㄹ敡㑡〵晥〹戴捡㍥捦て㔲愹㜶㔲ㅥ戰㠲㤹㤰摢㜳挵㐶㕥㘶挶つ㈴㌷㠲㘸扣㘳捥㜹㠳昲づ㑡ㄳ㈸㜴㔷挶愴㙤〱㥥愹搳㉤㉣慤ㄲ摤昸㘳㌲㈸ㅡ㠴〶攳㌸㉢ぢ㍡㜲㌸晣㕤ㄵ敥㝥摣㙥㘳㔶㘸㜵㔴〰㌲㘰㈵〳㥤㌶慢㔱㔱㡥㈳扢㔵㕤㙤㜴㌶㉥㠱㐳㑥㘵敢戸㜴慡㡡㠸ㄳづづ捥㑢㈲ㄵ搳㤵㠵挰摡〹〳昴收㡤摥〸ㄶ㠰㘱㑡晢愵㍢戹㌸㈷〳㜶捦攸㉢慡戲昹㜸㤱搹攱攲搴戱搰㈹〷㝤㔸改㝥摦慢捥㕤㔴㍥㔸㤳㜱ㄳ㐸㉤㘹扦挲㉥㕥扤㑣挴昹ㅤ昳戴㑤愱㠰慤㡣ㄲ㙢っ㈲ㄶ㠳扢ㄵ捣摥挴㤷㑡挶㉤昸捡慥搴愶㜱㕢㥣て戰㔲慦㠰ち㌴㌴改㑢〵ㄵ㌳慡〰㙤㜷㔷敥昶晣搹㈹捦㥢攵㝥㕡愳㑡挱㡣㤴㈱攱㔷㘷っ㌷ㄵ慣ㄴ㈲㤵㙡〰㐲㜵㌸㡤挰㑤ㅦ〰改ㅥ㉥㤷捤ㅡ挷㐰摦㠲慡ㄴ㠰愰扥ㄵ㤹つ愳摥摣㈲慦晢〸㘴攵攵㕣戸愵㝦㘰㐷摦㐲㌹㔸㄰㍦㠵〲〸㌴ㅥ㝥㙡敤敢摦晦攱昱㤱㘷㠷ㄶ敦㔸ㄷ㍣㌱㈳㝥ㄲ㌷戴㠰㈷㈲㈰㠵晤㙥㐵㐶扣㠴㙥慦攲㠳㝣㘳㌲㜶愰㙣散㈴搹〵〲昷愰ㄴづ敦㜰㝢㔴ㄴ㐴㔱昴㄰挶㙥㤲㍢㐰〴ㄱ㤰挲㠰㐳挸搴㤲㜸ㄱ晣㘹㜶㘵㍡挲慥㔶搳㡤愲㌶㙢慣搰㈶㠸慢㘸㍥㠳敡㌲愸㈰㠳捡ㄱ摦〱攳戶ち㜸㌶㙥㘸㠱㘰〴㔵㑡〱ㄳㅣ晦㌴扡扤㡡て昲㡤挹㌸㠴戲㜱㤸攴〸㐸㥤〲㡥㐶㐵㐱㘰愶ㄴ㤰㘷愷㐹㄰㐱昰愵ㄴ㜰っ㤹㕡ㄲ㑦㠲晦㤲〲㠸攴㕡ㄵ昰ㅥ搴㘶㡤ㄵ摡〴㈱㕤㍢〵㝣ㄹ捣摢㉡攰昱戸愱ㄹ晤㘹㈶㌸㥤挷慤慤㜴㘵ㅦ㜷攴〹扡㤹㌵㌶㥥㑥愳搵㈰昴㤴㑦散戶挷扣㐳㕥㌸收〴㜳㘵㙢㜱㥤ㅤ㘷敥㥥㤱㉥㄰㡢て攰搲㔴攷捤捤挹㤲㘱攷扤慡㕦㤴攳㘳㙦〷㐴〳㜵挰㜴ち捣㈴〵搲㠵㕤搲挰摢〲扢〴㈹愱昱㙡㙤昶戵敡〱㔷㠷㡢㔴㤶㈸戸㘷㔹愳㤳㑥㔸㤶㥤戶挲㈴㉡㥦戱愱挵攲慣㉣㜵搸㤳㌳昰㐱㘳摤昶㝥摦㈹㤵ㅤ㔷搲ㄸ敢愳慥ㄳ㜲ㅡ㤰敦㠸ㄷ攰㜹攰戹摤昶愴㙦戹挱ㅣ㙦慦攲攲摡㠶㤲扡收㌴㝢挴㜱〳㑣愳慣挸㝣㡦㥤㥦昱㑥㈰㤰㔲慤戸晢慤戹攰㙤㘱ㄵ扡㡢㈸㈹搳㠸愴㐸㈶㐵㈶㤹戹㔰晢攸㔳攰戶㍥㝥㄰㥢搸愸愱敦㑣㔵愹㌱㌵ぢ㕤㑡㥡㐴ㄹ㌱愱ㄱㄹ㌵㕦㔴㜵㌶㙣㐲㤹㕣㙣㐳㍣愲㉤攰㔹ち㑦㈹㔴㔷攴㤸ㄲ挸扢昷ㅦㅢ㕦㝥㝦扤愵挸㤲㐶㉣户㙡戸慢晣㜵戴㠷〸㠱戹愵㜰㌴戱ㄵ㔸㙡摥㤷㔹㕢昵攱ㄶ㕤戳㥣摤〷挴搴㘵㑦㔸㔳戲っ愰㔷戱挲㌵㔱㠱㠸ㅢ㙦摢㈰㙥㐳㜸愱㘲㜱捦㌱㝥㤲㉦攲㈱㥤戱㠷慢愱㠷戸㠴㘱㠳愸㡤ㄹ㔷㔹ぢ愸戲ㄶ㈲㐸㘶ㅦ攵〳㔰攵挹换㥢戶㝣㈷㥣愹㌸挵っぢ㝣愴扤㉤㌶㉢ㅣ㐸ㅡ㥡慦愵㥡㌳㘹挶㜸ㄱ搲㠲戹晢昰㉣愲敡㘸㝥㙣改愴搰昱㑦㕣攰晢〰慥㐷摤㈸㠶つ㙥ㅡ昱㌷㝤㤱㑡㘷㙡㌱搳㌳㈷㔱愳扣㤳㈰扣㘷戳㌱ㅤ㘷㔸㐸ㄳ㘱慦〸ㅥ戹㘷戳ㄳ㥥㔵摡㘷ㄵㄱぢ敤㠸㈳愱ㄹ㐶㡥攰㙢晣ㅣ攱晣㈸㕥㠸㜸㜹捥㍢㈵改㘷㔸㤱㐷散㌵捤㠷㠰ㅥ搹㄰挰㈶㤵搰戴捥㑣扢戹挶㙢扣㌶挶㈰愹㍥戶㍢摥挲晦㡤扢㜶㈸愰㤱捤愶戰㌶㘳㠶挴〱ㄱ㌷㠲㔰㥥愶づ昷戰挳㉣㠸㐶㐸摡㙣㥢㐶㘴つ晣㑤㜴㤶㔶㌱㐴㘲晥っ昰戱㝡㉣㘸㑡㤰捥㍡㤰慦㐷昸㍥㔳ぢ㑣敡㜹散㜲㔹捡㐶づ㤶㡦〹㥡㈳㤹㑣挳搴㝡㜳㠰愴㘵㕡㌰慢攴愵㐲晦㠲㠸㔷㉦㠳㑣昰戰㠰㝦攱愲挴改㥡愱㜳㌶㙢㈸㈷㤸ㄵ挴搰㌵捤昱攱㤵捤搲散㠶㐷㌲〷㈲㠸ㅡ㑤㝣敡慥㍢㐱愸挸㉢㉦愱摦ぢ昲㡥攵㠰摣㌹扤慣㈰挰愴愷㌵㝣㄰㐱愴㐹〷戶戴愱昹㠴㍤昷㠶㈶㈲㔵ㅢ扡ㅡ㘷㔸㄰㠴愵㌵㔱㤰㠵㈸㙡㤷捣㈳㙢㥣〰ㄱ㠴慣㙤㍡㉣戰挳㈲㍢㜰㜳㜱愷攸昷㠱㑣搶㉣㜰㔱㘳㠶㙤㉣昱㐱㑣㤶挸㡡㔱搰摡敡敡㉣㜱㍦慡㡤〷㐰〴攱慢㠹㑦扤㈵㠸㔹㈳㑢㥣㐴㙥㕤ㄴ㕦㍣户ㄵ㠸㜲㤵ㄵ㑥㈱㈳〸㜷ㅢ慣昰㈱㔴㥣摢ち㠴挵捡ちて挶ㄹ㘵〵㘲攳㥡ㄸ挸搶慣昰㘱㘴㡤㡦㠰〸攲收㌶ㅤㅥ㘲㠷㡦戲〳愱戴戲挲挳挸昴搶慣戰慡㔸㘸ㅢ敤㝥っ㑣愰㕤攲敤摡慣㜵摡晤㌸慡㡤㑦㠰㠸㈲〹㑢㥦㡣㌳㈹㝣㙢㌶㐸戳摦㘸昱改㘹㜴捡摡昴敥昹㜰戱㡣ㅢ㤵㔹晡㤱㈸㐷㡦ㄸ㌵挳扢㜹㍥㝥换㑡㌷㠷㜵㤶挶㕥ぢ㔶㥤敢㥢㐲㘶㙡ㄸ㕢㑡昸㘸㍥㘰晥㔹挷㔳㠲攵昷㌳挷㌰改㡦㠰慣㍦攸ㄴ㝤㉦昰散搰捣〳㉥㥡っ㐱㐲扣晥㘱㙤づㅣ摢捥㐹挱搲㉥㝦㌱㤹攷㤳㍣㍢敢㝡㈷㕣戵ㅡ㉤㘰㈴㔶改慢愳㠳搳昰挷〷㤵慥㠷ㄶ㜳搳挸㜲戰昱㈹㤰敥㔴㡥㥥㥡㈹攷㐴摦㠹ㅣ㕤㌳㔳㡥敥㤹㐹愳㐳㕡慤慦㈴㙦㌱㈵㡡愲㈴㘴扡愳㐳㙣㙡㡡昷戵昸搸愵㠰㠹慥搳挵㙡㉥㐴㕥摤愰㐶㡤㜲戰㤲晡㌴㌲挶㘷㐰戲㌹晡㑡㉥㐸晦㉣挸㥡搱㤱㐲ㅤ㔴搴㍦㠷扡㉥搴愹㍢〴扦㘸〵晡攷㔱㜳〹㙡ㅡ㝦愱搲扦㠰敡戵愸㐶ㄴ愰ㄶㄷ攰ㄶ捡搱〹㉢㔵慡㘷㤹㝡㝥㍥㡡慡攸㌱慣㥣㈸㑢㡦㠱㜰㕤摣戴㠲㑥㤴ㅢ㔷㑣㐱㑡㙥ㄷ攴ㄳ〶昷〰捤㉤㍥㠰ㅡ㥡扣搱㘴㜴愵㙡㥥慦㈰〳㤳搱㙤㌲攵攸㍡㤹㜲昴㤳㑣㌹晡㑡㈶㐱捦㐵戳㠹昷㠳ㅤ㔵㑡㈸㘲㝣㡤攴〹㤰㙣㡥捥㑢㌱愵㙡っ敡挲愰昸〶㠵捤搱愹愹挶戵慣㕡㐷昲㑤㤲慤㈰攲ㄴ〹㑢㑦挵ㄹ㈵ㄹㅤ㤳㤲散㈸㈶㙢㤵散〸㙡㕢㈵㝢㄰㠳搴㍣摦㐶〶㤲㝤ㄸ㕦㑣㌹扡㈳愶摣㐳搱㜷㈲㐷晦挳㈴攸㌵㤴㘴㠷㘲挹㌸扤昱㌴挹㌳㈰搹ㅣㅤ挷㔹㈵愳㐳㔱㡤㔷㜰〰挳〶挶昷㐸㈸㔹㡥晥㐵㌵㍥㡦㑣㜷㑡攳ㄱ戹慤㘹晦戶㝦㜷㙣㙥づ昵敦㐵攸㝥㤱㍡㑦〱㜰㐵㌰㈵㥤摣㜵㘱扣㜸㐲㍡挰㡡ㅦ㙤〴㔲扦〵㍥㌴摣戲ㄷ㈲㐷扡〸攳〵㤰㥥搳㈰ㅡ㍥㍡㍥㜵改捣㔰㕣搸ㄳ㝤㘷攲敦摣㥥ㅥ㥥㌲㌵攲㝤攲㥤㥦ㅥ搶㝥㜷昲昱㝦㍣㜹摢愶挷扥昵㘶晣㝤昲㑢㕦㘴晡㐶捣攱ㄷ㐳㠲〷愴〷㥦收搸搱㙥㠸㜵〶㥦㤶攰搹敤㜱㐳㜳昰㉣挷㜳愵㡣昵㈳㘴扡㔳㠲㠷㠳〶ㄳ扢㌰㠲㕡㔲㠲晤ㄸ㌵㍤摣昶ㄴ㙡搵㠲愱㉦搲晡㍤㍤㑦攰㑢㡤㍣㥢㠰㕢㔵㝡㍡ㄶ昰挵愱㐸攰㤷㠶〴捦㑢㍢㐱〷㘳㜹㕡〴摤ㄶ㌷㌴〷挹㜲㍣㘶㑡搰㥦㈱〳㐱㜹㔶㤴愰㕢敡〵晤㌹攷攳㈹㌸㍦ぢ昲挸慣㘸挱〳㉦摣㝦昵㡥改㘷㠶晥昵挰㍤捦㠵愷ㄷ㠶〴㡦㑢㍢挱㙥㌹㥢㘰扤㜱㐳㑢昰㡢愷散㕣挱慦扡㕦〹㌹愹㘶搳昳㜶摡㔱㌵て〶慥㙦愷㕣㔶㌷㕦ㄷ㥥慡㍥㝥愷㥢㐰㐸〶て㔴晣㡥ㅦ㍢㜲㠴㙡㠸晣㙢㡦㈱㐳㤵㌸㔸户て晢㜸ㅤ㜵搸攳〱㐲㘹愵っ㝥㘷〸㐳晣昶晦㜶㜸挷〲㡢愴改㐰昸㑡挳㥢㈵搹ㄶ〶㜰㡦慦㄰㘲㔸搶㐷敤攷户㈴㕦戸ㄷㄶ㔵搳㝦㠹挹㤶㠲㌶愵扡愰㑤㕡摣っㅢ㐷敥晤㔴攲㑤慥ㄹ㙦慣㠴昱㌲扥㔴㝣㔸摤ㄷ㈰㔹攳ㄵ㔶㙤慡㤱㠴昶〲戲捤㤲ㄱ㤵敤愳攸㑤扦愰㜵㜶㔲摣㕡ㄲ㍣昷摣㐲晡㙦㐰敡㕦㍡㡤㑢摢搸㜶㘹扦挵㤸愶愵扤捡慡攵愵〹扡づ㉥慦㤶〴捦㥦㥡昰昷挸搴〰㝤攳㘴搷戴㥤散㡦攸摦㌴搹㥦㔸㔵㌷ㄹ㡦㙦晤㘴ㅡ㜵户㙡换搲慢慦挳ㄹ㠸晦昸㡡愱㤸捤㘵晥改㔵扢㤷㝤㘳攴敢捦ㄸ㉡㘸ㄵ昲㌰晥ㄲ㘷㔸㄰搴㤱㌲攱㙢㉣㔱㍤慡捦㕦攳㡣敡㐳搱㔴㥦搷㔹㑢愹㔴㥦㌷敡晢愸㈹㔰㘱晣つ愴㤶㜲㥣㑡戹戵扦㈳〳户愶㈶㐱戶戱ㄷ㈷㔳扤捥㐴扤搴㌴㉤扤㌸㥤敡昵㑦搵㉢㔷㥢㐸㤰户昲㤵摤㌰っ㉦㠵ㄱ㔴㘴㐴㐲㤰㥤㙡攸㙡㙡㈰〷搵搰搹搸搰昹㍦㕣昷慥㌶ | C27: 㜸〱捤㔹㕤㙣ㅣ搵ㄵ摥㤹摤㔹敦慣搷昶收㠷〰㠱挲搲㈶㠴攲㜴ㅢ㈷㠴〴㘸㑡散㜵散ㄸ㥣搸挹㍡〹㤴愲㘵扣㝢㈷ㅥ㌲㍦㘶㘶搶昱愲愸愹搴搷㍥昱㔲搱㐲㐱戴㉦昰挲㕢㝦㄰㉦慤㤰㡡㔰晡㠶㐴晢㔶㈱愴㔶㉤㐲㔴㝤㐱㉤ㄵ晤扥㍢戳敢摤昵㝡ㄳ㑣㉡昹慥昶捣晤㥢㌳昷㥥扦㝢捥戹〹㈵㤱㐸㝣㠱挲㈷㑢㡡㤵㍢换㡤㈰ㄴ㑥戱攴搹戶愸㠶㤶攷〶挵㜱摦㌷ㅡ戳㔶㄰㈶㌱㈱㕤戱㌰ㅥ㘸㤵挰㝡㕥㘴㉡㉢挲て㌰㐹㑢㈴㌲ㄹ㕤挵㌸㤱昰㥦㙦㌶㜴扥㤵㑢〱㉣㤴㈶收ㄶ㥦〵搶㜲攸昹㘲㝦攱㝣昴敥戱戱戱攲㔸昱㠱㈳㘳てㄶて散㉦㤴敡㜶㔸昷挵㌱㔷搴㐳摦戰昷ㄷ收敢㡢戶㔵㝤㕣㌴ㄶ扣㑢挲㍤㈶ㄶてㅣ㕡㌴ㅥ㌸㍡昶挰攱挳收㐳てㅤ捤攱搳㠹搳愵㠹㜹㕦㤸挱捤挲㤹㈶捥戹搲㐴昱戴〸㙦ㄶ捥〱攰〴捡㐹捦㌱㉣昷㈶㈱搵㐸摢㐳㤳愲㙡㤱〹㐲昸㤶㝢戱㠸㘵㜷㄰ㅡ慤㈳挵㈹㔰扣㙡〴㘱㐹搸昶㔹㘱㜲㌱㌹㠷㌴ㄳ扥㜰慢㈲ㄸ㜶㑥慣㔶㠵ㅤて〷ㄹ攷扣攱㥦㌶ㅣ㤱㘲㘵挴㠹昸㌶㔳ㄳ㙥㘸㠵㡤㈱攷㕣㈰捥ㅡ敥㐵挱㈹㥡㌳㕤户㙡愹㤴㤲㑡㈵㤲晢㝡㉤㐶昲愶㌸攵㔷㑢㑢㠶ㅦ捡ㄶ戹㌶搶㙢㙥㥢㠴挸㠵㜷㉣㡢㔲㔴攸㝡㡢㙣㉡㕢捥攳挲㜷㠵捤㡦㤰㜹愳㕤㤳㈴㑤㈲搲户㠸搳摣つ㘹愱っ挶㜲㉦户㠲づ㍤㐳愰〳愴戳〰扢㑥〴愱攵ㄸ愱愸ㄵ㔶っ扢㉥ち摦づ戰ㄵ愱て㜲㔶づ㐰㐹晤ぢ慡搴㡥㠵㐳㙡挵㔰㉢㡢㙡愵慡㔶㙡㙡㐵愸ㄵ㔳慤㕣㔴㉢㑢㙡挵㔲㉢捦慡㤵㑢㤸搳㉣㤹㠱〱㌵㉥摦搵昷㝦昰㠳㜷㜷㥤晥敤慤㝢㍥晦昴敡摦㝥㤴ㅢ挶愴㌳昱ち㈷㝤攳㌲搸扣㈶㐱〷㡢〷昸扢扥敡㐰㜳捣挳收ㄱ㜳㙣慣㜶昸㠰㜱挸搰戸挷ㅢ㘵搸㑥捣捤㤹ㄷ㉣户收㕤㤶ㅣ捣㤹㔳㤶ㅤち㕦㌶㐶㑣㍣㈲㈹㤴敤㈱昳挴㉡搴户ㅡ㌱㝢愷㔹ㄲ㝥〸戱てㅢ㙢ㄲ㜰攷㠴ㄱ㠸戵收㘸㡣㝢挲慢扢戵攰㡥摥㠳攵㄰㉣搸摤㍤戶㠶㘴摤㙢㘵愸㠴〸攴㤲敥敡㝥敤㍣ㄹ㌹扥㙡㐵挳㕦敢ㅡ㠶㜲㜸㡢ㅢ㡦㑥昹攲戹搶攸扡ㄵ㡤挳㜲慥㐸摣敢㜶ㄹつ㐵敢㉡㤴㤶扣㐰戸㜲㜹愳捥扣㔵扤㈴晣戲愰摤ㄵ㌵戹搵㕢㌸ㄴ㙢攸攸㥣㡢㡤㐲攷㙡㕦㙦敦㈵愱㠵㕢ㄳ㌵慣㜷ㄹ㔴㙥㉣ㄸ㡢戶搸搵㌱㈵晡㈶〶㙥敦攸㥥昲慡昵愰攴戹愱敦搹㥤㈳攳戵ㄵ〳㔶愱㜶捡慢㠹㤴㉣㠹〸㉡㠹㘴㔲㔱ㄲ昷昵㔲㉦攲づ愸㠰㙤㐲㐲㌵敦㍦戹㑤㠸㌸戹愷攲戶㌰愳搲㈶㘴㥣晦捤扥㉢㘹ㄷ㐲捥㍥搰㜷㜶て㈱攵㑢户㜵㉡㕥昱㉣昸〳㍥搸㠲㕡愹敥搹ㄸ攵㥡㕣㕥㘷愵㙤㕣攱㌱换搹㝤㠸㈶搱戶㘴敦晦㍢㔹㔵㜷挴扢㍦戱〲摢㝦搲㜰㙢戶昰晢㍡〹ち㔷愴㡦㄰攴〹戶ㄱ㙣㈷搸〱愰㝤っ㌳戹㈱㐵㘹摦㤵㔵愵愱㕤戶㙡攱㔲㝡㐹㔸ㄷ㤷㐲昴挱戹挸㘴㐸敥扦挷晦㜷攰㕤㝣㐴㌷㐳扦㠵㘰ㄷ挱慤〰搹㙣㈲㝤ㅢ㥥戰摡晡敤㝣散〶ㄸ㘹ㅥ㝥㠵㐸㌲戳〹㡤㠶晤换ㅦ㍦㜴㘹㜴㜹摡挱ㅤ〹㌴〷㜸㠳㘴戲ㄷ㌵㑥ㅡ挱㔲㐸㐵散㍢挸敤敡㜷㄰摣〹㤰晢ㅡ挰改㤳挲㠶ㅡ摦㉣㑦㐶攳㈹㜴摤ㄳ㤳摣搹攵㤴ㅢ㙥㜵挹昷㕣昸㜵㤳㐶㘸㡣㔷攱ㄶ〴㡡㤱㜶㘶扤㔲㍤㑣㍢㈷㉤㍣㜲捥㔹戱㉣㡣戰〴㌳ㅤづ㌹戳㜰㈹愴ㅤ㥤愹慤㙡㑥攴つ㑣㡡愰慡搳㙤㤸㠱㔹㕡㑤愳〶㍢㥢㜳㘸㘸挴㙡㐸搴〳捥㍣づ㑦㌷搴㌱㘹㔴扥ㄵ搵昸收㤰散㙢扥㥤㡤㕢挰㤰㤷搵㌶㉣㠳戲㈳挲㤴㈰㈹ㄳ戰㑣㠹㘴㉡㠶摤ㅡ㜴㉥戴散愰ㄸ㤳户㌸改挱慤ㄴ搲戳㈵搹搳㘹〸㔸扡㉦戳扡ㄵ㥤㝥挷㕣㜵㌱㐲㡢愵㑣晢㕥㝤㤹扥挷捤挲㐳㕣〹晤㉥㠰㔷晥昹挶㈳㝢㕦㝥昳㡢昸㜹ㄵ㉡㈴㡢㑥搷㐴愷扣戳㠹㠷㉣晡㍤㜸㘴晢㡤㘹昴㔸㝡㕡摡つ㕣㈴慡㜴捥挱㙥ㄷ㝣㈱㝤扥㡣㙣㌴㤶挵㤰㜳挱昳㉦㉤㝡摥㈵㌲㝦㔸戶㠲㈵㈱㐲㍡㔲㠳戱摦挸扡愲㈸挹㘴㠷㝦搴收㜱搱〵㑢敦〵ㄸㅡ户敤㐲ㄳ㘳㤰扥ㄷ㕤㐹扡㜴晢㔰戹愳攴㉤㌷ち㥥㔹ㄸ㜷㡣攷㍤户㉣㤶挳㠳〷挶㡥ㄶ㔷敤㘰㔵昹ㄳ〸㐰て㑣昹攴ㄷ晦晥捦捦づ㤵㝥㍤㜱攵扤昰挷㙥㐱昹㈰ㅥ攸昶愹㌴㕡愸㙥ㄹ㤱㙥㘲敢戴㘹㍢挷㘸㝢搲收㌹搷ち㠳㐱㜳扣ㅥ㝡㔳㔶㌸ㄹ㠴㌹ㄳ〰㔵昹捡㙥㘹㤸摢㕥ㅡ㌵捦㕢攲昲〲愸㜴昷晡㈱㜸搰愵㝡㄰㝡㔲晣敦㕡㍦㍥改㥤昶挲㐹㉢㔸戶㡤挶㥥ㅥ挳搱挸㠵㈵攱挲㔳昰攱㌰㕣㙦㤲户扣㉣㙡㍤搶㔸昶敡㝥㔵捣㑣㙥〵㕦㐳㠹昴㌸〱㔱㠱ㄶ㉢㝢㌷㍥㕢摢攸㑥攱㔴㈱㕥捡㈶㡦㉡㜹㕥攸愳挰㠲挰㔵挱ㄱ愲敦㐷ㄵ㈷㠹挶昳慢扦㠸戴㜹㉦戴戴㔹ㄳ㙣㡤晡㠶㘲昷㜸挶つ慣㥡挸挶慤㔳㤶㍢ㅣ㔷攷敡㘱挷㠸戱扡㈳ㅥ㠱づ捣戹㘰㝤搵昰㙢㕢㠱㉢搸ㄸ㑡挴ㄲ㈵㡤摦收〸ㅤ愱㐹㈴㍥㙤㘶ㅣ㍥扤ち㌳昵㉤㜴㤳搶㜴ㄳ㝡㥡愴㤶㍡愲搲收晣㔱㝤㠷㐸敥㔶㜷㠶慤㔳挲㜰㈵ㄷ捡㘱㙤㔲慣っ换ㄹ〲〲㡥挰搵ㄶ㍢㍡㥢昲㘴搲捤昱挵挰戳敢愱ㄸ㙥搵愴愲敢收㔹㘱ㅢ㜴攴㜳慤摡㝣㌵㐴愸搳挲㐷㈷㝤敢㜰〸ㄴ㐹挵㕣㔲㈴㥦搲㝤㠴户㜳ㄳ搴愱㑤㜲ㄵ㘷慥㈹换㈷㡦㉡㍦㝤㤱攵昵㐷ㄳ捤㑡㤶㈵愱搱挱戸㜱㑦㥤㥡戴愳ㄹ㐰㐶ㄶ㑥ㅡ慦㕣戳㡦㑥昲㤰㈹敤ㅥ㈲㘱收㉣㐶愸㍡㌶ㄲ㑡愱㔵㌵㙣扢㌱㙣捥戸㔵扢㕥ㄳ戳挶愲戰㥢㌶摢昳ㄱ挲㙦〹㝥挹㕣㕢挴慢㍥㜴㠹挳㤷ㄹ㈴摣㥡㜱挱愶捤㕣㐲㉦㠲慣搲㔹〰㡥慣㝥〰㉤戲㠶㑥昹㤷づ㡢攸㜷㙣㕦ぢ敡㘵㉡〸愶㙤㕤ㄷ㙤ㅡ㕤挴㔶㘴㈵㌵慥㙤摡慣㌷敢㈱敡慤戵㜵㥤戴愲慥㉤挱㈷散㌳㌲㝣改㜴㝡戳〷っ㜱搰敡挵捦慢昱昳㔱搲㥦ㅣ㘰〴搳敤㕣戶㌹㈲昲散㤷㐶㤰挷搱〸㉤㔸攴㌸㉣㔸愱㉤〶㑤㌹㉥敢ㄹ慡〴愹㌹㘰㉥㉣挱㔱㥢ㅣ㌲愷㝤慢㘶㕢慥愰ㄳ㠲㉣っ搳㙦戳攲㈲昲〵昳㕥㘰㌱扢㍢㘴㉥昸㠶ㅢ㉣搳ㅦ慦㌶戶㜷戴㈴戳㌴㜳挲㜲愱㐰搱㌷㔹ㅦ㌱换㑢摥㘵㈴㠸敢㡥㍢㙤㉣〷㕢㠲㔱㡣〵愳ㄲ㘹㤵慡愸慡㤲㔱㌳㥢㍤慢愴晢㑣㠷㈰㜱㄰㘸㔵㠲㤸㕤㡣㌵晢攸㉣㌹ㄵ㘷㙣愸戳㕣㔷㐷愲戵㘷戸搸捡戰搳づ敢晣㔸敥㄰挰㘳搳攷㘶搶昲㝣㕦㈹㑤慥㌱㍡敥㜳ㅣ㐸搱㘸㈵ㄵ㈸㤲挳㤱戸戰㡦搲愳㑢慥戳搵㉤㠲㔹㔳捥愱㌴攲〴攵㜴㔶愷㄰敥攵愰晣㌰扦〸㤳㘱㜷㠷愳〶㕤㍡挷戰㠳㜸慣攴㌹㡥㐱昱愲㘸㤶㘱扢㐵㐶晡搷戰㈶扡〹㈰㘵㌰敥㌲㔶搱㘵慣捡㉥ㅣ挹㑣ㄴ捡㍡㜱㜹ㄷつ摦ち㤷ㅣ慢㥡㘱㠳挹扣㉤㈱㤷㄰㈱ㄹ㥡㠲愰㉣㔲㌸攱慣㜶㠷攴㔱ㄴ〹㜶ㄷㄱ㍦㤰㜴㘴㍦愴㔷㤵攷戸戲挹㉣っ挴㔷ㅡ㝣晤㌰戰㘹昲㐲㠶挱㌱㑢㥢ㄳ㠶ㅥ㘹㠸ㄴ㈶㑣㌸慣㍦ㄸ㔷搸㐸㌱㍦搱㌷㌰㘶昰㤶㥤昵㡣摡ㄴ昲扤㥥㍦㄰㕦敢㘴挰㕡㥡ㄵ㍦捦㘴㐸〹㤹㐴㘴㈸㔷攰ぢ晢ㄹ㜶㤴㤱㘶㐸㌱㡤㤲㡥㜸㐸摡㈴㌴㙤㌰搳敢㕢㌳㑤㕣㝢攲愰戱晤㝡㙡㘶ㅤ晥㡦捦ㅣ㠵㜵攵戶㜸㍦愲ㅦ㈱㌸ち愰㌰捤挲晤㜴㑤㜸㠸ㄳㅥ〶搰ㄸ㙤㜷㙢挹㠶㠹〳㈲搷ㅣ㈶㌴㌲づ户〳㤷㈳㡤㌴〷ㄲ㈳㈰㐹㝡㌰挳挴㠲晥〸挰ㅦ慦㕤㍢㠶㐷㐲戹〷愰昹㝤慡㝡㌶㑢攲改摦㈱攰っ㡤㔱挸㡤㐵㍤㝣㌱摦ㄶ㡡㔲㐷㠳㙤收㤹扡㘱攳㠶㘶づ晥㔰挸慥慤愰〴愹挸㉢敤扥㘹攸扣戸㐱㐰㈷户昰搴搳捣㝢㜴搳愰㜳㙥扣户㠰㌳㌷攷戵㘶戵摦㈳㉦㜰㘳㕦愱ㄶっ慣㌰㠹㔵愹㈰戹㠳ㄶㄹ㥦搵㈹㘲㌸扦ㄵ㐶㡢㔲㙤㡥愳搲㉣ち攳㥡㜵扤ㅡ㝤戰㍥㠷㐷㤷挳挷昷㜷慣㠹㍡㡤摡愸捤㝢搸㕥㍡搲㜹㠶㡣昳昳昴昱搶慤㐱攱昱㈲㝢㑢㜱㐵捡㌱㑤挴㜵慤ㄲ㑤ㄹ㐲㔹搸愷㜲搸戰㜱㈶戰捡挴㑦㔴愳ㄲ㐴挳㔸戴攷挳挹㑤㜵愷㝡㕢敦㌲愳㌲戸戳㉢戵㉥㕦攳〸捤㥦昶㌶㔸戴攱晢摣挱ㅡ㔷昸づ㑢晡〴挰捥㔳㔶搵昷〲捦っぢ㘵昸㌶〵㕥戶㤸昰㜲挷戵户㠰戱攷㌷戹戱㤴换换㑣挹攸散㈵搷扢散捡搵㘸〱敦㥣㈴扤〶〶昸ㄹ晡扥戲㝣〳㔴捣搳㔴昲㘵㝤ㅡ㘰㈸㤹愷慤㘱挹搳摥戰攴㘹㕣㔸昲㌴㌰㉣㈳㌴〹挴㐲㔱扡愹㈵㑦㐳㐲㙥愶㑦〲っ㤷㈶㉡㙤摥㐸㝡〶㝤㌹昴㐹㝢㝢ㄶ㜷㌵改挷搰戳つ㍤㥤户扢㜹㕡㈲㘲㔹扢〳搵㑦愱愹㔰攰㈵㈱㑥挷ㄳ㌸㈹㝦ㅣ㠰㐵ㄹ㈷挰㕦㍦づ挰挲㐶扥〴㈰〹㌴㡦捡㔰㔲㈳㥤ㅥ搹㌸慦搳戶攰㔱㘸㐳挷捤搶〹摣㔴㌵㜸㡡㈵㜱㙥㘸㜲ㅢ㈹昵攱捤攱愲慤愱〵㤶晦㌷㈱ㄶ㕦〱て昷戹㈶㡡挴㜸㌷晥晡㔹〰㠵㠴㘳戶㔵摦㑢㜰㉦挱㍥〰攵つ㝣戲㘷扥昲昵㜸愰㍢㕦㤹㈷搱㈵㈱㥦㈰㤲㈷〹扥〷㤰搵㐸搸晢㌷愶㐲攴㔹慤摤㠳㌲㜱愲㤹㔴摡㐱㌳扡㠶㈴㉤㘴㠲捡㤶ㄲ㥦㠳㤳攵攳㈶㜲ㄶ㜱〳㕣㉢摣慤挷昲㠱㜸㠲㠷㕤昳ㄸ搷㘵㡢㉦愷捤㌹ㅦ攷晡㠰㌹ㄳ㈰㍡愹㘵㤰摥て㜱㌳散㙥㠵挳〷㌶㈸㐵㤹㠱搴㌰愷愸昶㔴㝦敡㜵昷戱摦ㄶ㠲慤搱愳ㄹ㠶慢昴捤㌶㜷昴愴㥦挲挷搶慥愴愴扤〹㔴攵㤷攰㍢捤㔳昶ㅦ〷㙦晦㠲换㠵晦㤷搰㥦挶㐳㑡㡤㈲昷㠰散愴㕥㘱ㄷ㜳㤶ㄲ㈴㌴㡡㔹昷愶㘸㠸愷昸㐶搷㐵摡攰㈰㜷扡昰攲㕢挷晦㝢攸改㜱㠵㤲㐴㝤㔴㕥挱㠷愹〴戴ㅦㄹ㌵慤㔰扡攴挰捦攳〱㥡㠴っ晣㔶㑡㥣ㅣ㜸㌹ㅥ愰㑤搰㙢〰ㅡ㤷㝡挳㌴愴捡㙣昲㘴ㄳ㜸㔵㈱ㄱ愴慤㠱㕤㤷ㄵ㌶㐶戸㡥ぢ昸慢慢㑡昵㤹摡㌳捦㝣㌶㤲㉡散㑥㍤㜱㍣昷攲㕦摥晢昰㠵昷扦㝦散慦㥦扦昴搲晢ㅦ扤㜰敤昳户ㄷ㡦晤攱戵搷摥㜹散㤵㙢ㅦ㙥㌷㕦㔵㝦昵搹散慢㔷挶㉥㕤㜹捥㍣㜷晦昴㤵㈷㥦㍤㌳㌶扦㙤㌴㤹ㅣㄸ搸户攳摤摢敥换晦昰戹摦㈸扦晢昳慤慥㈲扦㡤て戴㑣ㅣ敡昰挲〰愴㘶㉥愱㌲㤴㔴昸㤰㐴晡㐹㑣愴〹㜴㘴㤴挴攰晦〰〶㤵㜳晥
A28: Decisioneering:7.0.0.0 | B28: Decisioneering:7.0.0.0 | C28: Decisioneering:7.0.0.0
B29: CB_Block_0 | C29: CB_Block_0
B30: 㜸〱敤㕣㕢㙣ㅣ㔷ㄹ摥㌳摥㕤敦慣敤搸㡤搳愶㈹愵㌵㤴戶㔰〷㌷㑥ㅢ㑡㠱㄰㝣㘹ㄲ户㑥散挶㑥㑡㔵搰㘶扣㝢㈶㥥㘶㘷挶㥤㤹㜵攲㔲愹〵捡㑤摣㈴㙥愲㔰㉥慡㄰ㄲ㉦㕣㕥捡昵〵〹〹㠴ち攲〱ㅥ㤰㜸㈸ㄵ㠲〷㄰㡡挴ぢて㐸昰㝤㘷㘶㜶㘷㜶扤㘳㜷摢㠲㡢㝣搲晤㝤收摣收㥣昳㕦捦晦㥦㘹㑥攴㜲戹㝦㈳昱㉦㔳㥥㤹敢㤷㌶晣㐰摡ㄳ㌳㙥扤㉥慢㠱攵㍡晥挴㤴攷ㄹㅢ昳㤶ㅦ昴愱㐱戱㘲愱摥㉦㔴㝣敢㔱㔹慡慣㑢捦㐷愳㐲㉥㔷㉡改ㅡ敡㌹〸㝦㈳昱㠳捥㕥㠳㜹㠰攵㤹改㠵㤵㠷㌱敡㔲攰㝡昲攰搸戹戰敦搱挹挹㠹挹㠹㍢敦㥡㝣换挴愱㠳㘳㌳㡤㝡搰昰攴㔱㐷㌶〲捦愸ㅦㅣ㕢㙣慣搴慤敡㝤㜲㘳搹扤㈸㥤愳㜲攵搰ㅤ㉢挶㥤㙦㥤扣昳挸ㄱ昳敥扢摦㍡㠸㔷攷㑥捦㑣㉦㝡搲昴㕦愶㌱ぢ㥣昲㥤戳戲㙡㜱㙤㔲㝡㤶㜳㘱㘲㘶ㅡ晦㈵收㡦愷扢㈶㤶㔶愵っ昸㙡改㐹愷㉡㝤ㅤㅤ〷散㈹摦㙦搸㙢摣㍣摤㍥㡥愵㔶つ㍦㈸搸㌳戲㕥搷敤㜸搴㤲扤㠰扤慢ㅢㅢ㠳昶㤲㜴㝣㉢戰搶慤㘰愳㘸㉦㘳愰摡㤰㝤搶㤷㘷っ攷㠲㍣㙤搸戲㘰㥦㘸㔸戵㝣㤸㜲㝤户挶㐳㈴㈷愶㤶㍦㌱攵摢㌳慢㠶愷㘶攴㜳㘳㌲摡ㅥ昷慡改戶㌷㜵ㅦ㤷㔳㔷㙦攰㤸㌷㜷㙦㠷㥡㜳㠶搷㙣㌹摥扤㘵戴昸昴っ㙥敦摥㍥戱㐷改㍥㙦敡摥㐷㙤㘵扡戵ㄸ㠸攸㕢敤㈸ㄶ愳ㄷ〹晡〹㑡〴㐴愰㕥㈶ㄸ㈰ㄸ〴㄰昹㝦㠰㑢㤲ㅤ㔹愵㔵っ慤戲愲㔵慡㕡愵愶㔵愴㔶㌱戵捡〵慤戲慡㔵㉣慤昲戰㔶戹㠸㌶㜱㉡昵昷㙢㔱摡晦敢㍦っ㕦㥣㕢㤸㝢晦㝤ㅦ㍥晤捥㠷ㅥ晢晤攰ㅥ㌴扡㍦㥡搴慣㘷㕣〲愹戵愸昸昰挴㈱晥摢㥡㉢挰ㄴ收ㄱ昳㉥㜳㜲戲㜶攴㤰㜱㠷㔱攰戲㌲㤰㥦㈲㤴ㄱ戴ㅤ㌴ㅦ戰㥣㥡㝢㐹攱敥晡㘹挳㤷慤㡤ㅢ㡦敡愶摤㠶㔳昳㕦戳㜹攵㔲㘰〴昲扡昶扡搶㈰ㅤ摤㤶挰㔶搲㔷敦扢愱扤摢㌹愳摥㤰㔳㤷慤戰晡戵㙤搵昶愲攷慥㜴慦㍤敥挹㐷㥡戵ㅤ㌳㥡㠲㔰㕢㔷㘳㜷慣㌲慣ち攷㌵㌶戳敡晡搲㔱搳ㅢ户ㄷ慤敡㐵改㉤㐹㡡㐴㔹㔳㑢扤㥡㔵ㄱ搷㡦㉦㌸㔸㈸戸戵昶晡㘴愹㜹捦攵〰捣㉣㙢㤸敦㥡昴㠲㡤㘵㘳愵㉥慦㐹㌵〹摦㠹㡡〳愹攲攳㙥戵攱捦戸㑥攰戹昵㜴捤㔴㙤摤㠰愴愹㥤㜲㙢㌲㥦捦㈹愱〰㠱摢搷㈷㐴敥戶敥扣愰㄰㤱㐰㌱ㄹ昹摡㌴搹㑤㥣挱敡戰㡡扡㈴㑤㙡㙦搸㘲㌰捥㔷挹㤸っづ㑣慣㠹晡㠳㉦㝤攳ㄶ挳㌶㌱昷捡㌶搶戴搱㘸昵昷慣㑢㈷㌸㘹㌸戵扡昴㌲戵㥦攰㡣昴㘱㠰挲ㄵ〸㠴慥扢㐷㔵㈷㉥㡢㡤挲㈵慢ㄶ慣ㄶ㔷愵㜵㘱㌵㐰ㄹ㌴㘴愹挴慤敤㐸晡㔵㈸搲昷ㄲ㡣〲㤴换戹攲㍥㌶㉡㤶㤱㜲〵㑡愷っ㕥㑥〹㜲昶㑢昱昲愰㜹摣慡〷㌲ㄴ捡挳㈶㌰ㄲ㙡㌵㠵扥㈱㤲愸㘷㔴㐳㠵戱捦㥣〱㤵ㅡ㤶ㄳ㙣戴昸戶㠳㑢㐲㈲摡㤵〵㍢㑥ㄶ㔰ㄴ愴攵㐱〶慦㠱㘸摡愴㐱㜶攳〴ㄱ㤱つ㌲㌴㍢㐶㑥ㄳㄹ摢㘷挸〸戴㑦ㄲ㈱㕢ㅦ敡㉥㈳㐸散㥤㐴捡㑥㕤昹㜱㔷㥡㙤㘶换㠷搲散㙡㙣㥣㝥つ挱㝥㠲㙢〹づ〰㠸㍦㐳挲㔱捡㈱㥦㑥晡㙢昰慣㕦㑦昰㕡〰挸㈷㥤㌲㈷ㄲ㔵戴愱戶㘳㐷戲摤㄰散㘴㘵ㄴ㠷愲㠸㤶㜱搳捥ㅣ戲ㄵ愲㈳慢㜳㘷攸摡扣搲戱户㜴愷捤攴㜲㐸㤱ㄹ㑤㤳㙢摤愲㘹㜲㈳搸戴㐷扤㜵㈳扡敡㘳〴慦〳㈸敢慦㈷㠴㜲愱挱扢㍤㡢㥥㈶攵慢挲㉣ち㡤愱ㅥㄵ㝣㐴挸㍣〲㘴〸戹㡥攳换慥つ㑤㜳㜰摣㝣搵摢搰〷扢昳㜷㠴昴㌶扤戹慢㜷攸㉦㝡㤱㔶昴㑤㘰㉦昱㠷慥㍡收㘶㔴敢户㄰摣ち搰愶㘳㜸晡㝥戱㥥〲㘵ㄶ摢〹捣敤愵搷㐵㔹戹换ㅢ㙢㔲㘹愰㐱㜳搹昰㉥挸〰ㅥ㡣戹㔹搸挲慥攷挹㍡づ戵㌵㔵挰昳换晥㜴愱㝦摣㜳㙤㤶敦摡挸晥慢㐲㌱攴昳㕡㕦慥捤㐶捥戰㌵ㄳ㍥愷〴攵㔰〷摦搱㕤㐸㈴㍡愵挹㡢晤戲捦㤷扢㤲愴〷㐹昲㈶㙣慢㝥ㅢ〰愴㠴昸㕤㔷㠹㜲㤰捤摥慣㥡愵㉤㔶㝡昸㌲㑥㈷㙤㍥挴づ㌹㌲㄰㍡㙣愷攱㍦昰㠷散㈵换㙥ち㡢〱㝢㔱㝡㔵昸ㄶ慣扡㉣㠷㙥㔹㡡㥡㕤㔹昱㉡㤱ㄵ㝤㝤ㅤ攷改っ晦㥡愲㤳㌶㈹㤱挹敤㤹㤵ㄹ㘷昱ㄶ㔱搱つ㐹愱㤲攱ㅡ㙡㑡㈰㔲ㅥ摢敥㡡㤸ㅥ㐴捣敤搸㌸晤㄰挱㈴挱㘱㠰挲慦㈰㘹戶扢昱っ㠷昵慦搳愵㕤愹攴㑡㐴㠳㜲ㄱ㍥搷㔵㔸ㅤ攱㙢摥㐲㜰ㄷ㐰㥢昹㐳〷㘴〶㈱㉡㤴㈷〸㔱㠵㌱捣㜳㤶扣㐴ㅡ搸㘳㈲戰㌴搳昰〳搷㘶㘴㘹挸㥣㜵㑦扢挱慣攵慦㈱ㄲ㌵㙡㐶㤹〷㔶愵〳敡昲㘰晢戴㤵戹㙢㙢戲愶㥢㑢㙥〳愲㙤㙥㜶㈷ㅣ捣戱ㅤ戰㈵搵搹㕣ㄳ㐸扤㥤㡦㌱㠴挰㑥㉢㝦㉢扤戱摢昲㝥昳搰㌷摣摡搱㘵㉢愸换〱㌳㘴㍡收㑢㈶㜶ㄱ㤱㠳㕡扦戹扣敡㐹㌹㍢㘴㥥昰慣㕡摤㜲㈴㤱〱ㅢ㤳挱扡㜹㜹〱㔱㠲㐵㤷㌱㐰搷ㄹ㌲㤷㍤挳昱搷っ〶ㄴ㌷昶愶㥥㔴㔸愴㘰㑥㕢㡥㡦搷㈸㉣㌲㍦㙣㉥慤扡㤷㄰戱㙤搸捥〹㘳捤摦ㄱ㔸㈱搱㠷㐹愱㐶㘸㐲搳㐴㐹㉢昵㡡ㅦㅥ挸㜳㌹昲㕥㥥㐰攱㉡㔷愰捦㍣㐳㝢搳慥㡦㘲㌴戴搳㌹愷㐱㐴㡦㥡㠵㝤㤹㔲㤸㥣慡摦捤㍥㙦〳戸昷挴搹戹㔶㘴敥㈵挵慣ぢ昴昲㘷挸㜸㐵ㄶ捤㐰〸㝤㜴㝢㐲㔲㘱ㄹ㈹〷ㅣ〸㡣昳愹㥤晣捡愶㙡㐳敡摢搳捡ㅥ㐷㈴㘹搰㥣㌷㔶㘴ㅤ昱㘸摢〸昶㠴て㌴㘳㙤愳敥㐷㜵㌳慥㙤ㅢ㈴㉤㤲攵㔲搵㈰〵㑦㌵〲昷㤴攵攸㈶㠰愲扦愸挸戸㡣㈲攳戲㉡ㅡ㌴捦㌰㌴愸昲ㅣ换扤㘰㜸㔶戰㙡㕢搵ㄲㅦㄸ扥摢ㄱ㌴〹㈶愷攴㡤㔳㉣㌳挶摡慣昹戳㌰搹晣〹愰㝢〲㜲㤴㕢㐷昴㠳㜲㌵㔱挴㍦搱愳㘳〹〲㐶㜹㑡昵㜷㘰戴㠲扡ㅤ〱㤱愳搲㤵昸づ挶㤵挷㔱ㄲち㈱㘲㍤㠳㐴攰ㄵ㑣〸㜹扡戸㡢收㔹挷ち㠰㍤㘲散戸ㄵ捣晡㐰㌹〰戲敡㜸㝢㥤挲㙡愲搳㜸㔳㉢摣搸㔹㤵㔲ㄳ㌷㜴搶㈷昵挶ㅢ㌶愹づ㌵㑡㐲㤱㙣搵㐸㘹㤶㑤收戸㤳㔴㡤㔰㡡㍢搶㌶㈲换㙤摡摡㜷㑡㤱㤷愰㤸ㄴ捤攴昴㜷㉡㐲㐱愰㌷搲㔱昴搹㘷㤳㐷㈲㘲㐳ㅢ愰㑣㍤ㄵ㤶つ㐵㈱挱㌹㕣㍢愹挹㜲昴〴晥摥ㄳ㘵ㄷㅡ㐱慡挶戸㍣ㅡ搵㑣搵敢ぢづ慣㠴慡攱搵㜶〸㑢㘳㙤愱㠶㔱摣搹慢昶て户㌷挱㠸ㄱㅢ㌲㉣㤲攱〷〶ㅢ㠲戹ㄲㄱ㔵㕡㘷㐳摣敡㘶㜱㠹㑦愷愴攱㈸っ㉣〵戵㔹戹慥捣戰㤶㈵㍦慡㍡㌴㑦㡢㑡㡥敡收搴㡡て㤵ㅥ㔰㡥㐷㌹挵攰扡㜹㠶㙥㈹㕣㘲㠰搸㡤㜲㡢搵〰愱摤收〰㍣ㄹ散ㅣ散㘰㐷挲搰〹慤㌳㑡搰㘲〶攱愶ㄷ㐱摥改ㄱ愳㄰愴愶㑡㝦㍦㈶扥昴ㄴ搳户㡥攵攲㑣挴㐴っ㜷㘵㔸て㐰㙥㌲㌲㐹㉥ㅡ㡤〳收愱㘴㔳㐲㙢㌰㉥愳㠹㌱㐴㤳捦ぢ㜰㡢㠷戱慣㘱戲㑤ㅤ昷摣〲ぢ摡戴扥戱挷㥣㜳慡昵㐶㑤㉡㔵ㅣ换㙡愵㤱㜷〴扥搴ㄵ挰㤰㥢㌲昶㈵摡㤴㌹ㅣ愵戸㘴㈲愹㜷扢㕢㍦㠶敥㑡挸㘱㡣㔰昵㌱〰㤹攱㤶㔳〱戱㡥㝢ち戴て昷戶㉥㌰愸换㜳㄰㘹ㅤ㐵㤴㘵昳戸㡦搷㡣㈲㉢㙥㑢㌴㥢㜷攷㕤摡散㠹愲㤳㔶㔸戴㈳㜰㠴㜵㠶〲慦㔸㠴㌱搲㈳㜷㜰㤰摣㤵㈸扡㝢攵㜱昵㤸扢〲㔴㈸っ〸挶㜸㜹ち捡㘱㔷挱㐸㌴戸戵㤶搵㉤ㄸ晤愵攵慤㑦〱〸㠶㠱㘹搰愲㘵㘸攰捣㈰扦戵㠱㜳㈳㕡㘵㐴㐸㤳挱㔴挶㈸㐷攱戰〷搲挰㑤㍣㐸㉦扢㔰㐲挱㍥㜵㌱㉣扥㥢㌸㙥攳〸攴㝡搷戴ㄵ㉥ㅡ〱慥扦㌸〷摡㡡愷㙡㌵㥡扢昰捦敤〸慣攲敡㐶㘸㡥敥㙢扢㤴愵搶㐴晢敥愶戶㡡攸戲攰攱搹㠹㤳㐶㔰㕤㕤ち㌶挲㡢㕢扤㤲㐴攱㈷昰㐷㙣晡㜶摡捣㜹㠷ㄷ㔱搷戹昷攵㡢㡥㝢挹㔱昳㉡昸扣昵〷ち挱ㄵ捡㝥㑥戲㥣晢㌷晥愹愴攵ち㍦挶㠸摢㤹㌶〷㘸㌹㐸㌸㡥㑡愱㌴ㄸ㐳㍥㠳㑥㘰扢㌷㙦つ㤰㑥昶戵搱㠹ㄲ〴扢㠴攲㕣㜸搹〸㐵晣〸㘸㈵戱㠴㐷㜲散昹㌷挱晡攲㠷㈸㈱挲昱ㅣ㠹㤱挲敢㤰换㐰㥤ㄲ攴搱ㄵて㕥〸昹晦挱㔲捣捤㥢戲搳㝦㠱㤹挵て摡㔱㜴〳㔱昴晤づㄴ〹㕥〳㔱晣㝢㉦㌲㜱㉡㌰㍣晢愲〲攱㕣搳敥〱昴ㄵ扦昰晢㍦㍣㠰捥㐷挴愱㙣㌴㠴摡㙥挶㜳搳㐴攸敢㌰ㄱㄸ扣㔷㈶挲㈹㘴〴愳昸愱㠹㄰昹㐰ㄶ㔰戰戵㠹挰搸㕥㠶㈱㤸〸戵㈶摣ㅡ㍣㠱㕤㘳搳㍦㜶ㄲㄷ㙦愵㡦㜸㍥㤴㤶㍦〳㡦搴晥捥攲㐵挳㌳散〳慡晣㠴㈷愱捣扣㘵摣攴㔶㕤搸攳扡㑤㙢㔴愷㑤㝣ㄵ戱㤷㝤搷㥦戲扤晢敢挰㔴㤸㐲昷扤㈸㠹攲㑢昰㤴〸㥥ㅢ㜲敦摢昷敤ㄳ㝦㝣昴挹㘳扣慤ㄶ搱㙡攱㌶攴㝢〹搹搳㥥㐰㔰㌷㜱㔱攴㙡㝥㤸㜳ち㥦㈸㔹㙢㜵㌹㙤㜸捡ち昲㜵㍢捥㠶㠴㤷㈰捣㤰昸㜶㠲㠹㠹㝢て愱㠹㌹搱收敥㔴ㅦ㌶㈹ㄷ攱㐴㘲攲捡愷ㄷ㠷つ㐵㔷㐵搶愳戵㔹昸㉥㔴搱㡢㥣㐸摡㑡攴愹㤳㐹㠸敦戴敢扡㈳搴㜵攱㐱㠶㘱晦㔸㑡㈱晥㐰ち㐹ㅥ㘴㜸㈱㐰㐹愹㌳挸ㄴ㙥〷挸㠸慣戵㠷㜸改て搸ㄵ〲戲㜹改慦挷㡦㔸戰㡢挰㘲散㡢敦昵㐴㑢㕢㌴㔶㑤っ搵㉡㥢㘶〹ㄹ㜵㜸㘱挱㘴㕣㥡戲㜴づ愳㜴摢敥㈸扥㘴挸づ〳㙦㈱㘳ㄷ㙣晡摡捡昶㍤㑥〳㌷㍦愰㘷㡡㑡㘱㌸㝢㔹㡣〳愹㡡搱㠵㑤换㘱ㄱ攱㜰㤸㙤㜶ㅡ㠸慡愰戳㥣〳㌸㤵㈲昸挷㉦㠵㔸㍦摥ㅡ晡敡昶ㅡ敡㌸愷ㅦぢ攴て昶搷つㄹ㡣㡤户㤲㘳㈰㘱户搵慡ㄴ㕥て㍦㡢㉥㕣㜴㑥攸慤慣㝡ㄶ㐷昰㈷收慣㍥慤㐳晦㌳㝡慤㌸敢ㅣ㝢㌳㡣㥤搲晦敦㐶挱㤶晡㕦㌰昶愶㄰昹㘰㤴攱㐳㠱昱㤳㉤㐳㌶摣ㄱ㜸戶ㄱ扣㔱〷㘳㕤㘵ㄹ昲づ㜳㑢昸㜸㌵慣㔶ㄲㅣ㝥慦㝣晢搵㠸㘶㕦摡戶〳㕤〵㈰㘳㐳㠵㙦㐲〴㜵敤㥦㤶㕢昱改戶昸㄰㍡敥㍢㘵㔵㍤搷㜷捤㘰㙣〹㐱摦㌱㝥㝢㘶挲收㤹ㄲ摦㘸ㄷ㙡㌷㘱㈷〶摦㡢㍥愷ㄷ㈰戰㑦换攰攵㡡㐵㌲戲戰扤㐸〶扦㐳ㅡ㐹㠴㤷愸ㅤ晣慢捣晢ㅢ㐶ㅤ㥦慥㉥挰搷ㄹ戰㘸㐷㈸扢搰攳摣㝥㐳㠳㕢㠷㍢㕡昷挱ㅦ㈴敢ㄳ〸㡥愹㈵㍣昴㕥敥㙢晢ㅥ愴摢㐶㙢昳搹戲㌷㥦㕢戹昰っ㜰扡扤户愴㐹㠶敦攴ㄷ挹㘵扤㐲㠸㑢晢挷昰㜷晢づ㕡㡥㌶ち㍡㡦㍥攸愶㈳㙣扣づ昷搹㌶愲摦攷搱㔵㑣ㄱ攰愷ㅢ㔱㠶て㠲㕥㍥戲愲昸㉡㤶㐵〶㐰㍥㔷慣〲㜴愷敡愷㌷愳敡㤱㔸㈰ぢ㥥㌱㐸㡥㘵昱㘵㌴攴㜶㠵换〶㑢㜰搹㐲㥤㈵㤰搷攳ㅥ挸攷〴捦ㄲ㙡㈲㕦㐴㠷收㐴㉣㤴㜶㥦挸ㄷ㌶㥢㠸愰ㄵ愰ㄶ㥡ㅣ㝦㈴搶㈲㝡ㅤ搵扡㑤攰㄰戸〰挳ㄴ㡢㤴㌵挵㌰戴昰㐳㘲〶改㌷搱摦攷㡦晤敡㌹愶扦ㅤㄳ㑡㄰愲㉡㍤㜹ち㐲㌵昹㑦㈷㈷敦愱戴晢攴㍦戹搹攴㐷㈸㈳㌹ㄳ㍤〰ㄸ敡ㄳㄵ晣㔱㡢㘹㈰挳㝤攴㑦㥣㈷挰㉦㌵㡢ㄱ〳㈵慡敦㈵㘴搰㤷ㅢ慥㕡㕤㐶㈶敥㕢攰晡㌳㍥敥㔱昶ㄱ㉦㐲搲㤷㔳っ㥤戱挵㔰㉢㤶散挸ぢ扢㈳㘴〳㤶挴慦㘵扢㡡昴㘲㡦ㄱ㝥昱㤱ㄸ㌱㈷㑦挶㕦㑥㘹㔱捣〹㠴ㄱ㕡愴愴ㅦ㙥愴昸㜰摣昸㝢捦戶㕣愶愸㐰〲昵㠴㡤㐹㘷慡昱㠷攲挶㠷昱㔵㤶㙡㤳攳つ〲愶攷攳挶愴㐷搵昸挹戸昱㕦てㅦ㘸㌶㡥改㌰ㅣ戹㐰㈲挹戰㜵㤵昵㥦昸㐲㝢ㄸ捤ぢ㈶昵攷㠰ㄹㄶ㔳㜲慡搰㜱㕤㘹搰㐱㕣〶昱昰㡤昴㍣敥㌶攱ち〸㠴㙣昸扦㑡㤸挳㥤愷㔹㈳㌰昰〹昴㍡㠲捤㥥慥㥥搸戹㘸㉥㜸㈸攸㌷攷㝣㥣愹㙡㍢㡡㐴㘰づ攴挳晤摤挲㈹㥦㘱㍡戶昶㈳づ㤲㘹扣㐳搲㥢昲㔰㠱㤵扣昸㐰㡣搹摣ㄳ㉤㥡搱ㅦ〷㜲㈰ㅤ〱㤹搱㥦〰っ〳㌱扣慤㥣ㅢ㈱晦㉢收晥〰㉢㍥㐸昰㈴㐰㔹㤰搹㐹〷挵て〱っ挷晦愳㡡戱㜵攵㉦搱挴愳昱换㤲㘴愴㝦㠴ㅤ㍥ち搰〷昷慤㠸㠸戰慣㝦っ㈵挹㤷㔲㜰愸㤷㝥㥣ㄵ㥦㈰昸㈴㐰戹挰挹㙥㝢搷戸愶ㅥ㌵搷愷搰㔵㍣㐱㠰㥦晥改㈸挳㠷〲昷攱敤摤㙤㘵ㅥ㠵攳て晢ㄱ敡㑣㝤挱㝦て扥挸摦攰愲晢昰㍦㈴㈹㈸挳㍥慦扤慤户戱挸〴戴挹搵㙦つ㥢晤ㄲ挶攱扡㕡ㄱㄴ㡥㐸愵㔲搲㡡㠲昸收㠲㠵㡢㌷昰㉤㐷㔵㠵㄰愴〱㔵攱㐴ㄵ挷㔰愰㝦㤶㑤㠹㘳攲㐹晦ㅣ㥦㠸㕡戵㠹㥦㡦㌲㝣㄰挴慢敡晥㜰搴㍤㝥㈱㜱慤㉡慣戶ㄷㄲ晦慡㘲㌵昹挲愷㌸㤸㐲ㄶ㌲㘹慤㐴愴㈹ㅡ晡㌲㌲㐳㝤挳㥣摢〳昸㘹㤷㐵昵㝣敤晣昹㝦づ攷挷慥换扦晢㕤㠳㑦㍤晦换ㄷ㍥昳摢昷ㅣ晤换扦㥥㝥晡户㝦晡捣㜳晦晡挹捡搱㥦㍦昳捣捦敥晤摡㜳㉦散㌵扦慥㍤晢捦昹慦㍦㌶㜹昱戱㐷捣戳户㥤㜸散挱㠷敦㥦㕣扣㙡扣慦慦扦晦搶搱㕦㕣晢挶㤱㈷ㅥ昹㠱昸改敦昷㍢㐲㉤ㄷ㉦㐸㑦㠳换㔶搳昸ち㌲㤸〶㘷晣㡡㑥㠳换㔵ㅢ戵ㄲ㙤搴㌴ち㑡昰㘹㜰〲慡挲㐸㔷っ晣〷㠵扣戱昵 | C30: 㜸〱敤㕣㔹㙣㈴㐷ㄹ㥥㙡捦㡣愷挷昶摡㔹㙦㡥つ㈱㜱〸㈱㄰㉦捥㝡㤳㈵〴㔸ㄶㅦ搹㈳㜸搷捥摡扢〱〱㥡㙤捦㔴慦㍢㍢摤敤㜴昷㜸搷㈱㔲㈲〸㤷㈰㈰㜱㠷㠴㐳ㄱ㐲㠲〷㡥㤷㄰㡥ㄷ㈴㈴慥㈰昱〰て㐸㍣㠴㐳㠰〰愱㐵〸㠹〷㈴昸扥敡敥㤹敥ㄹ㑦摢㤹㈴攰㈰搷㘶㝥㔷搷搵㔵昵㥦昵晦搵挹㠹㕣㉥昷㙦㈴晥㘵捡㌳㜳捤攲扡ㅦ㐸㝢㘲挶慤搷㘵㌵戰㕣挷㥦㤸昲㍣㘳㝤捥昲㠳㍥㌴㈸㔶㉣搴晢㠵㡡㙦摤㉦㑢㤵㌵改昹㘸㔴挸攵㑡㈵㕤㐳㍤〷攱㙦㈴㝥搰搹㙢㌰て戰㌴㌳㍤扦㝣㉦㐶㕤っ㕣㑦敥ㅢ㍢ㄳ昶㍤㌴㌹㌹㌱㌹㜱摢敤㤳慦㤹搸扦㙦㙣愶㔱てㅡ㥥㍣攴挸㐶攰ㄹ昵㝤㘳ぢ㡤攵扡㔵㝤戳㕣㕦㜲捦㑢攷㤰㕣摥㝦敢戲㜱摢㙢㈷㙦㍢㜸搰扣攳㡥搷づ攲搵戹㤳㌳搳ぢ㥥㌴晤攷㘹捣〲愷㝣摢慣慣㕡㕣㥢㤴㥥攵㥣㥢㤸㤹挶㝦㠹昹攳改昶㠹挵ㄵ㈹〳扥㕡㝡搲愹㑡㕦㐷挷〱㝢捡昷ㅢ昶㉡㌷㑦户㡦㘰愹㔵挳てち昶㡣慣搷㜵㍢ㅥ戵㘴捦㘳敦敡挶晡愰扤㈸ㅤ摦ち慣㌵㉢㔸㉦摡㑢ㄸ愸㌶㘴㥦昶攵㈹挳㌹㈷㑦ㅡ戶㉣搸㐷ㅢ㔶㉤ㅦ愶㕣摦㑤昱㄰挹㠹愹攵㑦㑣昹昶捣㡡攱愹ㄹ昹摣㤸㡣戶㐷扣㙡扡敤つ摤挷攵搴搵ㅢ㌸收㡤摤摢愱收㡣攱㌵㕢㡥㜷㙦ㄹ㉤㍥㍤㠳㕢扡户㑦散㔱扡捦慢扡昷㔱㕢㤹㙥㉤〶㈲晡㔶㍢㡡挵攸㐵㠲㝥㠲ㄲ〱ㄱ愸㤷〹〶〸〶〱㐴晥敦攰㤲㘴㐷㔶㘹ㄵ㐳慢㉣㙢㤵慡㔶愹㘹ㄵ愹㔵㑣慤㜲㑥慢慣㘸ㄵ㑢慢摣慢㔵捥愳㑤㥣㑡晤晤㕡㤴扥昲㤳㍦晥昶挴㈷晦㌶昷戱㝦扣昳㔳㝦㝡㑣晣㘸㜰ㄷㅡ摤ㅤ㑤㙡搶㌳㉥㠰搴㕡㔴㝣㘰㘲㍦晦㙤捥ㄵ㘰ち昳愰㜹扢㌹㌹㔹㍢戸摦戸搵㈸㜰㔹ㄹ挸㑦ㄱ捡〸摡づ㥡昷㔸㑥捤扤愰㜰㜷捤戴攱换搶挶㡤㐷㜵搳㙥挳愹昹㉦搹戸㜲㌱㌰〲㜹㜵㝢㕤㙢㤰㡥㙥㡢㘰㉢改慢昷㕤摢摥敤㡣㔱㙦挸愹㡢㔶㔸晤搲戶㙡㝢挱㜳㤷扢搷ㅥ昱攴㝤捤摡㡥ㄹ㑤㐱愸慤愹戱㍢㔶ㄹ㔶㠵昳ㅡ㥢㔹㜱㝤改愸改㡤摢ぢ㔶昵扣昴ㄶ㈵㐵愲慣愹愵㕥捥慡㠸敢挷攷ㅤ㉣ㄴ摣㕡㝢㔹戲搴扣昳㘲〰㘶㤶㌵捣㜷㔵㝡挱晡㤲戱㕣㤷㔷愴㥡㠴敦㐴挵摥㔴昱ㄱ户摡昰㘷㕣㈷昰摣㝡扡㘶慡戶㘶㐰搲搴㑥戸㌵㤹捦攷㤴㔰㠰挰敤敢ㄳ㈲㜷㜳㜷㕥㔰㠸㐸愰㤸㡣㝣㔵㥡散㈶㑥㘱㜵㔸㐵㕤㤲㈶戵㤷㙦㌲ㄸ攷慢㘴㑣〶〷㈶搶㐴晤挱㤷扥㜲㤳㘱㥢㤸㝢㘱ㅢ㙢摡㘸戴晡㍢搷愴ㄳㅣ㌳㥣㕡㕤㝡㤹摡㑦㜰㐶晡㌰㐰攱ㄲ〴㐲搷摤愳慡ㄳㄷ挵㝡攱㠲㔵ぢ㔶㡡㉢搲㍡户ㄲ愰っㅡ戲㔴攲搶㜶㈴晤㌲ㄴ改扢〹㐶〱捡攵㕣㜱てㅢㄵ换㐸戹〲愵㔳〶㉦愷〴㌹晢愵㜸㜹搰㍣㘲搵〳ㄹち攵㘱ㄳㄸ〹戵㥡㐲摦㄰㐹搴㌳慡愱挲搸㘳捥㠰㑡つ换〹搶㕢㝣摢挱㈵㈱ㄱ敤挸㠲㙤㈷ぢ㈸ち搲昲㈰㠳搷㐰㌴㙤搲㈰扢㜱㠲㠸挸〶ㄹ㥡ㅤ㈳愷㠹㡣敤㌳㘴〴摡㈷㠹㤰慤昷㜷㤷ㄱ㈴昶㑥㈲㘵愷慥晣戸㈳捤㌶戲攵㐳㘹㜶㌹㌶㑥扦㠲攰㑡㠲慢〸昶〲㠸摦㐳挲㔱捡㈱㥦㑥晡㑢昰慣㕦㐳昰㔲〰挸㈷㥤㌲㈷ㄲ㔵戴愱戶㘲㐷戲摤㄰散㘴㘵ㄴ㠷愲㠸㤶㜱搳捥ㅣ戲ㄵ愲㈳慢㜳㝢攸摡扣搲戱慦攸㑥㥢挹攵㤰㈲㌳㥡㈶搷扡㐹搳攴㐶戰㘹㡦㝡敢㍡㜴搵挷〸慥〷㈸敢㉦㈳㠴㜲愱挱扢㌵㡢㥥㈶攵㡢挲㉣ち㡤愱ㅥㄵ㝣㐴挸㍣〲㘴〸戹㡥攳换㡥つ㑤㜳㜰摣㝣搱摢搰晢扡昳㜷㠴昴㌶扤戹愳㜷攸㉦㝡㤶㔶昴つ㘰㉦昱慢慥㍡收㐶㔴敢慦㈰戸〹愰㑤挷昰昴晤㙣㍤〵捡㉣戶ㄳ㤸摢㑤慦㡢戲㜲㤷搶㔷愵搲㐰㠳收㤲攱㥤㤳〱㍣ㄸ挷㘷㘱ぢ扢㥥㈷敢㌸搴搶㔴〱捦㉦㔷愶ぢ晤㈳㥥㙢戳㝣挷㐶昶㕦ㄴ㡡㈱㥦搷晡㜲㙤㌶㜲㠶慤㤹昰㌹㈵㈸㠷㍡昸搶敥㐲㈲搱㈹㑤㕥散㤷㝤扥摣㤱㈴㍤㐸㤲㔷㘱㕢昵㥢〱㈰㈵挴㉦扡㑡㤴㝤㙣昶㙡搵㉣㙤戱搲挳㤷㜱㍡㘹昳㈱㜶挸㤱㠱搰㘱㍢つ晦㠱㍦㘴㉦㕡㜶㔳㔸っ搸ぢ搲慢挲户㘰搵㘵㌹㜴换㔲搴散挸㡡ㄷ㠹慣攸敢敢㌸㑦㘷昸搷ㄴ㥤戴㐹㠹㑣㙥捦慣捣㌸㡢户㠸㡡㙥㐸ち㤵っ搷㔰㔳〲㤱昲搸㜶㐷挴昴㈰㘲㙥挱挶改晢〹㈶〹づ〰ㄴ㝥ち㐹戳搵㡤㘷㌸慣㝦㡤㉥敤㑡㈵㔷㈲ㅡ㤴㡢昰改慥挲敡㈰㕦昳ㅡ㠲摢〱摡捣ㅦ㍡㈰㌳〸㔱愱㍣㐱㠸㉡㡣㘱㥥戱攴〵搲挰㉥ㄳ㠱愵㤹㠶ㅦ戸㌶㈳㑢㐳收慣㝢搲つ㘶㉤㝦ㄵ㤱愸㔱㌳捡摣戳㈲ㅤ㔰㤷〷摢愷慤捣㕤㕤㤵㌵摤㕣㜴ㅢ㄰㙤挷㘷户挳挱ㅣ摢〱㕢㔲㥤捤㌵㠱搴摢昹ㄸ㐳〸散戴昲户搲ㅢ扢㈵敦㌷て㝤挳慤ㅤ㕤戲㠲扡ㅣ㌰㐳愶㘳扥㘴㘲ㄷㄱ㌹愸昵㥢㑢㉢㥥㤴戳㐳收㔱捦慡搵㉤㐷ㄲㄹ戰㌱ㄹ慣㥢㤳攷㄰㈵㔸㜰ㄹ〳㜴㥤㈱㜳挹㌳ㅣ㝦搵㘰㐰㜱㝤㜷敡㐹㠵㐵ち收戴攵昸㜸㡤挲㈲昳挳收攲㡡㝢〱ㄱ摢㠶敤ㅣ㌵㔶晤㙤㠱ㄵㄲ㝤㤸ㄴ㙡㠴㈶㌴㑤㤴戴㔲慦昸攱㠱㍣㤷㈳敦攵〹ㄴ慥㜲〵晡捣㌳戴㌷敤晡㈸㐶㐳㍢㥤㜳ㅡ㐴昴愸㔹搸㤷㈹㠵挹愹晡ㅤ散昳㍡㠰扢㡥㥥㍥摥㡡捣㍤愷㤸㜵㠱㕥晥っㄹ慦挸愲ㄹ〸愱㡦㙥㔷㐸㉡㉣㈳攵㠰〳㠱㜱㍥戵㤳㕦搹㔴㙤㐸㝤扢㕡搹㈳㠸㈴つ㥡㜳挶戲慣㈳ㅥ㙤ㅢ挱慥昰㠱㘶慣㙤搴晤愸㙥挶戵㙤㠳愴㐵戲㕣慣ㅡ愴攰愹㐶攰㥥戰ㅣ摤〴㔰昴ㄷㄵㄹㄷ㔱㘴㕣㔴㐵㠳收㈹㠶〶㔵㥥㘳戹攷っ捦ち㔶㙣慢㕡攲〳挳㜷摢㠲㈶挱攴㤴扣㜱㡡㘵挶㔸㥢㌵㝦ㅡ㈶㥢㍦〱㜴㑦㐰㡥㜲敢㠸㝥㔰慥㈶㡡昸㈷㝡㜴㉣㐱挰㈸㑦愹晥〶㡣㔶㔰户㈳㈰㜲㔴扡ㄴ摦挱戸昴㈰㑡㐲㈱㐴慣㘷㤰〸扣㠲〹㈱㑦ㄷ㜷搱㍣敤㔸〱戰㐷㡣ㅤ戱㠲㔹ㅦ㈸〷㐰㔶ㅤ㙦慦㔶㔸㑤㜴ㅡ㙦㙡㠵敢㍡慢㔲㙡攲摡捥晡愴摥㜸昹〶搵愱㐶㐹㈸㤲捤ㅡ㈹捤戲挱ㅣ户㤳慡ㄱ㑡㜱挷摡㐶㘴戹㑤㕢晢㑥㈹昲ㅣㄴ㤳愲㤹㥣晥㐶㐵㈸〸昴㐶㍡㡡㍥晢㙣昲㐸㐴㙣㘸〳㤴愹愷挲戲愱㈸㈴㜸ㅣ搷㑥㙡戲ㅣ㍤㠱扦㜷㐵搹昹㐶㤰慡㌱㉥㡥㐶㌵㔳昵晡扣〳㉢愱㙡㜸戵㙤挲搲㔸㕢愸㘱ㄴ㜷昶慡晤挳敤㑤㌰㘲挴㠶っ㡢㘴昸㠱挱㠶㘰慥㐴㐴㤵搶搹㄰户扡㔹㕣攲搳〹㘹㌸ち〳㡢㐱㙤㔶慥㈹㌳慣㘵挹㡦慡づ捤搳愲㤲愳扡㌹戵散㐳愵〷㤴攳㔱㑥㌱戸㙥㥥愲㕢ち㤷ㄸ㈰㜶愳摣㐲㌵㐰㘸户㌹〰㑦〶摢〷㍢搸㤱㌰㜴㐲敢㡣ㄲ戴㤸㐱戸改㐵㤰㜷㝡挴㈸〴愹愹搲㕦て㡢捦㍣捡昴攵挳戹㌸ㄳ㌱ㄱ挳㕤ㄹ搶〳㤰㥢㡣㑣㤲㡢㐶攳㠰㜹㈸搹㤴搰ㅡ㡣换㘸㘲っ搱攴昳〲摣攲㘱㉣㙢㤸㙣㔳挷㍤户挰㠲㌶慤慦敦㌲㡦㍢搵㝡愳㈶㤵㉡㡥㘵戵搲挸摢〲㕦敡ち㘰挸㑤ㄹ晢ㄲ㙤捡㜱ㅣ愵戸㘴㈲愹㜷扢㕢㍦㡣敥㑡挸㘱㡣㔰昵㌱〰㤹攱㤶㔳〱戱㡥㝢ち戴て㜷户㉥㌰愸换㜳㄰㘹ㅤ㐵㤴㘵㜳戸㡦搷㡣㈲㉢㙥㑢㌴㥢㜳攷㕣摡散㠹愲㘳㔶㔸戴㉤㜰㠴㜵㠶〲慦㔸㠴㌱搲㈳㜷㜰㤰摣愵㈸扡㝢改㐱昵㤸扢〴㔴㈸っ〸挶㜸㜹ち捡㘱㔷挱㐸㌴戸戵㤶搵㉤ㄸ晤愵攵慤㑦〱〸㠶㠱㘹搰愲㘵㘸攰捣㈰扦戹㠱㜳ㅤ㕡㘵㐴㐸㤳挱㔴挶㈸㐷攱戰〷搲挰㑤㍣㐸㉦戹㔰㐲挱ㅥ㜵㌱㉣扥㥢㌸㙥攳〸攴㝡㔷戴ㄵ㉥ㄸ〱慥扦㌸㝢摢㡡愷㙡㌵㥡扢昰捦㙤ぢ慣攲敡㐶㘸㡥敥㘹扢㤴愵搶㐴晢敥㠶戶㡡攸戲攰㠱搹㠹㘳㐶㔰㕤㔹っ搶挳㡢㕢扤㤲㐴攱扢昰㐷㙣昸㜶摡捣㜹㠷ㄷ㔱搷戸昷攵昳㡥㝢挱㔱昳㉡昸扣昵〷ち挱ㄵ捡㝥㑥戲㥣晢㌷晥愹愴攵ち摦挱㠸㕢㤹㌶〷㘸㌹㐸㌸㡥㑡愱㌴ㄸ㐳㍥㠳㑥㘰扢㌷㙦つ㤰㑥昶戴搱㠹ㄲ〴㍢㠴攲㥣㝢摥〸㐵㝣ㅢ㘸㈵戱㠴㐷㜲散昹㤷挰晡攲㕢㈸㈱挲昱ㅣ㠹㤱挲昵挸㘵愰㑥〹昲攸㡡〷㉦㠴晣晦㘰㈹收收つ搹改扦挰捣攲愹㜶ㄴ㕤㑢ㄴ㝤戳〳㐵㠲搷㐰ㄴ晦摥㠵㑣㥣ちっ捦㍥慢㐰㌸搷戴㜳〰㝤挱㉦晣晥てて愰㜳ㄱ㜱㈸ㅢつ愱戶ㅢ昱摣㌴ㄱ晡㍡㑣〴〶敦㤵㠹㜰〲ㄹ挱㈸㝥㘸㈲㐴㍥㤰㜹ㄴ㙣㙥㈲㌰戶㤷㘱〸㈶㐲慤〹户〶㑦㘰㔷搸昴㡦ㅤ挳挵㕢改㈳㥥て愵攵捦挰㈳㜵㘵㘷昱㠲攱ㄹ昶㕥㔵㝥搴㤳㔰㘶摥ㄲ㙥㜲慢㉥散㜱昵㠶㌵慡搳〶扥㡡搸换扥攳㑦搹摡晤㜵㘰㉡㑣愱晢㕥㤴㐴昱㌹㜸㑡〴捦つ戹㜷敥昹敡搱㕦摦晦昰㘱摥㔶㡢㘸戵㜰㌳昲扤㠴散㘹㑦㈰愸㥢戸㈸㜲㌹㍦捣㌹㠱㑦㤴慣搵扡㥣㌶㍣㘵〵昹扡ㅤ㘷㐳挲㑢㄰㘶㐸㝣摢挱挴挴扤㠷搰挴㥣㘸㜳㜷慡て㥢㤴㡢㜰㈲㌱㜱攵搳㡢挳㠶愲慢㈲敢搱摡㉣㝣ㅤ慡攸㔹㑥㈴㙤㈵昲搴挹㈴挴搷摡㜵摤㐱敡扡昰㈰挳戰㝦㉣愵㄰㝦㈰㠵㈴て㌲扣㄰愰愴搴㈹㘴ち户〰㘴㐴搶摡㐳扣昴〷散〸〱搹扣昴搷攳㐷㉣搸㐵㘰㌱昶挵昷㝡愲愵㉤ㅡ慢㈶㠶㙡㤵㑤戳㠸㡣㍡扣戰㘰㌲㉥㑤㔹㍡〷㔰扡㘵㜷ㄴ㕦㌲㘴㠷㠱户㤰戱ぢ㌶㝤㙤㘵晢㑥愷㠱㥢ㅦ搰㌳㐵愵㌰㥣摤㉣挶㠱㔴挵攸挲愶攵戰㠸㜰㌸捣㌶㍢つ㐴㔵搰㔹捥㕥㥣㑡ㄱ晣攳㤷㐲慣ㅦ㙦つ㝤㜹㝢つ㜵㥣搳㡦〵昲〷晢敢摡っ挶挶㕢挹㌱㤰戰㕢㙡㔵ち慦㠷㥦㐶ㄷ㉥㍡㈷昴㔶㔶㍤㡢㠳昸ㄳ㜳㔶㥦搶愱晦ㄹ扤㔶㥣㜵㠶扤ㄹ挶㑥改晦户愰㘰㔳晤㉦ㄸ㝢㔳㠸㝣㙢㤴攱㐳㠱昱㤳㑤㐳㌶摣ㄱ㜸戶ㄱ扣㔱〷㘳㕤㘵ㄹ昲づ㜳㡢昸㜸㌵慣㔶ㄲㅣ㝥慦㝣晢搵㠸㘶㕦摡戶〳㕤〵㈰㘳㐳㠵㉦㐱〴㜵敤㥦㤶㕢昱改戶昸㌶㜴摣㜳挲慡㝡慥敦㥡挱搸㈲㠲扥㘳晣昶捣㠴捤㌳㈵扥搸㉥搴㙥挰㑥っ扥〳㝤㑥捥㐳㘰㥦㤴挱昳ㄵ㡢㘴㘴㘱㙢㤱っ㝥㠷㌴㤲〸㉦㔱㍢昸㤷㤹㜷㌷㡣㍡㍥㕤㥤㠷慦㌳㘰搱戶㔰㜶愱挷戹晤㠶〶户づ㜷戴摥っ㝦㤰慣㑦㈰㌸愶㤶昰戶㜷㜰㕦摢昷㈰摤㌶㕡㥢捦㤶扤昹摣捡㠵㈷㠰搳慤扤㈵㑤㌲㝣㈷扦㐸㉥敢ㄵ㐲㕣摡㍦㡣扦㕢㜷搰㜲戴㔱搰㜹昴㐱㌷ㅤ㘱攳㜵戸捦戶㄰晤㍥㡢慥㘲㡡〰㍦摤㠸㌲㝣㄰昴昲㤱ㄵ挵攷戰㉣㌲〰昲戹㘲ㄵ愰㍢㔵㍦扥ㄱ㔵㡦挴〲㔹昰㡣㐱㜲㉣㡢挷搰㤰摢ㄵ㉥ㅢ㉣挱㘵ぢ㜵㤶㐰㕥㡦㝢㈰㥦ㄳ㍣㑢愸㠹㝣ㅡㅤ㥡ㄳ戱㔰摡㝤㈲㥦摣㘸㈲㠲㔶㠰㕡㘸㜲晣㤱㔸㡢攸㜵㔴敢㌶㠱㐳攰〲っ㔳㉣㔲搶ㄴ挳搰挲户㠸ㄹ愴㥦㐵㝦㥦㌹晣搳愷㤹晥㜲㔸㈸㐱㠸慡昴攴㈹〸搵攴㍦㤲㥣扣㠷搲敥㤳㝦㘴愳挹㡦㔰㐶㜲㈶㝡〰㌰搴㈷㉡昸愳ㄶ搳㐰㠶晢挸㥦㌸㑢㠰㕦㙡ㄶ㈳〶㑡㔴摦ぢ挸愰㉦㌷㕣戵扡㠸㑣摣户挰昵㘷㝣摣愳散㈳㕥㠴愴㉦愷ㄸ㍡㘳㡢愱㔶㉣搹㤱ㄷ㜶㕢挸〶㉣㠹㕦换㜶ㄵ改挵ㅥ㈳晣攲㝤㌱㘲㡥ㅤ㡢扦㥣搲愲㤸ㄳ〸㈳戴㐸㐹㍦摣㐸昱摥戸昱㌷㥥㙣戹㑣㔱㠱〴敡〹ㅢ㤳捥㔴攳昷挴㡤て攰慢㉣搵㈶挷ㅢ〴㑣捦挴㡤㐹㡦慡昱挳㜱攳㍦ㅦ搸摢㙣ㅣ搳㘱㌸㜲㠱㐴㤲㘱敢㉡敢㍦昱㠵昶㌰㥡ㄷ㑣敡捦〱㌳㉣愶攴㔴愱攳扡搲愰㠳戸っ攲攱ㅢ改㌹摣㙤挲ㄵ㄰〸搹昰㝦㤵㜰ㅣ㜷㥥㘶㡤挰挰㈷搰㙢〸㌶㝢扡㝡㘲攷愲㌹敦愱愰摦㍣敥攳㑣㔵摢㔶㈴〲㜳㈰ㅦ敥敦㈶㑥昹っ搳戱戵ㅦ㜱㤰㑣攳ㅤ㤲摥㤴㠷ち慣攴挵扢㘲捣收ㅥ㙡搱㡣晥㈰㤰〳改〸挸㡣晥㄰㘰ㄸ㠸攱㙤攵摣〸昹㕦㌱昷扢㔸昱㙥㠲㠷〱捡㠲捣㑥㍡㈸扥〷㘰㌸晥ㅦ㔵㡣慤㈹㝦㠹㈶敥㡦㕦㤶㈴㈳晤㝤散昰㝥㠰㍥戸㙦㐵㐴㠴㘵晤〳㈸㐹扥㤴㠲㐳扤昴㠳慣昸㄰挱㈳〰攵〲㈷扢攵㕤攳㥡㝡搴㕣ㅦ㐶㔷昱㄰〱㝥晡㐷愲っㅦち摣㠷搷㜷户㤵㜹ㄴ㡥㍦散㐷愸㌳昵〵晦㥤昸㈲㝦㥤㡢敥挳晦㤰愴愰っ晢扣昶扡摥挶㈲ㄳ搰㈶㔷扦㔵㙣昶㜳ㄸ㠷敢㙡㐵㔰㌸㈲㤵㑡㐹㉢ち攲㥢ぢㄶ㉥摥挰户ㅣ㔲ㄵ㐲㤰〶㔴㠵ㄳ㔵ㅣ㐶㠱晥㌱㌶㈵㡥㠹㈷晤攳㝣㈲㙡搵㈶㝥㈲捡昰㐱㄰慦慡晢扤㔱昷昸㠵挴戵慡戰摡㕥㐸晣慢㡡㤵攴ぢㅦ攵㘰ち㔹挸愴戵ㄲ㤱愶㘸攸㌱㘴㠶晡㠶㌹户㝢昰搳㉥㡡敡搹摡搹戳晦ㅣ捥㡦㕤㥤㝦换㥢〶ㅦ㝤收挷扦昹攸捦摦㝥攸て晦㝡晣昱㥦晦敥愳㑦晦敢扢换㠷㝥昰挴ㄳ摦扦敢昳㑦晦㘶户昹〵敤挹㝦捥㝤攱㠱挹昳て摣㘷㥥扥昹攸〳㙦扤昷敥挹㠵换挶晢晡晡晢㙦ㅡ晤攱㔵慦ㅣ㜹攸扥愷挴昷㝥㜹愵㈳搴㜲昱㠲昴㌴戸㙣㌵㡤捦㈲㠳㘹㜰挶㉦攸㌴戸㕣戵㔱换搱㐶㑤愳愰〴㥦〶㈷愰㉡㡣㜴挵挰㝦〰昳㍦戵㤴
B31: Decisioneering:7.0.0.0 | C31: Decisioneering:7.0.0.0

Sheet Input sheet
A1: Date of valuation | B1: 41882 | C1: Important: Before you run this spreadsheet, go into preferences in Excel and check under Calculation options
A2: Company name | B2: Amazon | C2: There should be a check against the iteration box. If there is not, you will get circular reasoning errors.
A3: Numbers from your base year below ( in consistent units)
B4: This year | C4: Last year
A5: Country of incorporation | B5: United States
A6: Industry (US) | B6: Retail (General)
A7: Industry (Global) | B7: Retail (General) | C7: Last 10K | D7: Years since last 10K
A8: Revenues | B8: 208125 | C8: 177866 | D8: 0.5
A9: Operating income or EBIT | B9: 7385 | C9: 4106 | D9: 0.5
A10: Interest expense | B10: 1239 | C10: 848
A11: Book value of equity | B11: 34995 | C11: 27709
A12: Book value of debt | B12: 27050 | C12: 24473
A13: Do you have R&D expenses to capitalize? | B13: Yes | C13: If you want to capitalize R&D, you have to input the numbers into the R&D worksheet.
A14: Do you have operating lease commitments? | B14: Yes | C14: If you have operating leases, please enter your lease commitments in the lease worksheet below and I will convert to debt
A15: Cash and Marketable Securities | B15: 27050 | C15: 30986
A16: Cross holdings and other non-operating assets | B16: 0 | C16: 0
A17: Minority interests | B17: 0 | C17: 0
A18: Number of shares outstanding = | B18: 497
A19: Current stock price = | B19: 1970.19 | E19: Computed numbers: Here is what your company's numbers look like, relative to industry.
A20: Effective tax rate = | B20: =769/3806 | E20: If you are not working in US dollars, you should add the inflation differential to the industry averages.
A21: Marginal tax rate = | B21: 0.24 | I21: Company | J21: Industry (US data) | K21: Industry (Global data)
A22: The value drivers below: | E22: Revenue growth in the most recent year = | I22: =IF(C8>0,(B8/C8)^(1/D8)-1, "NA") | J22: =VLOOKUP(B6,'Industry Averages(US)'!A2:S95,3) | K22: =VLOOKUP(B7,'Global industry averages'!A2:N95,3)
A23: Compounded annual revenue growth rate over next 5 years = | B23: 0.15 | C23: Growth Lever | E23: Pre-tax operating margin in the most recent year = | I23: ='Valuation output'!B4 | J23: =VLOOKUP(B6,'Industry Averages(US)'!A2:S95,4) | K23: =VLOOKUP(B7,'Global industry averages'!A2:N95,4)
A24: Target pre-tax operating margin (EBIT as % of sales in year 10) = | B24: 0.125 | C24: Profitability Lever | E24: Sales to capital ratio in most recent year = | I24: =B8/(B11+B12-B15) | J24: =VLOOKUP(B6,'Industry Averages(US)'!A2:S95,14) | K24: =VLOOKUP(B7,'Global industry averages'!A2:N95,14)
A25: Year of convergence | B25: 5 | C25: Speed of convergence level | E25: Return on invested capital in most recent year= | I25: ='Valuation output'!B7/'Valuation output'!B39 | J25: =VLOOKUP(B6,'Industry Averages(US)'!A2:S95,5) | K25: =VLOOKUP(B7,'Global industry averages'!A2:N95,5)
A26: Sales to capital ratio (for computing reinvestment) = | B26: =I24 | C26: Efficency of Growth Lever | E26: Standard deviation in stock prices = | J26: =VLOOKUP(B6,'Industry Averages(US)'!A2:S95,10) | K26: =VLOOKUP(B6,'Global industry averages'!A2:Z95,10)
A27: Market numbers | E27: Cost of capital = | J27: =VLOOKUP(B6,'Industry Averages(US)'!A2:S95,13) | K27: =VLOOKUP(B6,'Global industry averages'!A2:Z95,13)
A28: Riskfree rate | B28: 0.03
A29: Initial cost of capital = | B29: 0.0797 | E29: Valuation Output Feedback (for you to use to fine tune your inputs, if you want)
A30: Other inputs | E30: Revenues in year 10, based on your revenue growth = | J30: ='Valuation output'!M3
A31: Do you have employee options outstanding? | B31: No | E31: Pre-tax Operating Income in year 10, based on your operating margin = | J31: ='Valuation output'!M5
A32: Number of options outstanding = | B32: 21.65 | E32: Return on invested capital in year 10, based on your sales/capital ratio = | J32: ='Valuation output'!L40
A33: Average strike price = | B33: 61.13 | E33: Check the Diagnostics worksheet for more details.
A34: Average maturity = | B34: 5.97
A35: Standard deviation on stock price = | B35: 0.3
A37: Default assumptions.
A38: In stable growth, I will assume that your firm will have a cost of capital similar to that of typical mature companies (riskfree rate + 4.5%)
A39: Do you want to override this assumption = | B39: Yes | C39: Mature companies generally see their risk levels approach the average
A40: If yes, enter the cost of capital after year 10 = | B40: 0.075 | C40: Though some sectors, even in stable growth, may have higher risk.
A41: I will assume that your firm will earn a return on capital equal to its cost of capital after year 10. I am assuming that whatever competitive advantages you have today will fade over time.
...

Sheet Valuation output
B1: Base year | C1: 1 | D1: 2 | E1: 3 | F1: 4 | G1: 5 | H1: 6 | I1: 7 | J1: 8 | K1: 9 | L1: 10 | M1: Terminal year
A2: Revenue growth rate | C2: ='Input sheet'!B23 | D2: =C2 | E2: =D2 | F2: =E2 | G2: =F2 | H2: =G2-((G2-$M$2)/5) | I2: =G2-((G2-$M$2)/5)*2 | J2: =G2-((G2-$M$2)/5)*3 | K2: =G2-((G2-$M$2)/5)*4 | L2: =G2-((G2-$M$2)/5)*5 | M2: =IF('Input sheet'!B55="Yes",'Input sheet'!B56,'Input sheet'!B28)
A3: Revenues | B3: ='Input sheet'!B8 | C3: =B3*(1+C2) | D3: =C3*(1+D2) | E3: =D3*(1+E2) | F3: =E3*(1+F2) | G3: =F3*(1+G2) | H3: =G3*(1+H2) | I3: =H3*(1+I2) | J3: =I3*(1+J2) | ... M3: =L3*(1+M2)
A4: EBIT (Operating) margin | B4: =B5/B3 | C4: =IF(C1>'Input sheet'!$B$25,'Input sheet'!$B$24,'Input sheet'!$B$24-(('Input sheet'!$B$24-$B$4)/'Input sheet'!$B$25)*('Input sheet'!$B$25-C1)) | D4: =IF(D1>'Input sheet'!$B$25,'Input sheet'!$B$24,'Input sheet'!$B$24-(('Input sheet'!$B$24-$B$4)/'Input sheet'!$B$25)*('Input sheet'!$B$25-D1)) | E4: =IF(E1>'Input sheet'!$B$25,'Input sheet'!$B$24,'Input sheet'!$B$24-(('Input sheet'!$B$24-$B$4)/'Input sheet'!$B$25)*('Input sheet'!$B$25-E1)) | F4: =IF(F1>'Input sheet'!$B$25,'Input sheet'!$B$24,'Input sheet'!$B$24-(('Input sheet'!$B$24-$B$4)/'Input sheet'!$B$25)*('Input sheet'!$B$25-F1)) | G4: =IF(G1>'Input sheet'!$B$25,'Input sheet'!$B$24,'Input sheet'!$B$24-(('Input sheet'!$B$24-$B$4)/'Input sheet'!$B$25)*('Input sheet'!$B$25-G1)) | H4: =IF(H1>'Input sheet'!$B$25,'Input sheet'!$B$24,'Input sheet'!$B$24-(('Input sheet'!$B$24-$B$4)/'Input sheet'!$B$25)*('Input sheet'!$B$25-H1)) | I4: =IF(I1>'Input sheet'!$B$25,'Input sheet'!$B$24,'Input sheet'!$B$24-(('Input sheet'!$B$24-$B$4)/'Input sheet'!$B$25)*('Input sheet'!$B$25-I1)) | J4: =IF(J1>'Input sheet'!$B$25,'Input sheet'!$B$24,'Input sheet'!$B$24-(('Input sheet'!$B$24-$B$4)/'Input sheet'!$B$25)*('Input sheet'!$B$25-J1)) | ... L4: =IF(L1>'Input sheet'!$B$25,'Input sheet'!$B$24,'Input sheet'!$B$24-(('Input sheet'!$B$24-$B$4)/'Input sheet'!$B$25)*('Input sheet'!$B$25-L1)) | M4: =L4
A5: EBIT (Operating income) | B5: =IF('Input sheet'!B14="Yes",IF('Input sheet'!B13="Yes",'Input sheet'!B9+'Operating lease converter'!F32+'R& D converter'!D39,'Input sheet'!B9+'Operating lease converter'!F32),IF('Input sheet'!B13="Yes",'Input sheet'!B9+'R& D converter'!D39,'Input sheet'!B9)) | C5: =C4*C3 | D5: =D4*D3 | E5: =E4*E3 | F5: =F4*F3 | G5: =G4*G3 | H5: =H4*H3 | I5: =I4*I3 | J5: =J4*J3 | ... M5: =M4*M3 | N5: =M5-B5
A6: Tax rate | B6: ='Input sheet'!B20 | C6: =B6 | D6: =C6 | E6: =D6 | F6: =E6 | G6: =F6 | H6: =G6+($M$6-$G$6)/5 | I6: =H6+($M$6-$G$6)/5 | J6: =I6+($M$6-$G$6)/5 | K6: =J6+($M$6-$G$6)/5 | L6: =K6+($M$6-$G$6)/5 | M6: =IF('Input sheet'!B50="Yes",'Input sheet'!B20,'Input sheet'!B21)
A7: EBIT(1-t) | B7: =IF(B5>0,B5*(1-B6),B5) | C7: =IF(C5>0,IF(C5<B10,C5,C5-(C5-B10)*C6),C5) | D7: =IF(D5>0,IF(D5<C10,D5,D5-(D5-C10)*D6),D5) | E7: =IF(E5>0,IF(E5<D10,E5,E5-(E5-D10)*E6),E5) | F7: =IF(F5>0,IF(F5<E10,F5,F5-(F5-E10)*F6),F5) | G7: =IF(G5>0,IF(G5<F10,G5,G5-(G5-F10)*G6),G5) | H7: =IF(H5>0,IF(H5<G10,H5,H5-(H5-G10)*H6),H5) | I7: =IF(I5>0,IF(I5<H10,I5,I5-(I5-H10)*I6),I5) | J7: =IF(J5>0,IF(J5<I10,J5,J5-(J5-I10)*J6),J5) | ... L7: =IF(L5>0,IF(L5<K10,L5,L5-(L5-K10)*L6),L5) | M7: =M5*(1-M6)
A8: - Reinvestment | C8: =(C3-B3)/C38 | D8: =(D3-C3)/D38 | E8: =(E3-D3)/E38 | F8: =(F3-E3)/F38 | G8: =(G3-F3)/G38 | H8: =(H3-G3)/H38 | I8: =(I3-H3)/I38 | J8: =(J3-I3)/J38 | ... L8: =(L3-K3)/L38 | M8: =IF(M2>0,(M2/M40)*M7,0) | N8: =SUM(C8:M8)
A9: FCFF | C9: =C7-C8 | D9: =D7-D8 | E9: =E7-E8 | F9: =F7-F8 | G9: =G7-G8 | H9: =H7-H8 | I9: =I7-I8 | J9: =J7-J8 | ... M9: =M7-M8
A10: NOL | B10: =IF('Input sheet'!B52="Yes",'Input sheet'!B53,0) | C10: =IF(C5<0,B10-C5,IF(B10>C5,B10-C5,0)) | D10: =IF(D5<0,C10-D5,IF(C10>D5,C10-D5,0)) | E10: =IF(E5<0,D10-E5,IF(D10>E5,D10-E5,0)) | F10: =IF(F5<0,E10-F5,IF(E10>F5,E10-F5,0)) | G10: =IF(G5<0,F10-G5,IF(F10>G5,F10-G5,0)) | H10: =IF(H5<0,G10-H5,IF(G10>H5,G10-H5,0)) | I10: =IF(I5<0,H10-I5,IF(H10>I5,H10-I5,0)) | J10: =IF(J5<0,I10-J5,IF(I10>J5,I10-J5,0)) | ... M10: =IF(M5<0,L10-M5,IF(L10>M5,L10-M5,0))
A12: Cost of capital | C12: ='Input sheet'!B29 | D12: =C12 | E12: =D12 | F12: =E12 | G12: =F12 | H12: =G12-($G$12-$M$12)/5 | I12: =H12-($G$12-$M$12)/5 | J12: =I12-($G$12-$M$12)/5 | K12: =J12-($G$12-$M$12)/5 | L12: =K12-($G$12-$M$12)/5 | M12: =IF('Input sheet'!B39="Yes",'Input sheet'!B40,'Input sheet'!B28+0.045)
A13: Cumulated discount factor | C13: =1/(1+C12) | D13: =C13*(1/(1+D12)) | E13: =D13*(1/(1+E12)) | F13: =E13*(1/(1+F12)) | G13: =F13*(1/(1+G12)) | H13: =G13*(1/(1+H12)) | I13: =H13*(1/(1+I12)) | J13: =I13*(1/(1+J12)) | K13: =J13*(1/(1+K12)) | L13: =K13*(1/(1+L12))
A14: PV(FCFF) | C14: =C9*C13 | D14: =D9*D13 | E14: =E9*E13 | F14: =F9*F13 | G14: =G9*G13 | H14: =H9*H13 | I14: =I9*I13 | J14: =J9*J13 | ... L14: =L9*L13
A16: Terminal cash flow | B16: =M9
A17: Terminal cost of capital | B17: =M12
A18: Terminal value | B18: =B16/(B17-M2)
A19: PV(Terminal value) | B19: =B18*L13
A20: PV (CF over next 10 years) | B20: =SUM(C14:L14)
A21: Sum of PV | B21: =B19+B20
A22: Probability of failure = | B22: =IF('Input sheet'!B45="Yes",'Input sheet'!B46,0)
A23: Proceeds if firm fails = | B23: =IF('Input sheet'!B47="B",('Input sheet'!B11+'Input sheet'!B12)*'Input sheet'!B48,'Valuation output'!B21*'Input sheet'!B48)
A24: Value of operating assets = | B24: =B21*(1-B22)+B23*B22
A25: - Debt | B25: =IF('Input sheet'!B14="Yes",'Input sheet'!B12+'Operating lease converter'!C28,'Input sheet'!B12)
A26: - Minority interests | B26: ='Input sheet'!B17
A27: + Cash | B27: =IF('Input sheet'!B58="YES",'Input sheet'!B15-'Input sheet'!B59*('Input sheet'!B21-'Input sheet'!B60),'Input sheet'!B15)
A28: + Non-operating assets | B28: ='Input sheet'!B16
A29: Value of equity | B29: =B24-B25-B26+B27+B28
A30: - Value of options | B30: =IF('Input sheet'!B31="No",0,'Option value'!D27)
A31: Value of equity in common stock | B31: =B29-B30
A32: Number of shares | B32: ='Input sheet'!B18
A33: Estimated value /share | B33: =B31/B32
A34: Price | B34: ='Input sheet'!B19
A35: Price as % of value | B35: =B34/B33
A37: Implied variables | M37: After year 10
A38: Sales to capital ratio | C38: ='Input sheet'!B26 | D38: =C38 | E38: =D38 | F38: =E38 | G38: =F38 | H38: =G38 | I38: =H38 | J38: =I38 | K38: =J38 | L38: =K38
A39: Invested capital | B39: =IF('Input sheet'!B14="Yes",IF('Input sheet'!B13="Yes",'Input sheet'!B11+'Input sheet'!B12-'Input sheet'!B15+'Operating lease converter'!F33+'R& D converter'!D35,'Input sheet'!B11+'Input sheet'!B12-'Input sheet'!B15+'Operating lease converter'!F33),IF('Input sheet'!B13="Yes",'Input sheet'!B11+'Input sheet'!B12-'Input sheet'!B15+'R& D converter'!D35,'Input sheet'!B11+'Input sheet'!B12-'Input sheet'!B15)) | C39: =B39+C8 | D39: =C39+D8 | E39: =D39+E8 | F39: =E39+F8 | G39: =F39+G8 | H39: =G39+H8 | I39: =H39+I8 | J39: =I39+J8 | ... L39: =K39+L8
A40: ROIC | B40: =B7/B39 | C40: =C7/C39 | D40: =D7/D39 | E40: =E7/E39 | F40: =F7/F39 | G40: =G7/G39 | H40: =H7/H39 | I40: =I7/I39 | ... L40: =L7/L39 | M40: =IF('Input sheet'!B42="Yes",'Input sheet'!B43,'Valuation output'!L12)

Sheet Stories to Numbers
A1: ='Input sheet'!B2
A2: The Greatest (and most Feared) Disruptive Platform in History
A3: Amazon will complete its metaphorsis from being a retail company to one that can take its competitive advantages - access to capital & willingness to lose money for long periods, while disrupting and changing the status quo - to any business that it targets, giving it the potential for high revenue growth on top of already-large revenues. It will be able to use the pricing power it accumulates in each business it is in, to increase profit margins, partly through economies of scale and partly through higher prices. Its low debt ratio and divergent business mix give it a low cost of capital. | H3: Tell your story about the company. Keep it focuses on the company's businesses and tie it into the three key levers of value: cash flows, growth and risk
A7: The Assumptions
B8: Base year | C8: Years 1-5 | D8: Years 6-10 | F8: After year 10 | G8: Link to story
A9: Revenues (a) | B9: ='Valuation output'!B3 | C9: ='Input sheet'!B23 | D9: =F9 | F9: ='Valuation output'!M2 | G9: Expanding into new businessses | H9: Tie each assumption to the part of your story that relates to it.
A10: Operating margin (b) | B10: ='Valuation output'!B4 | C10: =B10 | D10: =F10 | F10: ='Valuation output'!M4 | G10: Economies of scale and pricing power increase margins
A11: Tax rate | B11: ='Valuation output'!B6 | C11: =B11 | D11: =F11 | F11: ='Valuation output'!M6 | G11: Converging on a global tax rate of 25%
A12: Reinvestment (c ) | C12: Sales to capital ratio = | D12: ='Input sheet'!B26 | E12: RIR = | F12: ='Valuation output'!M2/'Valuation output'!M40 | G12: Big payoffs from investing in technology and content
A13: Return on capital | B13: ='Valuation output'!B40 | C13: Marginal ROIC = | D13: =Diagnostics!B6 | F13: ='Valuation output'!M40 | G13: The last man standing…
A14: Cost of capital (d) | C14: ='Valuation output'!C12 | D14: =F14 | F14: ='Valuation output'!M12 | G14: Low debt & diverse business mix
A15: The Cash Flows
B16: Revenues | C16: Operating Margin | D16: EBIT | E16: EBIT (1-t) | F16: Reinvestment | G16: FCFF | H16: These are the numbers that come from your assumptions. The revenues over time reflect your revenue growth, the operating margins evolve towards your target margin and your tax rate will change, if you have set it to. The reinvestment is estimated using the sales to capital ratio for the first 10 years and based on a reinvestment rate in stable growth (g/ ROC).
A17: 1 | B17: ='Valuation output'!C3 | C17: ='Valuation output'!C4 | D17: =B17*C17 | E17: ='Valuation output'!C7 | F17: ='Valuation output'!C8 | G17: =E17-F17
A18: 2 | B18: ='Valuation output'!D3 | C18: ='Valuation output'!D4 | D18: =B18*C18 | E18: ='Valuation output'!D7 | F18: ='Valuation output'!D8 | G18: =E18-F18
A19: 3 | B19: ='Valuation output'!E3 | C19: ='Valuation output'!E4 | D19: =B19*C19 | E19: ='Valuation output'!E7 | F19: ='Valuation output'!E8 | G19: =E19-F19
A20: 4 | B20: ='Valuation output'!F3 | C20: ='Valuation output'!F4 | D20: =B20*C20 | E20: ='Valuation output'!F7 | F20: ='Valuation output'!F8 | G20: =E20-F20
A21: 5 | B21: ='Valuation output'!G3 | C21: ='Valuation output'!G4 | D21: =B21*C21 | E21: ='Valuation output'!G7 | F21: ='Valuation output'!G8 | G21: =E21-F21
A22: 6 | B22: ='Valuation output'!H3 | C22: ='Valuation output'!H4 | D22: =B22*C22 | E22: ='Valuation output'!H7 | F22: ='Valuation output'!H8 | G22: =E22-F22
A23: 7 | B23: ='Valuation output'!I3 | C23: ='Valuation output'!I4 | D23: =B23*C23 | E23: ='Valuation output'!I7 | F23: ='Valuation output'!I8 | G23: =E23-F23
A24: 8 | B24: ='Valuation output'!J3 | C24: ='Valuation output'!J4 | D24: =B24*C24 | E24: ='Valuation output'!J7 | F24: ='Valuation output'!J8 | G24: =E24-F24
A25: 9 | B25: ='Valuation output'!K3 | C25: ='Valuation output'!K4 | D25: =B25*C25 | E25: ='Valuation output'!K7 | F25: ='Valuation output'!K8 | G25: =E25-F25
A26: 10 | B26: ='Valuation output'!L3 | C26: ='Valuation output'!L4 | D26: =B26*C26 | E26: ='Valuation output'!L7 | F26: ='Valuation output'!L8 | G26: =E26-F26
A27: Terminal year | B27: ='Valuation output'!M3 | C27: ='Valuation output'!M4 | D27: =B27*C27 | E27: ='Valuation output'!M7 | F27: ='Valuation output'!M8 | G27: =E27-F27
A28: The Value
A29: Terminal value | D29: ='Valuation output'!B18 | H29: This is the output from your valuation. It reflects your cash flows being discounted back at the cost of capital to get to your operating asset value, which then gets adjusted for the likelihood that your firm will not make it. We add cash and non-operating assets, subtract out debt and minority interests to get to value of equity.
A30: PV(Terminal value) | D30: ='Valuation output'!B19
A31: PV (CF over next 10 years) | D31: ='Valuation output'!B20
A32: Value of operating assets = | D32: ='Valuation output'!B21
A33: Adjustment for distress | D33: =D32-'Valuation output'!B24 | E33: Probability of failure = | G33: ='Valuation output'!B22
A34: - Debt & Mnority Interests | D34: ='Valuation output'!B25+'Valuation output'!B26
A35: + Cash & Other Non-operating assets | D35: ='Valuation output'!B27+'Valuation output'!B28
A36: Value of equity | D36: =D32-D33-D34+D35
A37: - Value of equity options | D37: ='Valuation output'!B30
A38: Number of shares | D38: ='Valuation output'!B32
A39: Value per share | D39: =(D36-D37)/D38 | E39: Stock was trading at = | G39: ='Input sheet'!B19
J43: =D39/1944

Sheet Summary Sheet
A1: Year | B1: Revenues | C1: Revenue Growth Rate | D1: Pre-Tax Operating Margin | E1: Pre-Tax Operating Income | F1: NOL | G1: Taxes | H1: After-Tax Operating Income
A2: Traling 12 month | B2: ='Valuation output'!B3 | D2: ='Valuation output'!B4 | E2: =B2*D2 | F2: ='Valuation output'!B10 | G2: =E2-H2 | H2: ='Valuation output'!B7
A3: 1 | B3: ='Valuation output'!C3 | C3: ='Valuation output'!C2 | D3: ='Valuation output'!C4 | E3: =B3*D3 | F3: ='Valuation output'!C10 | G3: =E3-H3 | H3: ='Valuation output'!C7
A4: 2 | B4: ='Valuation output'!D3 | C4: =B4/B3-1 | D4: ='Valuation output'!D4 | E4: =B4*D4 | F4: ='Valuation output'!D10 | G4: =E4-H4 | H4: ='Valuation output'!D7
A5: 3 | B5: ='Valuation output'!E3 | C5: =B5/B4-1 | D5: ='Valuation output'!E4 | E5: =B5*D5 | F5: ='Valuation output'!E10 | G5: =E5-H5 | H5: ='Valuation output'!E7
A6: 4 | B6: ='Valuation output'!F3 | C6: =B6/B5-1 | D6: ='Valuation output'!F4 | E6: =B6*D6 | F6: ='Valuation output'!F10 | G6: =E6-H6 | H6: ='Valuation output'!F7
A7: 5 | B7: ='Valuation output'!G3 | C7: =B7/B6-1 | D7: ='Valuation output'!G4 | E7: =B7*D7 | F7: ='Valuation output'!G10 | G7: =E7-H7 | H7: ='Valuation output'!G7
A8: 6 | B8: ='Valuation output'!H3 | C8: =B8/B7-1 | D8: ='Valuation output'!H4 | E8: =B8*D8 | F8: ='Valuation output'!H10 | G8: =E8-H8 | H8: ='Valuation output'!H7
A9: 7 | B9: ='Valuation output'!I3 | C9: =B9/B8-1 | D9: ='Valuation output'!I4 | E9: =B9*D9 | F9: ='Valuation output'!I10 | G9: =E9-H9 | H9: ='Valuation output'!I7
A10: 8 | B10: ='Valuation output'!J3 | C10: =B10/B9-1 | D10: ='Valuation output'!J4 | E10: =B10*D10 | F10: ='Valuation output'!J10 | G10: =E10-H10 | H10: ='Valuation output'!J7
A11: 9 | B11: ='Valuation output'!K3 | C11: =B11/B10-1 | D11: ='Valuation output'!K4 | E11: =B11*D11 | F11: ='Valuation output'!K10 | G11: =E11-H11 | H11: ='Valuation output'!K7
A12: 10 | B12: ='Valuation output'!L3 | C12: =B12/B11-1 | D12: ='Valuation output'!L4 | E12: =B12*D12 | F12: ='Valuation output'!L10 | G12: =E12-H12 | H12: ='Valuation output'!L7
A14: Year | B14: After-Tax Operating Income | C14: Change in Revenues | D14: Sales to Capital | E14: Reinvestment | F14: FCFF | G14: Capital Invested | H14: Implied ROC
A15: =A2 | B15: =H2 | G15: ='Valuation output'!B39 | H15: =B15/G15
A16: =A3 | B16: =H3 | C16: =B3-B2 | D16: ='Valuation output'!C38 | E16: =C16/D16 | F16: =B16-E16 | G16: =G15+E16 | H16: =B16/G16
A17: =A4 | B17: =H4 | C17: =B4-B3 | D17: ='Valuation output'!D38 | E17: =C17/D17 | F17: =B17-E17 | G17: =G16+E17 | H17: =B17/G17
A18: =A5 | B18: =H5 | C18: =B5-B4 | D18: ='Valuation output'!E38 | E18: =C18/D18 | F18: =B18-E18 | G18: =G17+E18 | H18: =B18/G18
A19: =A6 | B19: =H6 | C19: =B6-B5 | D19: ='Valuation output'!F38 | E19: =C19/D19 | F19: =B19-E19 | G19: =G18+E19 | H19: =B19/G19
A20: =A7 | B20: =H7 | C20: =B7-B6 | D20: ='Valuation output'!G38 | E20: =C20/D20 | F20: =B20-E20 | G20: =G19+E20 | H20: =B20/G20
A21: =A8 | B21: =H8 | C21: =B8-B7 | D21: ='Valuation output'!H38 | E21: =C21/D21 | F21: =B21-E21 | G21: =G20+E21 | H21: =B21/G21
A22: =A9 | B22: =H9 | C22: =B9-B8 | D22: ='Valuation output'!I38 | E22: =C22/D22 | F22: =B22-E22 | G22: =G21+E22 | H22: =B22/G22
A23: =A10 | B23: =H10 | C23: =B10-B9 | D23: ='Valuation output'!J38 | E23: =C23/D23 | F23: =B23-E23 | G23: =G22+E23 | H23: =B23/G23
A24: =A11 | B24: =H11 | C24: =B11-B10 | D24: ='Valuation output'!K38 | E24: =C24/D24 | F24: =B24-E24 | G24: =G23+E24 | H24: =B24/G24
A25: =A12 | B25: =H12 | C25: =B12-B11 | D25: ='Valuation output'!L38 | E25: =C25/D25 | F25: =B25-E25 | G25: =G24+E25 | H25: =B25/G25
A27: Year | B27: Beta | C27: Cost of Equity | D27: Pre-Tax Cost of Debt | E27: Tax Savings | F27: After-Tax Cost of Debt | G27: Debt Ratio | H27: Cost of Capital
A28: =A16 | H28: ='Valuation output'!C12
A29: =A17 | H29: ='Valuation output'!D12
A30: =A18 | H30: ='Valuation output'!E12
A31: =A19 | H31: ='Valuation output'!F12
A32: =A20 | H32: ='Valuation output'!G12
A33: =A21 | H33: ='Valuation output'!H12
A34: =A22 | H34: ='Valuation output'!I12
A35: =A23 | H35: ='Valuation output'!J12
A36: =A24 | H36: ='Valuation output'!K12
A37: =A25 | H37: ='Valuation output'!L12
A39: Year | B39: Cost of Capital | C39: Cumulated Cost of Capital | D39: FCFF | E39: Terminal Value | F39: Present Value
A40: =A28 | B40: =H28 | C40: =(1+'Summary Sheet'!B40) | D40: =F16 | F40: =D40/C40
A41: =A29 | B41: =H29 | C41: =C40*(1+B41) | D41: =F17 | F41: =D41/C41
A42: =A30 | B42: =H30 | C42: =C41*(1+B42) | D42: =F18 | F42: =D42/C42
A43: =A31 | B43: =H31 | C43: =C42*(1+B43) | D43: =F19 | F43: =D43/C43
...

Sheet Option value
A1: Valuing Options or Warrants
A2: Enter the current stock price = | D2: ='Input sheet'!B19
A3: Enter the strike price on the option = | D3: ='Input sheet'!B33
A4: Enter the expiration of the option = | D4: ='Input sheet'!B34
A5: Enter the standard deviation in stock prices = | D5: ='Input sheet'!B35 | E5: (volatility)
A6: Enter the annualized dividend yield on stock = | D6: 0
A7: Enter the treasury bond rate = | D7: ='Input sheet'!B28
A8: Enter the number of warrants (options) outstanding = | D8: ='Input sheet'!B32
A9: Enter the number of shares outstanding = | D9: ='Input sheet'!B18
A11: Do not input any numbers below this line
A12: VALUING WARRANTS WHEN THERE IS DILUTION
A13: Stock Price= | C13: =D2 | D13: # Warrants issued= | F13: =D8
A14: Strike Price= | C14: =D3 | D14: # Shares outstanding= | F14: =D9
A15: Adjusted S = | C15: =(C13*F14+C26*F13)/(F14+F13) | D15: T.Bond rate= | F15: =D7
A16: Adjusted K = | C16: =C14 | D16: Variance= | F16: =D5^2
A17: Expiration (in years) = | C17: =D4 | D17: Annualized dividend yield= | F17: =D6
D18: Div. Adj. interest rate= | F18: =F15-F17
A20: d1 = | B20: =(LN(C15/C16)+(F18+(F16/2))*C17)/(((F16)^(0.5))*(C17^0.5))
A21: N (d1) = | B21: =NORMSDIST(B20)
A23: d2 = | B23: =B20-((F16^0.5)*(C17^(0.5)))
A24: N (d2) = | B24: =NORMSDIST(B23)
A26: Value per option = | C26: =((EXP((0-F17)*C17))*C15*B21-C16*(EXP((0-F15)*C17))*B24)
A27: Value of all options outstanding = | D27: =C26*D8

Sheet Diagnostics
A1: VALUATION DIAGNOSTICS
A2: Invested capital at start of valuation | B2: ='Valuation output'!B39
A3: Invested capital at end of valuation | B3: ='Valuation output'!L39
A4: Change in invested capital over 10 years | B4: =B3-B2
A5: Change in EBIT*(1–t) (after-tax operating income) over 10 years | B5: ='Valuation output'!L5-'Valuation output'!B5
A6: Marginal ROIC over 10 years | B6: =B5/B4
A7: ROIC at end of valuation | B7: ='Valuation output'!L40
A8: Average WACC over the 10 years (compounded) | B8: =(1/'Valuation output'!L13)^(1/10)-1
A9: Your calculated value as a percent of current price | B9: ='Valuation output'!B33/'Valuation output'!B34
B10: =IF(B9="NA","Value is negative. See below",IF(B9>2,"Value seems high. See below",IF(B9<0.5,"Value seems low. See below"," ")))
A11: Inputs | B11: If calculated value is negative or looks too low | C11: If calculated value looks too high
A12: Revenue growth rate (input cell B3) | B12: Increase revenue growth rate | C12: Decrease revenue growth rate
A13: Last period EBIT as % of revenue (Input cell B14) | B13: Increase the target pre-tax operating margin | C13: Decrease the target pre-tax operating margin
A14: Sales to Capital Ratio or reinvestment (Input cell B15) | B14: Decrease the sales/capital ratio | C14: Increase the sales/capital ratio
A15: Return on capital in perpetuity (B30 & B31) | B15: Increase relative to your cost of capital | C15: If higher than your cost of capital, lower towards your cost of capital | D15: T

Sheet R& D converter
A1: R & D Converter
A2: This spreadsheet converts R&D expenses from operating to capital expenses. It makes the appropriate adjustments to operating income, net
A3: income, the book value of assets and the book value of equity.
A5: Inputs
A6: Over how many years do you want to amortize R&D expenses | F6: 2 | G6: ! If in doubt, use the lookup table below
A7: Enter the current year's R&D expense = | F7: 22620 | G7: The maximum allowed is ten years
A8: Enter R& D expenses for past years: the number of years that you will need to enter will be determined by the amortization period
A9: Do not input numbers in the first column (Year). It will get automatically updated based on the input above.
A10: Year | B10: R& D Expenses
A11: -1 | B11: 16085 | C11: ! Year -1 is the year prior to the current year
A12: =IF((0-A11)<$F$6,IF(A11>-1,,A11-1),) | B12: 12540 | C12: ! Year -2 is the two years prior to the current year
A13: =IF((0-A12)<$F$6,IF(A12>-1,,A12-1),)
A14: =IF((0-A13)<$F$6,IF(A13>-1,,A13-1),)
A15: =IF((0-A14)<$F$6,IF(A14>-1,,A14-1),)
A16: =IF((0-A15)<$F$6,IF(A15>-1,,A15-1),)
A17: =IF((0-A16)<$F$6,IF(A16>-1,,A16-1),)
A18: =IF((0-A17)<$F$6,IF(A17>-1,,A17-1),)
A19: =IF((0-A18)<$F$6,IF(A18>-1,,A18-1),)
A20: =IF((0-A19)<$F$6,IF(A19>-1,,A19-1),)
A22: Output
A23: Year | B23: R&D Expense | C23: Unamortized portion | E23: Amortization this year
A24: Current | B24: =F7 | C24: =1 | D24: =B24*C24
A25: =A11 | B25: =B11 | C25: =IF(A25<0,($F$6+A25)/$F$6,0) | D25: =B25*C25 | E25: =IF(A25<0,B25/$F$6,0)
A26: =A12 | B26: =B12 | C26: =IF(A26<0,($F$6+A26)/$F$6,0) | D26: =B26*C26 | E26: =IF(A26<0,B26/$F$6,0)
A27: =A13 | B27: =B13 | C27: =IF(A27<0,($F$6+A27)/$F$6,0) | D27: =B27*C27 | E27: =IF(A27<0,B27/$F$6,0)
A28: =A14 | B28: =B14 | C28: =IF(A28<0,($F$6+A28)/$F$6,0) | D28: =B28*C28 | E28: =IF(A28<0,B28/$F$6,0)
A29: =A15 | B29: =B15 | C29: =IF(A29<0,($F$6+A29)/$F$6,0) | D29: =B29*C29 | E29: =IF(A29<0,B29/$F$6,0)
A30: =A16 | B30: =B16 | C30: =IF(A30<0,($F$6+A30)/$F$6,0) | D30: =B30*C30 | E30: =IF(A30<0,B30/$F$6,0)
A31: =A17 | B31: =B17 | C31: =IF(A31<0,($F$6+A31)/$F$6,0) | D31: =B31*C31 | E31: =IF(A31<0,B31/$F$6,0)
A32: =A18 | B32: =B18 | C32: =IF(A32<0,($F$6+A32)/$F$6,0) | D32: =B32*C32 | E32: =IF(A32<0,B32/$F$6,0)
A33: =A19 | B33: =B19 | C33: =IF(A33<0,($F$6+A33)/$F$6,0) | D33: =B33*C33 | E33: =IF(A33<0,B33/$F$6,0)
A34: =A20 | B34: =B20 | C34: =IF(A34<0,($F$6+A34)/$F$6,0) | D34: =B34*C34 | E34: =IF(A34<0,B34/$F$6,0)
A35: Value of Research Asset = | D35: =SUM(D24:D34) | E35: =SUM(E25:E34)
A37: Amortization of asset for current year = | D37: =E35
A39: Adjustment to Operating Income = | D39: =F7-D37 | E39: ! A positive number indicates an increase in operating income (add to reported EBIT)
A40: Tax Effect of R&D Expensing | D40: =D39*'Input sheet'!B21

Sheet Operating lease converter
A1: Operating Lease Converter
A2: The yellow cells are input cells. Please enter them.
A3: Inputs
A4: Operating lease expense in current year = | E4: 2200
A5: Operating Lease Commitments (From footnote to financials)
A6: Year | B6: Commitment | C6: ! Year 1 is next year, ….
A7: 1 | B7: 2427
A8: 2 | B8: 2376
A9: 3 | B9: 2258
A10: 4 | B10: 2039
A11: 5 | B11: 1813
A12: 6 and beyond | B12: 11935
A14: Output
A15: Pre-tax Cost of Debt = | C15: 0.0413 | D15: ! If you do not have a cost of debt, use the synthetic rating estimator
A18: Number of years embedded in yr 6 estimate = | D18: =IF(B12>0,ROUND(B12/AVERAGE(B7:B11),0),0) | E18: ! I use the average lease expense over the first five years
E19: to estimate the number of years of expenses in yr 6
A20: Converting Operating Leases into debt
A21: Year | B21: Commitment | C21: Present Value
A22: =A7 | B22: =B7 | C22: =B22/(1+$C$15)^A22
A23: =A8 | B23: =B8 | C23: =B23/(1+$C$15)^A23
A24: =A9 | B24: =B9 | C24: =B24/(1+$C$15)^A24
A25: =A10 | B25: =B10 | C25: =B25/(1+$C$15)^A25
A26: =A11 | B26: =B11 | C26: =B26/(1+$C$15)^A26
A27: =A12 | B27: =IF(B12>0,IF(D18>0,B12/D18,B12),0) | C27: =IF(D18>0,(B27*(1-(1+C15)^(-D18))/C15)/(1+$C$15)^5,B27/(1+C15)^6) | D27: ! Commitment beyond year 6 converted into an annuity for ten years
A28: Debt Value of leases = | C28: =SUM(C22:C27)
A30: Restated Financials
A31: Depreciation on Operating Lease Asset = | F31: =C28/(5+D18) | G31: ! I use straight line depreciation
A32: Adjustment to Operating Earnings = | F32: =E4-F31 | G32: ! Add this amount to pre-tax operating income
A33: Adjustment to Total Debt outstanding = | F33: =C28 | G33: ! Add this amount to debt
A34: Adjustment to Depreciation = | F34: =C28/(5+D18)

Sheet Cost of capital worksheet
A1: Estimation of Current Cost of Capital | G1: Operating Countries ERP calculator
A2: Inputs | G2: Country | H2: Revenues | I2: ERP | J2: Weight | K2: Weighted ERP
A3: Equity | G3: United States of America | H3: 120486 | I3: =IF(H3=0,0,VLOOKUP(G3,'Country equity risk premiums'!$A$2:$D$187,4)) | J3: =IF(H3>0,H3/$H$16,) | K3: =IF(J3=0,0,I3*J3) | M3: The last two rows in each of country/region risk premium tables is set aside for your input to provide you with flexibility to enter some numbers directly. For instance, assume that you have a company that breaks its revenues down into three countries and then puts the rest into "Rest of the World". You can enter the "Rest of the World" in one of these two rows and enter an equity risk premium for the rest of the world. The easiest way to do that is to go into the country equity risk premium worksheet and change the GDP for the three countries that you have data for to zero and compute the global weighted average ERP for the remaining countries. With the regional worksheet, you can use the last two rows to enter the data for an individual country (usually the domestic country) that might be broken out though the rest of the revenues are broken down by region. You can look up the ERP for the country in the country ERP worksheet.
A4: Number of Shares outstanding = | B4: ='Input sheet'!B18 | G4: Germany | H4: 16951 | I4: =IF(H4=0,0,VLOOKUP(G4,'Country equity risk premiums'!$A$2:$D$187,4)) | J4: =IF(H4>0,H4/$H$16,) | K4: =IF(J4=0,0,I4*J4)
A5: Current Market Price per share = | B5: ='Input sheet'!B19 | G5: United Kingdom | H5: 11372 | I5: =IF(H5=0,0,VLOOKUP(G5,'Country equity risk premiums'!$A$2:$D$187,4)) | J5: =IF(H5>0,H5/$H$16,) | K5: =IF(J5=0,0,I5*J5)
G6: Japan | H6: 11907 | I6: =IF(H6=0,0,VLOOKUP(G6,'Country equity risk premiums'!$A$2:$D$187,4)) | J6: =IF(H6>0,H6/$H$16,) | K6: =IF(J6=0,0,I6*J6)
A7: Approach for estimating beta | B7: Multibusiness(Global) | I7: =IF(H7=0,0,VLOOKUP(G7,'Country equity risk premiums'!$A$2:$D$187,4)) | J7: =IF(H7>0,H7/$H$16,) | K7: =IF(J7=0,0,I7*J7)
A8: If direct input, enter levered beta (or regression beta) | B8: 1.2 | I8: =IF(H8=0,0,VLOOKUP(G8,'Country equity risk premiums'!$A$2:$D$187,4)) | J8: =IF(H8>0,H8/$H$16,) | K8: =IF(J8=0,0,I8*J8)
A9: Unlevered beta = | B9: =IF(B7="Single Business(US)",VLOOKUP('Input sheet'!B6,'Industry Averages(US)'!A2:G95,7),IF(B7="Multibusiness(US)",K46,IF(B7="Single Business(Global)",VLOOKUP('Input sheet'!B7,'Global industry averages'!A2:G95,7),'Cost of capital worksheet'!K62))) | I9: =IF(H9=0,0,VLOOKUP(G9,'Country equity risk premiums'!$A$2:$D$187,4)) | J9: =IF(H9>0,H9/$H$16,) | K9: =IF(J9=0,0,I9*J9)
A10: Riskfree Rate = | B10: ='Input sheet'!B28 | I10: =IF(H10=0,0,VLOOKUP(G10,'Country equity risk premiums'!$A$2:$D$187,4)) | J10: =IF(H10>0,H10/$H$16,) | K10: =IF(J10=0,0,I10*J10)
A11: What approach do you want to use to input ERP? | B11: Operating countries | I11: =IF(H11=0,0,VLOOKUP(G11,'Country equity risk premiums'!$A$2:$D$187,4)) | J11: =IF(H11>0,H11/$H$16,) | K11: =IF(J11=0,0,I11*J11)
A12: Direct input for ERP (if you choose "will input" | B12: 0.05 | I12: =IF(H12=0,0,VLOOKUP(G12,'Country equity risk premiums'!$A$2:$D$187,4)) | J12: =IF(H12>0,H12/$H$16,) | K12: =IF(J12=0,0,I12*J12)
A13: Equity Risk Premium used in cost of equity = | B13: =IF(B11="Will Input",B12,IF(B11="Country of Incorporation",VLOOKUP('Input sheet'!B5,'Country equity risk premiums'!A2:E187,4),IF(B11="Operating regions",'Cost of capital worksheet'!K30,'Cost of capital worksheet'!K16))) | I13: =IF(H13=0,0,VLOOKUP(G13,'Country equity risk premiums'!$A$2:$D$187,4)) | J13: =IF(H13>0,H13/$H$16,) | K13: =IF(J13=0,0,I13*J13)
J14: =IF(H14>0,H14/$H$16,) | K14: =IF(J14=0,0,I14*J14)
A15: Debt | G15: Rest of the World | H15: 17150 | I15: 0.0621 | J15: =IF(H15>0,H15/$H$16,) | K15: =IF(J15=0,0,I15*J15)
A16: Book Value of Straight Debt = | B16: ='Input sheet'!B12 | G16: Total | H16: =SUM(H3:H15) | J16: =SUM(J3:J15) | K16: =SUM(K3:K15)
A17: Interest Expense on Debt = | B17: ='Input sheet'!B10 | G17: Operating Regions ERP calculator
A18: Average Maturity = | B18: 3 | G18: Region | H18: Revenues | I18: ERP | J18: Weight | K18: Weighted ERP
A19: Approach for estimating pre-tax cost of debt | B19: Synthetic rating | G19: ='Country equity risk premiums'!A191 | H19: 0 | I19: ='Country equity risk premiums'!B191 | J19: =H19/$H$30 | K19: =I19*J19
A20: If direct input, input the pre-tax cost of debt | B20: 0.035 | G20: ='Country equity risk premiums'!A192 | H20: =3159+4281 | I20: ='Country equity risk premiums'!B192 | J20: =H20/$H$30 | K20: =I20*J20
A21: If actual rating, input the rating | B21: Aa2/AA | G21: ='Country equity risk premiums'!A193 | I21: ='Country equity risk premiums'!B193 | J21: =H21/$H$30 | K21: =I21*J21
A22: If synethetic rating, input the type of company | B22: 1 | G22: ='Country equity risk premiums'!A194 | H22: 0 | I22: ='Country equity risk premiums'!B194 | J22: =H22/$H$30 | K22: =I22*J22
A23: Pre-tax Cost of Debt = | B23: =IF(B19="Direct Input",B20,IF(B19="Synthetic Rating",'Synthetic rating'!D13,B10+VLOOKUP('Cost of capital worksheet'!B21,'Synthetic rating'!G39:H53,2))) | G23: ='Country equity risk premiums'!A195 | H23: 0 | I23: ='Country equity risk premiums'!B195 | J23: =H23/$H$30 | K23: =I23*J23
A24: Tax Rate = | B24: ='Input sheet'!B21 | G24: ='Country equity risk premiums'!A196 | I24: ='Country equity risk premiums'!B196 | J24: =H24/$H$30 | K24: =I24*J24
G25: ='Country equity risk premiums'!A197 | H25: 0 | I25: ='Country equity risk premiums'!B197 | J25: =H25/$H$30 | K25: =I25*J25
A26: Book Value of Convertible Debt = | B26: 0 | G26: ='Country equity risk premiums'!A198 | H26: 93864 | I26: ='Country equity risk premiums'!B198 | J26: =H26/$H$30 | K26: =I26*J26
A27: Interest Expense on Convertible = | B27: 0 | G27: ='Country equity risk premiums'!A199 | I27: ='Country equity risk premiums'!B199 | J27: =H27/$H$30 | K27: =I27*J27
A28: Maturity of Convertible Bond = | B28: 0 | J28: =H28/$H$30 | K28: =I28*J28
A29: Market Value of Convertible = | B29: 0 | J29: =H29/$H$30 | K29: =I29*J29
G30: Total | H30: =SUM(H19:H29) | J30: =SUM(J19:J29) | K30: =SUM(K19:K29)
A31: Debt value of operating leases = | B31: =IF('Input sheet'!B14="Yes",'Operating lease converter'!F33,0)
G32: Multi Business (US Industry Averages)
A33: Preferred Stock | G33: Business | H33: Revenues | I33: EV/Sales | J33: Estimated Value | K33: Unlevered Beta
A34: Number of Preferred Shares = | B34: 0 | G34: Advertising | H34: 70 | I34: =IF(G34=0,,VLOOKUP(G34,'Industry Averages(US)'!$A$2:$S$95,15)) | J34: =H34*I34 | K34: =IF(I34=0,0,VLOOKUP(G34,'Industry Averages(US)'!$A$2:$S$95,7))
A35: Current Market Price per Share= | B35: 70 | G35: Computer Services | H35: 30 | I35: =IF(G35=0,,VLOOKUP(G35,'Industry Averages(US)'!$A$2:$S$95,15)) | J35: =H35*I35 | K35: =IF(I35=0,0,VLOOKUP(G35,'Industry Averages(US)'!$A$2:$S$95,7))
A36: Annual Dividend per Share = | B36: 5 | I36: =IF(G36=0,,VLOOKUP(G36,'Industry Averages(US)'!$A$2:$S$95,15)) | J36: =H36*I36 | K36: =IF(I36=0,0,VLOOKUP(G36,'Industry Averages(US)'!$A$2:$S$95,7))
I37: =IF(G37=0,,VLOOKUP(G37,'Industry Averages(US)'!$A$2:$S$95,15)) | J37: =H37*I37 | K37: =IF(I37=0,0,VLOOKUP(G37,'Industry Averages(US)'!$A$2:$S$95,7))
A38: Output | I38: =IF(G38=0,,VLOOKUP(G38,'Industry Averages(US)'!$A$2:$S$95,15)) | J38: =H38*I38 | K38: =IF(I38=0,0,VLOOKUP(G38,'Industry Averages(US)'!$A$2:$S$95,7))
A39: Estimating Market Value of Straight Debt = | C39: =B17*(1-(1+B23)^(-B18))/B23+B16/(1+B23)^B18 | I39: =IF(G39=0,,VLOOKUP(G39,'Industry Averages(US)'!$A$2:$S$95,15)) | J39: =H39*I39 | K39: =IF(I39=0,0,VLOOKUP(G39,'Industry Averages(US)'!$A$2:$S$95,7))
A40: Estimated Value of Straight Debt in Convertible = | C40: =B27*(1-(1+B23)^(-B28))/B23+B26/(1+B23)^B28 | I40: =IF(G40=0,,VLOOKUP(G40,'Industry Averages(US)'!$A$2:$S$95,15)) | J40: =H40*I40 | K40: =IF(I40=0,0,VLOOKUP(G40,'Industry Averages(US)'!$A$2:$S$95,7))
...

Sheet Synthetic rating
A1: Inputs for synthetic rating estimation
A2: Please read the special cases worksheet (see below) before you use this spreadsheet.
A3: Before you use this spreadsheet, make sure that the iteration box (under calculation options in excel) is checked.
A4: Enter the type of firm = | C4: ='Cost of capital worksheet'!B22
A5: Enter current Earnings before interest and taxes (EBIT) = | F5: =IF('Input sheet'!B14="Yes",'Input sheet'!B9+'Operating lease converter'!F32,'Input sheet'!B9) | G5: (Add back only long term interest expense for financial firms)
A6: Enter current interest expenses = | F6: =IF('Input sheet'!B14="Yes",'Cost of capital worksheet'!B17+'Operating lease converter'!C28*'Operating lease converter'!C15,'Cost of capital worksheet'!B17) | G6: (Use only long term interest expense for financial firms)
A7: Enter long term risk free rate = | F7: ='Input sheet'!B28
A8: Output
A9: Interest coverage ratio = | D9: =IF(F6=0,1000000,IF(F5<0,-100000,F5/F6))
A10: Estimated Bond Rating = | D10: =IF(C4=1,VLOOKUP(D9,A19:D33,3),(IF(C4=2,VLOOKUP(D9,A38:D52,3),VLOOKUP(D9,F19:I33,3)))) | F10: Note: If you get REF! All over the place, set the operating lease commitment question in cell F5
A11: Estimated Company Default Spread = | D11: =IF(C4=1,VLOOKUP(D9,A19:D33,4),(IF(C4=2,VLOOKUP(D9,A38:D52,4),VLOOKUP(D9,F19:I33,4)))) | F11: to No, and then reset it to Yes. It should work.
A12: Estimated County Default Spread (if any) = | D12: =VLOOKUP('Input sheet'!B5,'Country equity risk premiums'!A2:C187,3)
A13: Estimated Cost of Debt = | D13: =F7+D11+D12
A15: If you want to update the spreads listed below, please visit http://www.bondsonline.com
A16: For large manufacturing firms
A17: If interest coverage ratio is
A18: > | B18: ≤ to | C18: Rating is | D18: Spread is
A19: -100000 | B19: 0.199999 | C19: D2/D | D19: 0.186
A20: 0.2 | B20: 0.649999 | C20: Caa/CCC | D20: 0.1395
A21: 0.65 | B21: 0.799999 | C21: Ca2/CC | D21: 0.1063
A22: 0.8 | B22: 1.249999 | C22: C2/C | D22: 0.0864
A23: 1.25 | B23: 1.499999 | C23: B3/B- | D23: 0.0437
A24: 1.5 | B24: 1.749999 | C24: B2/B | D24: 0.0357
A25: 1.75 | B25: 1.999999 | C25: B1/B+ | D25: 0.0298
A26: 2 | B26: 2.2499999 | C26: Ba2/BB | D26: 0.0238
A27: 2.25 | B27: 2.49999 | C27: Ba1/BB+ | D27: 0.0198
A28: 2.5 | B28: 2.999999 | C28: Baa2/BBB | D28: 0.0127
A29: 3 | B29: 4.249999 | C29: A3/A- | D29: 0.0113
A30: 4.25 | B30: 5.499999 | C30: A2/A | D30: 0.0099
... A33: 8.5 | B33: 100000 | C33: Aaa/AAA | D33: 0.0054
A35: For smaller and riskier firms
A36: If interest coverage ratio is
A37: greater than | B37: ≤ to | C37: Rating is | D37: Spread is
A38: -100000 | B38: 0.499999 | C38: D2/D | D38: 0.186 | G38: Rating is | H38: Spread is
