Workbook

Sheet Valuation Comparison
A1: Amazon Valuation - September 2018
A2: Comparison: Base Case vs. Review Scenario
A4: KEY ASSUMPTIONS
A5: Assumption | B5: Base Case | C5: Review Scenario | D5: Difference
A6: Revenue Growth (Years 1-5) | B6: ='Input sheet'!B23 | C6: ='Input sheet'!B23 | D6: =C6-B6
A7: Terminal Revenue Growth | B7: ='Valuation output'!M2 | C7: ='Valuation output'!AA2 | D7: =C7-B7
A8: Terminal Operating Margin | B8: ='Valuation output'!M4 | C8: ='Valuation output'!AA4 | D8: =C8-B8
A9: Cost of Capital (Initial) | B9: ='Input sheet'!B29 | C9: ='Input sheet'!B29 | D9: =C9-B9
A10: Cost of Capital (Terminal) | B10: ='Valuation output'!M12 | C10: ='Valuation output'!AA12 | D10: =C10-B10
A12: VALUATION RESULTS
A13: Metric | B13: Base Case | C13: Review Scenario | D13: Difference | E13: % Difference
A14: Value of Operating Assets | B14: ='Valuation output'!B24 | C14: ='Valuation output'!P24 | D14: =C14-B14 | E14: =D14/B14
A15: Value of Equity | B15: ='Valuation output'!B29 | C15: ='Valuation output'!P29 | D15: =C15-B15 | E15: =D15/B15
A16: Value per Share | B16: ='Valuation output'!B33 | C16: ='Valuation output'!P33 | D16: =C16-B16 | E16: =D16/B16
A17: Number of Shares | B17: ='Valuation output'!B32 | C17: ='Valuation output'!P32 | D17: =C17-B17
A18: Market Price | B18: ='Valuation output'!B34 | C18: ='Valuation output'!P34 | D18: =C18-B18
A20: EXPLANATION
A21: The review scenario reduces the terminal operating margin target by 2 percentage points
A22: compared to the base case. The linear convergence from the base year margin to the
A23: terminal margin follows the same transition convention as the original model over
A24: the convergence period specified in the input sheet. All other assumptions (growth
A25: rates, cost of capital, reinvestment assumptions) remain identical between the two cases.
A27: The equity value difference reflects the impact of lower profitability on terminal value,
A28: flowing through to reduced cash flows in all forecast periods as margins converge to
A29: the lower target.

Sheet CB_DATA_
A1: Crystal Ball Data
A3: Workbook Variables | B3: Last Var Column | C3: 0
A4: Name:
A5: Value:
A7: Worksheet Data | B7: Last Data Column Used
B8: 3
A10: Sheet Ref
A11: =CB_DATA_!#REF! | B11: ='Input sheet'!#REF! | C11: ='Valuation output'!#REF!
A13: Sheet Guid
A14: 271d6a2b-7a93-4e27-808c-aa1aada6a76d | B14: eb12ad88-c3be-4256-b53f-793e1373a468 | C14: faa3ee01-9bfb-4333-b742-7cca748c6e20
A16: Deleted sheet count
A19: Last row used
A20: 28 | B20: 31 | C20: 31

Sheet Input sheet
A1: Date of valuation | B1: 41882 | C1: Important: Before you run this spreadsheet, go into preferences in Excel and check under Calculation options
A2: Company name | B2: Amazon | C2: There should be a check against the iteration box. If there is not, you will get circular reasoning errors.
A3: Numbers from your base year below ( in consistent units)
B4: This year | C4: Last year
A5: Country of incorporation | B5: United States
A6: Industry (US) | B6: Retail (General)
A7: Industry (Global) | B7: Retail (General) | C7: Last 10K | D7: Years since last 10K
A8: Revenues | B8: 208125 | C8: 177866 | D8: 0.5
A9: Operating income or EBIT | B9: 7385 | C9: 4106 | D9: 0.5
A10: Interest expense | B10: 1239 | C10: 848
A11: Book value of equity | B11: 34995 | C11: 27709
A12: Book value of debt | B12: 27050 | C12: 24473
A13: Do you have R&D expenses to capitalize? | B13: Yes | C13: If you want to capitalize R&D, you have to input the numbers into the R&D worksheet.
A14: Do you have operating lease commitments? | B14: Yes | C14: If you have operating leases, please enter your lease commitments in the lease worksheet below and I will convert to debt
A15: Cash and Marketable Securities | B15: 27050 | C15: 30986
A16: Cross holdings and other non-operating assets | B16: 0 | C16: 0
A17: Minority interests | B17: 0 | C17: 0
A18: Number of shares outstanding = | B18: 497
A19: Current stock price = | B19: 1970.19 | E19: Computed numbers: Here is what your company's numbers look like, relative to industry.
A20: Effective tax rate = | B20: =769/3806 | E20: If you are not working in US dollars, you should add the inflation differential to the industry averages.
A21: Marginal tax rate = | B21: 0.24 | I21: Company | J21: Industry (US data) | K21: Industry (Global data)
A22: The value drivers below: | E22: Revenue growth in the most recent year = | I22: =IF(C8>0,(B8/C8)^(1/D8)-1, "NA") | J22: =VLOOKUP(B6,'Industry Averages(US)'!A2:S95,3) | K22: =VLOOKUP(B7,'Global industry averages'!A2:N95,3)
A23: Compounded annual revenue growth rate over next 5 years = | B23: 0.16 | C23: Growth Lever | E23: Pre-tax operating margin in the most recent year = | I23: ='Valuation output'!B4 | J23: =VLOOKUP(B6,'Industry Averages(US)'!A2:S95,4) | K23: =VLOOKUP(B7,'Global industry averages'!A2:N95,4)
A24: Target pre-tax operating margin (EBIT as % of sales in year 10) = | B24: 0.125 | C24: Profitability Lever | E24: Sales to capital ratio in most recent year = | I24: =B8/(B11+B12-B15) | J24: =VLOOKUP(B6,'Industry Averages(US)'!A2:S95,14) | K24: =VLOOKUP(B7,'Global industry averages'!A2:N95,14)
A25: Year of convergence | B25: 5 | C25: Speed of convergence level | E25: Return on invested capital in most recent year= | I25: ='Valuation output'!B7/'Valuation output'!B39 | J25: =VLOOKUP(B6,'Industry Averages(US)'!A2:S95,5) | K25: =VLOOKUP(B7,'Global industry averages'!A2:N95,5)
A26: Sales to capital ratio (for computing reinvestment) = | B26: =I24 | C26: Efficency of Growth Lever | E26: Standard deviation in stock prices = | J26: =VLOOKUP(B6,'Industry Averages(US)'!A2:S95,10) | K26: =VLOOKUP(B6,'Global industry averages'!A2:Z95,10)
A27: Market numbers | E27: Cost of capital = | J27: =VLOOKUP(B6,'Industry Averages(US)'!A2:S95,13) | K27: =VLOOKUP(B6,'Global industry averages'!A2:Z95,13)
A28: Riskfree rate | B28: 0.03
A29: Initial cost of capital = | B29: 0.0797 | E29: Valuation Output Feedback (for you to use to fine tune your inputs, if you want)
A30: Other inputs | E30: Revenues in year 10, based on your revenue growth = | J30: ='Valuation output'!M3
A31: Do you have employee options outstanding? | B31: No | E31: Pre-tax Operating Income in year 10, based on your operating margin = | J31: ='Valuation output'!M5
A32: Number of options outstanding = | B32: 21.65 | E32: Return on invested capital in year 10, based on your sales/capital ratio = | J32: ='Valuation output'!L40
A33: Average strike price = | B33: 61.13 | E33: Check the Diagnostics worksheet for more details.
A34: Average maturity = | B34: 5.97
A35: Standard deviation on stock price = | B35: 0.3
A37: Default assumptions.
A38: In stable growth, I will assume that your firm will have a cost of capital similar to that of typical mature companies (riskfree rate + 4.5%)
A39: Do you want to override this assumption = | B39: Yes | C39: Mature companies generally see their risk levels approach the average
A40: If yes, enter the cost of capital after year 10 = | B40: 0.075 | C40: Though some sectors, even in stable growth, may have higher risk.
A41: I will assume that your firm will earn a return on capital equal to its cost of capital after year 10. I am assuming that whatever competitive advantages you have today will fade over time.
...

Sheet Valuation output
B1: Base year | C1: 1 | D1: 2 | E1: 3 | F1: 4 | G1: 5 | H1: 6 | I1: 7 | J1: 8 | K1: 9 | L1: 10 | M1: Terminal year | O1: REVIEW SCENARIO | P1: Base year | Q1: 1 | R1: 2 | S1: 3 | T1: 4 | U1: 5 | V1: 6 | W1: 7 | X1: 8 | Y1: 9 | Z1: 10 | AA1: Terminal year
A2: Revenue growth rate | C2: ='Input sheet'!B23 | D2: =C2 | E2: =D2 | F2: =E2 | G2: =F2 | H2: =G2-((G2-$M$2)/5) | I2: =G2-((G2-$M$2)/5)*2 | J2: =G2-((G2-$M$2)/5)*3 | K2: =G2-((G2-$M$2)/5)*4 | L2: =G2-((G2-$M$2)/5)*5 | M2: =IF('Input sheet'!B55="Yes",'Input sheet'!B56,'Input sheet'!B28) | O2: Revenue growth rate | Q2: =C2 | R2: =D2 | S2: =E2 | T2: =F2 | U2: =G2 | V2: =H2 | W2: =I2 | X2: =J2 | ... AA2: =M2
A3: Revenues | B3: ='Input sheet'!B8 | C3: =B3*(1+C2) | D3: =C3*(1+D2) | E3: =D3*(1+E2) | F3: =E3*(1+F2) | G3: =F3*(1+G2) | H3: =G3*(1+H2) | I3: =H3*(1+I2) | J3: =I3*(1+J2) | ... M3: =L3*(1+M2) | O3: Revenues | P3: =B3 | Q3: =P3*(1+Q2) | R3: =Q3*(1+R2) | S3: =R3*(1+S2) | T3: =S3*(1+T2) | U3: =T3*(1+U2) | V3: =U3*(1+V2) | W3: =V3*(1+W2) | X3: =W3*(1+X2) | ... AA3: =Z3*(1+AA2)
A4: EBIT (Operating) margin | B4: =B5/B3 | C4: =IF(C1>'Input sheet'!$B$25,'Input sheet'!$B$24,'Input sheet'!$B$24-(('Input sheet'!$B$24-$B$4)/'Input sheet'!$B$25)*('Input sheet'!$B$25-C1)) | D4: =IF(D1>'Input sheet'!$B$25,'Input sheet'!$B$24,'Input sheet'!$B$24-(('Input sheet'!$B$24-$B$4)/'Input sheet'!$B$25)*('Input sheet'!$B$25-D1)) | E4: =IF(E1>'Input sheet'!$B$25,'Input sheet'!$B$24,'Input sheet'!$B$24-(('Input sheet'!$B$24-$B$4)/'Input sheet'!$B$25)*('Input sheet'!$B$25-E1)) | F4: =IF(F1>'Input sheet'!$B$25,'Input sheet'!$B$24,'Input sheet'!$B$24-(('Input sheet'!$B$24-$B$4)/'Input sheet'!$B$25)*('Input sheet'!$B$25-F1)) | G4: =IF(G1>'Input sheet'!$B$25,'Input sheet'!$B$24,'Input sheet'!$B$24-(('Input sheet'!$B$24-$B$4)/'Input sheet'!$B$25)*('Input sheet'!$B$25-G1)) | H4: =IF(H1>'Input sheet'!$B$25,'Input sheet'!$B$24,'Input sheet'!$B$24-(('Input sheet'!$B$24-$B$4)/'Input sheet'!$B$25)*('Input sheet'!$B$25-H1)) | I4: =IF(I1>'Input sheet'!$B$25,'Input sheet'!$B$24,'Input sheet'!$B$24-(('Input sheet'!$B$24-$B$4)/'Input sheet'!$B$25)*('Input sheet'!$B$25-I1)) | J4: =IF(J1>'Input sheet'!$B$25,'Input sheet'!$B$24,'Input sheet'!$B$24-(('Input sheet'!$B$24-$B$4)/'Input sheet'!$B$25)*('Input sheet'!$B$25-J1)) | ... L4: =IF(L1>'Input sheet'!$B$25,'Input sheet'!$B$24,'Input sheet'!$B$24-(('Input sheet'!$B$24-$B$4)/'Input sheet'!$B$25)*('Input sheet'!$B$25-L1)) | M4: =L4 | O4: EBIT (Operating) margin | P4: =B4 | Q4: =IF(Q1>'Input sheet'!$B$25,'Input sheet'!$B$24-0.02,('Input sheet'!$B$24-0.02)-(('Input sheet'!$B$24-0.02-$P$4)/'Input sheet'!$B$25)*('Input sheet'!$B$25-Q1)) | R4: =IF(R1>'Input sheet'!$B$25,'Input sheet'!$B$24-0.02,('Input sheet'!$B$24-0.02)-(('Input sheet'!$B$24-0.02-$P$4)/'Input sheet'!$B$25)*('Input sheet'!$B$25-R1)) | S4: =IF(S1>'Input sheet'!$B$25,'Input sheet'!$B$24-0.02,('Input sheet'!$B$24-0.02)-(('Input sheet'!$B$24-0.02-$P$4)/'Input sheet'!$B$25)*('Input sheet'!$B$25-S1)) | T4: =IF(T1>'Input sheet'!$B$25,'Input sheet'!$B$24-0.02,('Input sheet'!$B$24-0.02)-(('Input sheet'!$B$24-0.02-$P$4)/'Input sheet'!$B$25)*('Input sheet'!$B$25-T1)) | U4: =IF(U1>'Input sheet'!$B$25,'Input sheet'!$B$24-0.02,('Input sheet'!$B$24-0.02)-(('Input sheet'!$B$24-0.02-$P$4)/'Input sheet'!$B$25)*('Input sheet'!$B$25-U1)) | V4: =IF(V1>'Input sheet'!$B$25,'Input sheet'!$B$24-0.02,('Input sheet'!$B$24-0.02)-(('Input sheet'!$B$24-0.02-$P$4)/'Input sheet'!$B$25)*('Input sheet'!$B$25-V1)) | W4: =IF(W1>'Input sheet'!$B$25,'Input sheet'!$B$24-0.02,('Input sheet'!$B$24-0.02)-(('Input sheet'!$B$24-0.02-$P$4)/'Input sheet'!$B$25)*('Input sheet'!$B$25-W1)) | X4: =IF(X1>'Input sheet'!$B$25,'Input sheet'!$B$24-0.02,('Input sheet'!$B$24-0.02)-(('Input sheet'!$B$24-0.02-$P$4)/'Input sheet'!$B$25)*('Input sheet'!$B$25-X1)) | ... Z4: =IF(Z1>'Input sheet'!$B$25,'Input sheet'!$B$24-0.02,('Input sheet'!$B$24-0.02)-(('Input sheet'!$B$24-0.02-$P$4)/'Input sheet'!$B$25)*('Input sheet'!$B$25-Z1)) | AA4: =Z4
A5: EBIT (Operating income) | B5: =IF('Input sheet'!B14="Yes",IF('Input sheet'!B13="Yes",'Input sheet'!B9+'Operating lease converter'!F32+'R& D converter'!D39,'Input sheet'!B9+'Operating lease converter'!F32),IF('Input sheet'!B13="Yes",'Input sheet'!B9+'R& D converter'!D39,'Input sheet'!B9)) | C5: =C3*C4 | D5: =D3*D4 | E5: =E3*E4 | F5: =F3*F4 | G5: =G3*G4 | H5: =H3*H4 | I5: =I3*I4 | J5: =J3*J4 | ... M5: =M3*M4 | N5: =M5-B5 | O5: EBIT (Operating income) | Q5: =Q3*Q4 | R5: =R3*R4 | S5: =S3*S4 | T5: =T3*T4 | U5: =U3*U4 | V5: =V3*V4 | W5: =W3*W4 | X5: =X3*X4 | ... AA5: =AA3*AA4
A6: Tax rate | B6: ='Input sheet'!B20 | C6: =B6 | D6: =C6 | E6: =D6 | F6: =E6 | G6: =F6 | H6: =G6+($M$6-$G$6)/5 | I6: =H6+($M$6-$G$6)/5 | J6: =I6+($M$6-$G$6)/5 | K6: =J6+($M$6-$G$6)/5 | L6: =K6+($M$6-$G$6)/5 | M6: =IF('Input sheet'!B50="Yes",'Input sheet'!B20,'Input sheet'!B21) | O6: Tax rate | P6: =B6 | Q6: =C6 | R6: =D6 | S6: =E6 | T6: =F6 | U6: =G6 | V6: =H6 | W6: =I6 | ... AA6: =M6
A7: EBIT(1-t) | B7: =IF(B5>0,B5*(1-B6),B5) | C7: =IF(C5>0,MAX(C5*(1-C6)-C10,C5),C5) | D7: =IF(D5>0,MAX(D5*(1-D6)-D10,D5),D5) | E7: =IF(E5>0,MAX(E5*(1-E6)-E10,E5),E5) | F7: =IF(F5>0,MAX(F5*(1-F6)-F10,F5),F5) | G7: =IF(G5>0,MAX(G5*(1-G6)-G10,G5),G5) | H7: =IF(H5>0,MAX(H5*(1-H6)-H10,H5),H5) | I7: =IF(I5>0,MAX(I5*(1-I6)-I10,I5),I5) | J7: =IF(J5>0,MAX(J5*(1-J6)-J10,J5),J5) | ... L7: =IF(L5>0,MAX(L5*(1-L6)-L10,L5),L5) | M7: =M5*(1-M6) | O7: EBIT(1-t) | Q7: =IF(Q5>0,MAX(Q5*(1-Q6)-Q10,Q5),Q5) | R7: =IF(R5>0,MAX(R5*(1-R6)-R10,R5),R5) | S7: =IF(S5>0,MAX(S5*(1-S6)-S10,S5),S5) | T7: =IF(T5>0,MAX(T5*(1-T6)-T10,T5),T5) | U7: =IF(U5>0,MAX(U5*(1-U6)-U10,U5),U5) | V7: =IF(V5>0,MAX(V5*(1-V6)-V10,V5),V5) | W7: =IF(W5>0,MAX(W5*(1-W6)-W10,W5),W5) | X7: =IF(X5>0,MAX(X5*(1-X6)-X10,X5),X5) | ... Z7: =IF(Z5>0,MAX(Z5*(1-Z6)-Z10,Z5),Z5) | AA7: =AA5*(1-AA6)
A8: - Reinvestment | C8: =(C3-B3)/C38 | D8: =(D3-C3)/D38 | E8: =(E3-D3)/E38 | F8: =(F3-E3)/F38 | G8: =(G3-F3)/G38 | H8: =(H3-G3)/H38 | I8: =(I3-H3)/I38 | J8: =(J3-I3)/J38 | ... L8: =(L3-K3)/L38 | M8: =(M3*M2)/M38 | N8: =SUM(C8:M8) | O8: - Reinvestment | Q8: =(Q3-P3)/Q38 | R8: =(R3-Q3)/R38 | S8: =(S3-R3)/S38 | T8: =(T3-S3)/T38 | U8: =(U3-T3)/U38 | V8: =(V3-U3)/V38 | W8: =(W3-V3)/W38 | X8: =(X3-W3)/X38 | ... Z8: =(Z3-Y3)/Z38 | AA8: =(AA3*AA2)/AA38
A9: FCFF | C9: =C7-C8 | D9: =D7-D8 | E9: =E7-E8 | F9: =F7-F8 | G9: =G7-G8 | H9: =H7-H8 | I9: =I7-I8 | J9: =J7-J8 | ... M9: =M7-M8 | O9: FCFF | Q9: =Q7-Q8 | R9: =R7-R8 | S9: =S7-S8 | T9: =T7-T8 | U9: =U7-U8 | V9: =V7-V8 | W9: =W7-W8 | X9: =X7-X8 | ... AA9: =AA7-AA8
A10: NOL | B10: =IF('Input sheet'!B52="Yes",'Input sheet'!B53,0) | C10: =IF(C5>0,MAX(B10-C5*C6,0),B10-C5) | D10: =IF(D5>0,MAX(C10-D5*D6,0),C10-D5) | E10: =IF(E5>0,MAX(D10-E5*E6,0),D10-E5) | F10: =IF(F5>0,MAX(E10-F5*F6,0),E10-F5) | G10: =IF(G5>0,MAX(F10-G5*G6,0),F10-G5) | H10: =IF(H5>0,MAX(G10-H5*H6,0),G10-H5) | I10: =IF(I5>0,MAX(H10-I5*I6,0),H10-I5) | J10: =IF(J5>0,MAX(I10-J5*J6,0),I10-J5) | ... M10: =IF(M5>0,MAX(L10-M5*M6,0),L10-M5) | O10: NOL | P10: =B10 | Q10: =IF(Q5>0,MAX(P10-Q5*Q6,0),P10-Q5) | R10: =IF(R5>0,MAX(Q10-R5*R6,0),Q10-R5) | S10: =IF(S5>0,MAX(R10-S5*S6,0),R10-S5) | T10: =IF(T5>0,MAX(S10-T5*T6,0),S10-T5) | U10: =IF(U5>0,MAX(T10-U5*U6,0),T10-U5) | V10: =IF(V5>0,MAX(U10-V5*V6,0),U10-V5) | W10: =IF(W5>0,MAX(V10-W5*W6,0),V10-W5) | X10: =IF(X5>0,MAX(W10-X5*X6,0),W10-X5) | ... AA10: =IF(AA5>0,MAX(Z10-AA5*AA6,0),Z10-AA5)
A12: Cost of capital | C12: ='Input sheet'!B29 | D12: =C12 | E12: =D12 | F12: =E12 | G12: =F12 | H12: =G12-($G$12-$M$12)/5 | I12: =H12-($G$12-$M$12)/5 | J12: =I12-($G$12-$M$12)/5 | K12: =J12-($G$12-$M$12)/5 | L12: =K12-($G$12-$M$12)/5 | M12: =IF('Input sheet'!B39="Yes",'Input sheet'!B40,'Input sheet'!B28+0.045) | O12: Cost of capital | Q12: =C12 | R12: =D12 | S12: =E12 | T12: =F12 | U12: =G12 | V12: =H12 | W12: =I12 | X12: =J12 | ... AA12: =M12
A13: Cumulated discount factor | C13: =1/(1+C12) | D13: =C13*(1/(1+D12)) | E13: =D13*(1/(1+E12)) | F13: =E13*(1/(1+F12)) | G13: =F13*(1/(1+G12)) | H13: =G13*(1/(1+H12)) | I13: =H13*(1/(1+I12)) | J13: =I13*(1/(1+J12)) | K13: =J13*(1/(1+K12)) | L13: =K13*(1/(1+L12)) | M13: =L13/(1+M12) | O13: Cumulated discount factor | Q13: =1/(1+Q12) | R13: =Q13/(1+R12) | S13: =R13/(1+S12) | T13: =S13/(1+T12) | U13: =T13/(1+U12) | V13: =U13/(1+V12) | W13: =V13/(1+W12) | X13: =W13/(1+X12) | Y13: =X13/(1+Y12) | ... AA13: =Z13/(1+AA12)
A14: PV(FCFF) | C14: =C9*C13 | D14: =D9*D13 | E14: =E9*E13 | F14: =F9*F13 | G14: =G9*G13 | H14: =H9*H13 | I14: =I9*I13 | J14: =J9*J13 | ... M14: =M9*M13 | O14: PV(FCFF) | Q14: =Q9*Q13 | R14: =R9*R13 | S14: =S9*S13 | T14: =T9*T13 | U14: =U9*U13 | V14: =V9*V13 | W14: =W9*W13 | X14: =X9*X13 | ... AA14: =AA9*AA13
A16: Terminal cash flow | M16: =M9 | O16: Terminal cash flow | AA16: =AA9
A17: Terminal cost of capital | M17: =M12 | O17: Terminal cost of capital | AA17: =AA12
A18: Terminal value | M18: =M16/(M17-M2) | O18: Terminal value | AA18: =AA16/(AA17-AA2)
A19: PV(Terminal value) | M19: =M18*M13 | O19: PV(Terminal value) | AA19: =AA18*AA13
A20: PV (CF over next 10 years) | B20: =SUM(C14:L14) | O20: PV (CF over next 10 years) | P20: =SUM(Q14:Z14)
A21: Sum of PV | B21: =B20+M19 | O21: Sum of PV | P21: =P20+AA19
A22: Probability of failure = | B22: =IF('Input sheet'!B45="Yes",'Input sheet'!B46,0) | O22: Probability of failure = | P22: =B22
A23: Proceeds if firm fails = | B23: =IF('Input sheet'!B47="V",B21*'Input sheet'!B48,IF('Input sheet'!B47="BV",'Input sheet'!B11*'Input sheet'!B48,0)) | O23: Proceeds if firm fails = | P23: =IF('Input sheet'!B47="V",P21*'Input sheet'!B48,IF('Input sheet'!B47="BV",'Input sheet'!B11*'Input sheet'!B48,0))
A24: Value of operating assets = | B24: =B21*(1-B22)+B22*B23 | O24: Value of operating assets = | P24: =P21*(1-P22)+P22*P23
A25: - Debt | B25: ='Input sheet'!B12 | O25: - Debt | P25: =B25
A26: - Minority interests | B26: ='Input sheet'!B17 | O26: - Minority interests | P26: =B26
A27: + Cash | B27: =IF('Input sheet'!B58="Yes",'Input sheet'!B15-'Input sheet'!B59,'Input sheet'!B15) | O27: + Cash | P27: =B27
A28: + Non-operating assets | B28: ='Input sheet'!B16 | O28: + Non-operating assets | P28: =B28
A29: Value of equity | B29: =B24-B25-B26+B27+B28 | O29: Value of equity | P29: =P24-P25-P26+P27+P28
A30: - Value of options | B30: =IF('Input sheet'!B31="Yes",'Option value'!H18,0) | O30: - Value of options | P30: =B30
A31: Value of equity in common stock | B31: =B29-B30 | O31: Value of equity in common stock | P31: =P29-P30
A32: Number of shares | B32: ='Input sheet'!B18 | O32: Number of shares | P32: =B32
A33: Estimated value /share | B33: =B31/B32 | O33: Estimated value /share | P33: =P31/P32
A34: Price | B34: ='Input sheet'!B19 | O34: Price | P34: =B34
A35: Price as % of value | B35: =B34/B33 | O35: Price as % of value | P35: =P34/P33
A37: Implied variables | M37: After year 10 | O37: Implied variables
A38: Sales to capital ratio | C38: ='Input sheet'!B26 | D38: =C38 | E38: =C38 | F38: =C38 | G38: =C38 | H38: =C38 | I38: =C38 | J38: =C38 | K38: =C38 | L38: =C38 | M38: =(M12-M2)/M40 | O38: Sales to capital ratio | Q38: =C38 | R38: =D38 | S38: =E38 | T38: =F38 | U38: =G38 | V38: =H38 | W38: =I38 | X38: =J38 | ... Z38: =L38 | AA38: =(AA12-AA2)/AA40
A39: Invested capital | B39: =IF('Input sheet'!B14="Yes",IF('Input sheet'!B13="Yes",'Input sheet'!B11+'Input sheet'!B12-'Input sheet'!B15+'Operating lease converter'!F33+'R& D converter'!D35,'Input sheet'!B11+'Input sheet'!B12-'Input sheet'!B15+'Operating lease converter'!F33),IF('Input sheet'!B13="Yes",'Input sheet'!B11+'Input sheet'!B12-'Input sheet'!B15+'R& D converter'!D35,'Input sheet'!B11+'Input sheet'!B12-'Input sheet'!B15)) | C39: =B39+C8 | D39: =C39+D8 | E39: =D39+E8 | F39: =E39+F8 | G39: =F39+G8 | H39: =G39+H8 | I39: =H39+I8 | J39: =I39+J8 | ... M39: =L39+M8 | O39: Invested capital | P39: =B39 | Q39: =P39+Q8 | R39: =Q39+R8 | S39: =R39+S8 | T39: =S39+T8 | U39: =T39+U8 | V39: =U39+V8 | W39: =V39+W8 | X39: =W39+X8 | ... AA39: =Z39+AA8
A40: ROIC | B40: =B7/B39 | C40: =C7/C39 | D40: =D7/D39 | E40: =E7/E39 | F40: =F7/F39 | G40: =G7/G39 | H40: =H7/H39 | I40: =I7/I39 | ... L40: =L7/L39 | M40: =IF('Input sheet'!B42="Yes",'Input sheet'!B43,M12) | O40: ROIC | Q40: =Q7/Q39 | R40: =R7/R39 | S40: =S7/S39 | T40: =T7/T39 | U40: =U7/U39 | V40: =V7/V39 | W40: =W7/W39 | X40: =X7/X39 | ... Z40: =Z7/Z39 | AA40: =IF('Input sheet'!B42="Yes",'Input sheet'!B43,AA12)

Sheet Stories to Numbers
A1: ='Input sheet'!B2
A2: The Greatest (and most Feared) Disruptive Platform in History
A3: Amazon will complete its metaphorsis from being a retail company to one that can take its competitive advantages - access to capital & willingness to lose money for long periods, while disrupting and changing the status quo - to any business that it targets, giving it the potential for high revenue growth on top of already-large revenues. It will be able to use the pricing power it accumulates in each business it is in, to increase profit margins, partly through economies of scale and partly through higher prices. Its low debt ratio and divergent business mix give it a low cost of capital. | H3: Tell your story about the company. Keep it focuses on the company's businesses and tie it into the three key levers of value: cash flows, growth and risk
A7: The Assumptions
B8: Base year | C8: Years 1-5 | D8: Years 6-10 | F8: After year 10 | G8: Link to story
A9: Revenues (a) | B9: ='Valuation output'!B3 | C9: ='Input sheet'!B23 | D9: =F9 | F9: ='Valuation output'!M2 | G9: Expanding into new businessses | H9: Tie each assumption to the part of your story that relates to it.
A10: Operating margin (b) | B10: ='Valuation output'!B4 | C10: =B10 | D10: =F10 | F10: ='Valuation output'!M4 | G10: Economies of scale and pricing power increase margins
A11: Tax rate | B11: ='Valuation output'!B6 | C11: =B11 | D11: =F11 | F11: ='Valuation output'!M6 | G11: Converging on a global tax rate of 25%
A12: Reinvestment (c ) | C12: Sales to capital ratio = | D12: ='Input sheet'!B26 | E12: RIR = | F12: ='Valuation output'!M2/'Valuation output'!M40 | G12: Big payoffs from investing in technology and content
A13: Return on capital | B13: ='Valuation output'!B40 | C13: Marginal ROIC = | D13: =Diagnostics!B6 | F13: ='Valuation output'!M40 | G13: The last man standing…
A14: Cost of capital (d) | C14: ='Valuation output'!C12 | D14: =F14 | F14: ='Valuation output'!M12 | G14: Low debt & diverse business mix
A15: The Cash Flows
B16: Revenues | C16: Operating Margin | D16: EBIT | E16: EBIT (1-t) | F16: Reinvestment | G16: FCFF | H16: These are the numbers that come from your assumptions. The revenues over time reflect your revenue growth, the operating margins evolve towards your target margin and your tax rate will change, if you have set it to. The reinvestment is estimated using the sales to capital ratio for the first 10 years and based on a reinvestment rate in stable growth (g/ ROC).
A17: 1 | B17: ='Valuation output'!C3 | C17: ='Valuation output'!C4 | D17: =B17*C17 | E17: ='Valuation output'!C7 | F17: ='Valuation output'!C8 | G17: =E17-F17
A18: 2 | B18: ='Valuation output'!D3 | C18: ='Valuation output'!D4 | D18: =B18*C18 | E18: ='Valuation output'!D7 | F18: ='Valuation output'!D8 | G18: =E18-F18
A19: 3 | B19: ='Valuation output'!E3 | C19: ='Valuation output'!E4 | D19: =B19*C19 | E19: ='Valuation output'!E7 | F19: ='Valuation output'!E8 | G19: =E19-F19
A20: 4 | B20: ='Valuation output'!F3 | C20: ='Valuation output'!F4 | D20: =B20*C20 | E20: ='Valuation output'!F7 | F20: ='Valuation output'!F8 | G20: =E20-F20
A21: 5 | B21: ='Valuation output'!G3 | C21: ='Valuation output'!G4 | D21: =B21*C21 | E21: ='Valuation output'!G7 | F21: ='Valuation output'!G8 | G21: =E21-F21
A22: 6 | B22: ='Valuation output'!H3 | C22: ='Valuation output'!H4 | D22: =B22*C22 | E22: ='Valuation output'!H7 | F22: ='Valuation output'!H8 | G22: =E22-F22
A23: 7 | B23: ='Valuation output'!I3 | C23: ='Valuation output'!I4 | D23: =B23*C23 | E23: ='Valuation output'!I7 | F23: ='Valuation output'!I8 | G23: =E23-F23
A24: 8 | B24: ='Valuation output'!J3 | C24: ='Valuation output'!J4 | D24: =B24*C24 | E24: ='Valuation output'!J7 | F24: ='Valuation output'!J8 | G24: =E24-F24
A25: 9 | B25: ='Valuation output'!K3 | C25: ='Valuation output'!K4 | D25: =B25*C25 | E25: ='Valuation output'!K7 | F25: ='Valuation output'!K8 | G25: =E25-F25
A26: 10 | B26: ='Valuation output'!L3 | C26: ='Valuation output'!L4 | D26: =B26*C26 | E26: ='Valuation output'!L7 | F26: ='Valuation output'!L8 | G26: =E26-F26
A27: Terminal year | B27: ='Valuation output'!M3 | C27: ='Valuation output'!M4 | D27: =B27*C27 | E27: ='Valuation output'!M7 | F27: ='Valuation output'!M8 | G27: =E27-F27
A28: The Value
A29: Terminal value | D29: ='Valuation output'!B18 | H29: This is the output from your valuation. It reflects your cash flows being discounted back at the cost of capital to get to your operating asset value, which then gets adjusted for the likelihood that your firm will not make it. We add cash and non-operating assets, subtract out debt and minority interests to get to value of equity.
A30: PV(Terminal value) | D30: ='Valuation output'!B19
A31: PV (CF over next 10 years) | D31: ='Valuation output'!B20
A32: Value of operating assets = | D32: ='Valuation output'!B21
A33: Adjustment for distress | D33: =D32-'Valuation output'!B24 | E33: Probability of failure = | G33: ='Valuation output'!B22
A34: - Debt & Mnority Interests | D34: ='Valuation output'!B25+'Valuation output'!B26
A35: + Cash & Other Non-operating assets | D35: ='Valuation output'!B27+'Valuation output'!B28
A36: Value of equity | D36: =D32-D33-D34+D35
A37: - Value of equity options | D37: ='Valuation output'!B30
A38: Number of shares | D38: ='Valuation output'!B32
A39: Value per share | D39: =(D36-D37)/D38 | E39: Stock was trading at = | G39: ='Input sheet'!B19
J43: =D39/1944

Sheet Summary Sheet
A1: Year | B1: Revenues | C1: Revenue Growth Rate | D1: Pre-Tax Operating Margin | E1: Pre-Tax Operating Income | F1: NOL | G1: Taxes | H1: After-Tax Operating Income
A2: Traling 12 month | B2: ='Valuation output'!B3 | D2: ='Valuation output'!B4 | E2: =B2*D2 | F2: ='Valuation output'!B10 | G2: =E2-H2 | H2: ='Valuation output'!B7
A3: 1 | B3: ='Valuation output'!C3 | C3: ='Valuation output'!C2 | D3: ='Valuation output'!C4 | E3: =B3*D3 | F3: ='Valuation output'!C10 | G3: =E3-H3 | H3: ='Valuation output'!C7
A4: 2 | B4: ='Valuation output'!D3 | C4: =B4/B3-1 | D4: ='Valuation output'!D4 | E4: =B4*D4 | F4: ='Valuation output'!D10 | G4: =E4-H4 | H4: ='Valuation output'!D7
A5: 3 | B5: ='Valuation output'!E3 | C5: =B5/B4-1 | D5: ='Valuation output'!E4 | E5: =B5*D5 | F5: ='Valuation output'!E10 | G5: =E5-H5 | H5: ='Valuation output'!E7
A6: 4 | B6: ='Valuation output'!F3 | C6: =B6/B5-1 | D6: ='Valuation output'!F4 | E6: =B6*D6 | F6: ='Valuation output'!F10 | G6: =E6-H6 | H6: ='Valuation output'!F7
A7: 5 | B7: ='Valuation output'!G3 | C7: =B7/B6-1 | D7: ='Valuation output'!G4 | E7: =B7*D7 | F7: ='Valuation output'!G10 | G7: =E7-H7 | H7: ='Valuation output'!G7
A8: 6 | B8: ='Valuation output'!H3 | C8: =B8/B7-1 | D8: ='Valuation output'!H4 | E8: =B8*D8 | F8: ='Valuation output'!H10 | G8: =E8-H8 | H8: ='Valuation output'!H7
A9: 7 | B9: ='Valuation output'!I3 | C9: =B9/B8-1 | D9: ='Valuation output'!I4 | E9: =B9*D9 | F9: ='Valuation output'!I10 | G9: =E9-H9 | H9: ='Valuation output'!I7
A10: 8 | B10: ='Valuation output'!J3 | C10: =B10/B9-1 | D10: ='Valuation output'!J4 | E10: =B10*D10 | F10: ='Valuation output'!J10 | G10: =E10-H10 | H10: ='Valuation output'!J7
A11: 9 | B11: ='Valuation output'!K3 | C11: =B11/B10-1 | D11: ='Valuation output'!K4 | E11: =B11*D11 | F11: ='Valuation output'!K10 | G11: =E11-H11 | H11: ='Valuation output'!K7
A12: 10 | B12: ='Valuation output'!L3 | C12: =B12/B11-1 | D12: ='Valuation output'!L4 | E12: =B12*D12 | F12: ='Valuation output'!L10 | G12: =E12-H12 | H12: ='Valuation output'!L7
A14: Year | B14: After-Tax Operating Income | C14: Change in Revenues | D14: Sales to Capital | E14: Reinvestment | F14: FCFF | G14: Capital Invested | H14: Implied ROC
A15: =A2 | B15: =H2 | G15: ='Valuation output'!B39 | H15: =B15/G15
A16: =A3 | B16: =H3 | C16: =B3-B2 | D16: ='Valuation output'!C38 | E16: =C16/D16 | F16: =B16-E16 | G16: =G15+E16 | H16: =B16/G16
A17: =A4 | B17: =H4 | C17: =B4-B3 | D17: ='Valuation output'!D38 | E17: =C17/D17 | F17: =B17-E17 | G17: =G16+E17 | H17: =B17/G17
A18: =A5 | B18: =H5 | C18: =B5-B4 | D18: ='Valuation output'!E38 | E18: =C18/D18 | F18: =B18-E18 | G18: =G17+E18 | H18: =B18/G18
A19: =A6 | B19: =H6 | C19: =B6-B5 | D19: ='Valuation output'!F38 | E19: =C19/D19 | F19: =B19-E19 | G19: =G18+E19 | H19: =B19/G19
A20: =A7 | B20: =H7 | C20: =B7-B6 | D20: ='Valuation output'!G38 | E20: =C20/D20 | F20: =B20-E20 | G20: =G19+E20 | H20: =B20/G20
A21: =A8 | B21: =H8 | C21: =B8-B7 | D21: ='Valuation output'!H38 | E21: =C21/D21 | F21: =B21-E21 | G21: =G20+E21 | H21: =B21/G21
A22: =A9 | B22: =H9 | C22: =B9-B8 | D22: ='Valuation output'!I38 | E22: =C22/D22 | F22: =B22-E22 | G22: =G21+E22 | H22: =B22/G22
A23: =A10 | B23: =H10 | C23: =B10-B9 | D23: ='Valuation output'!J38 | E23: =C23/D23 | F23: =B23-E23 | G23: =G22+E23 | H23: =B23/G23
A24: =A11 | B24: =H11 | C24: =B11-B10 | D24: ='Valuation output'!K38 | E24: =C24/D24 | F24: =B24-E24 | G24: =G23+E24 | H24: =B24/G24
A25: =A12 | B25: =H12 | C25: =B12-B11 | D25: ='Valuation output'!L38 | E25: =C25/D25 | F25: =B25-E25 | G25: =G24+E25 | H25: =B25/G25
A27: Year | B27: Beta | C27: Cost of Equity | D27: Pre-Tax Cost of Debt | E27: Tax Savings | F27: After-Tax Cost of Debt | G27: Debt Ratio | H27: Cost of Capital
A28: =A16 | H28: ='Valuation output'!C12
A29: =A17 | H29: ='Valuation output'!D12
A30: =A18 | H30: ='Valuation output'!E12
A31: =A19 | H31: ='Valuation output'!F12
A32: =A20 | H32: ='Valuation output'!G12
A33: =A21 | H33: ='Valuation output'!H12
A34: =A22 | H34: ='Valuation output'!I12
A35: =A23 | H35: ='Valuation output'!J12
A36: =A24 | H36: ='Valuation output'!K12
A37: =A25 | H37: ='Valuation output'!L12
A39: Year | B39: Cost of Capital | C39: Cumulated Cost of Capital | D39: FCFF | E39: Terminal Value | F39: Present Value
A40: =A28 | B40: =H28 | C40: =(1+'Summary Sheet'!B40) | D40: =F16 | F40: =D40/C40
A41: =A29 | B41: =H29 | C41: =C40*(1+B41) | D41: =F17 | F41: =D41/C41
A42: =A30 | B42: =H30 | C42: =C41*(1+B42) | D42: =F18 | F42: =D42/C42
A43: =A31 | B43: =H31 | C43: =C42*(1+B43) | D43: =F19 | F43: =D43/C43
...

Sheet Option value
A1: Valuing Options or Warrants
A2: Enter the current stock price = | D2: ='Input sheet'!B19
A3: Enter the strike price on the option = | D3: ='Input sheet'!B33
A4: Enter the expiration of the option = | D4: ='Input sheet'!B34
A5: Enter the standard deviation in stock prices = | D5: ='Input sheet'!B35 | E5: (volatility)
A6: Enter the annualized dividend yield on stock = | D6: 0
A7: Enter the treasury bond rate = | D7: ='Input sheet'!B28
A8: Enter the number of warrants (options) outstanding = | D8: ='Input sheet'!B32
A9: Enter the number of shares outstanding = | D9: ='Input sheet'!B18
A11: Do not input any numbers below this line
A12: VALUING WARRANTS WHEN THERE IS DILUTION
A13: Stock Price= | C13: =D2 | D13: # Warrants issued= | F13: =D8
A14: Strike Price= | C14: =D3 | D14: # Shares outstanding= | F14: =D9
A15: Adjusted S = | C15: =(C13*F14+C26*F13)/(F14+F13) | D15: T.Bond rate= | F15: =D7
A16: Adjusted K = | C16: =C14 | D16: Variance= | F16: =D5^2
A17: Expiration (in years) = | C17: =D4 | D17: Annualized dividend yield= | F17: =D6
D18: Div. Adj. interest rate= | F18: =F15-F17
A20: d1 = | B20: =(LN(C15/C16)+(F18+(F16/2))*C17)/(((F16)^(0.5))*(C17^0.5))
A21: N (d1) = | B21: =NORMSDIST(B20)
A23: d2 = | B23: =B20-((F16^0.5)*(C17^(0.5)))
A24: N (d2) = | B24: =NORMSDIST(B23)
A26: Value per option = | C26: =((EXP((0-F17)*C17))*C15*B21-C16*(EXP((0-F15)*C17))*B24)
A27: Value of all options outstanding = | D27: =C26*D8

Sheet Diagnostics
A1: VALUATION DIAGNOSTICS
A2: Invested capital at start of valuation | B2: ='Valuation output'!B39
A3: Invested capital at end of valuation | B3: ='Valuation output'!L39
A4: Change in invested capital over 10 years | B4: =B3-B2
A5: Change in EBIT*(1–t) (after-tax operating income) over 10 years | B5: ='Valuation output'!L5-'Valuation output'!B5
A6: Marginal ROIC over 10 years | B6: =B5/B4
A7: ROIC at end of valuation | B7: ='Valuation output'!L40
A8: Average WACC over the 10 years (compounded) | B8: =(1/'Valuation output'!L13)^(1/10)-1
A9: Your calculated value as a percent of current price | B9: ='Valuation output'!B33/'Valuation output'!B34
B10: =IF(B9="NA","Value is negative. See below",IF(B9>2,"Value seems high. See below",IF(B9<0.5,"Value seems low. See below"," ")))
A11: Inputs | B11: If calculated value is negative or looks too low | C11: If calculated value looks too high
A12: Revenue growth rate (input cell B3) | B12: Increase revenue growth rate | C12: Decrease revenue growth rate
A13: Last period EBIT as % of revenue (Input cell B14) | B13: Increase the target pre-tax operating margin | C13: Decrease the target pre-tax operating margin
A14: Sales to Capital Ratio or reinvestment (Input cell B15) | B14: Decrease the sales/capital ratio | C14: Increase the sales/capital ratio
A15: Return on capital in perpetuity (B30 & B31) | B15: Increase relative to your cost of capital | C15: If higher than your cost of capital, lower towards your cost of capital | D15: T

Sheet R& D converter
A1: R & D Converter
A2: This spreadsheet converts R&D expenses from operating to capital expenses. It makes the appropriate adjustments to operating income, net
A3: income, the book value of assets and the book value of equity.
A5: Inputs
A6: Over how many years do you want to amortize R&D expenses | F6: 2 | G6: ! If in doubt, use the lookup table below
A7: Enter the current year's R&D expense = | F7: 22620 | G7: The maximum allowed is ten years
A8: Enter R& D expenses for past years: the number of years that you will need to enter will be determined by the amortization period
A9: Do not input numbers in the first column (Year). It will get automatically updated based on the input above.
A10: Year | B10: R& D Expenses
A11: -1 | B11: 16085 | C11: ! Year -1 is the year prior to the current year
A12: =IF((0-A11)<$F$6,IF(A11>-1,,A11-1),) | B12: 12540 | C12: ! Year -2 is the two years prior to the current year
A13: =IF((0-A12)<$F$6,IF(A12>-1,,A12-1),)
A14: =IF((0-A13)<$F$6,IF(A13>-1,,A13-1),)
A15: =IF((0-A14)<$F$6,IF(A14>-1,,A14-1),)
A16: =IF((0-A15)<$F$6,IF(A15>-1,,A15-1),)
A17: =IF((0-A16)<$F$6,IF(A16>-1,,A16-1),)
A18: =IF((0-A17)<$F$6,IF(A17>-1,,A17-1),)
A19: =IF((0-A18)<$F$6,IF(A18>-1,,A18-1),)
A20: =IF((0-A19)<$F$6,IF(A19>-1,,A19-1),)
A22: Output
A23: Year | B23: R&D Expense | C23: Unamortized portion | E23: Amortization this year
A24: Current | B24: =F7 | C24: =1 | D24: =B24*C24
A25: =A11 | B25: =B11 | C25: =IF(A25<0,($F$6+A25)/$F$6,0) | D25: =B25*C25 | E25: =IF(A25<0,B25/$F$6,0)
A26: =A12 | B26: =B12 | C26: =IF(A26<0,($F$6+A26)/$F$6,0) | D26: =B26*C26 | E26: =IF(A26<0,B26/$F$6,0)
A27: =A13 | B27: =B13 | C27: =IF(A27<0,($F$6+A27)/$F$6,0) | D27: =B27*C27 | E27: =IF(A27<0,B27/$F$6,0)
A28: =A14 | B28: =B14 | C28: =IF(A28<0,($F$6+A28)/$F$6,0) | D28: =B28*C28 | E28: =IF(A28<0,B28/$F$6,0)
A29: =A15 | B29: =B15 | C29: =IF(A29<0,($F$6+A29)/$F$6,0) | D29: =B29*C29 | E29: =IF(A29<0,B29/$F$6,0)
A30: =A16 | B30: =B16 | C30: =IF(A30<0,($F$6+A30)/$F$6,0) | D30: =B30*C30 | E30: =IF(A30<0,B30/$F$6,0)
A31: =A17 | B31: =B17 | C31: =IF(A31<0,($F$6+A31)/$F$6,0) | D31: =B31*C31 | E31: =IF(A31<0,B31/$F$6,0)
A32: =A18 | B32: =B18 | C32: =IF(A32<0,($F$6+A32)/$F$6,0) | D32: =B32*C32 | E32: =IF(A32<0,B32/$F$6,0)
A33: =A19 | B33: =B19 | C33: =IF(A33<0,($F$6+A33)/$F$6,0) | D33: =B33*C33 | E33: =IF(A33<0,B33/$F$6,0)
A34: =A20 | B34: =B20 | C34: =IF(A34<0,($F$6+A34)/$F$6,0) | D34: =B34*C34 | E34: =IF(A34<0,B34/$F$6,0)
A35: Value of Research Asset = | D35: =SUM(D24:D34) | E35: =SUM(E25:E34)
A37: Amortization of asset for current year = | D37: =E35
A39: Adjustment to Operating Income = | D39: =F7-D37 | E39: ! A positive number indicates an increase in operating income (add to reported EBIT)
A40: Tax Effect of R&D Expensing | D40: =D39*'Input sheet'!B21

Sheet Operating lease converter
A1: Operating Lease Converter
A2: The yellow cells are input cells. Please enter them.
A3: Inputs
A4: Operating lease expense in current year = | E4: 2200
A5: Operating Lease Commitments (From footnote to financials)
A6: Year | B6: Commitment | C6: ! Year 1 is next year, ….
A7: 1 | B7: 2427
A8: 2 | B8: 2376
A9: 3 | B9: 2258
A10: 4 | B10: 2039
A11: 5 | B11: 1813
A12: 6 and beyond | B12: 11935
A14: Output
A15: Pre-tax Cost of Debt = | C15: 0.0413 | D15: ! If you do not have a cost of debt, use the synthetic rating estimator
A18: Number of years embedded in yr 6 estimate = | D18: =IF(B12>0,ROUND(B12/AVERAGE(B7:B11),0),0) | E18: ! I use the average lease expense over the first five years
E19: to estimate the number of years of expenses in yr 6
A20: Converting Operating Leases into debt
A21: Year | B21: Commitment | C21: Present Value
A22: =A7 | B22: =B7 | C22: =B22/(1+$C$15)^A22
A23: =A8 | B23: =B8 | C23: =B23/(1+$C$15)^A23
A24: =A9 | B24: =B9 | C24: =B24/(1+$C$15)^A24
A25: =A10 | B25: =B10 | C25: =B25/(1+$C$15)^A25
A26: =A11 | B26: =B11 | C26: =B26/(1+$C$15)^A26
A27: =A12 | B27: =IF(B12>0,IF(D18>0,B12/D18,B12),0) | C27: =IF(D18>0,(B27*(1-(1+C15)^(-D18))/C15)/(1+$C$15)^5,B27/(1+C15)^6) | D27: ! Commitment beyond year 6 converted into an annuity for ten years
A28: Debt Value of leases = | C28: =SUM(C22:C27)
A30: Restated Financials
A31: Depreciation on Operating Lease Asset = | F31: =C28/(5+D18) | G31: ! I use straight line depreciation
A32: Adjustment to Operating Earnings = | F32: =E4-F31 | G32: ! Add this amount to pre-tax operating income
A33: Adjustment to Total Debt outstanding = | F33: =C28 | G33: ! Add this amount to debt
A34: Adjustment to Depreciation = | F34: =C28/(5+D18)

Sheet Cost of capital worksheet
A1: Estimation of Current Cost of Capital | G1: Operating Countries ERP calculator
A2: Inputs | G2: Country | H2: Revenues | I2: ERP | J2: Weight | K2: Weighted ERP
A3: Equity | G3: United States of America | H3: 120486 | I3: =IF(H3=0,0,VLOOKUP(G3,'Country equity risk premiums'!$A$2:$D$187,4)) | J3: =IF(H3>0,H3/$H$16,) | K3: =IF(J3=0,0,I3*J3) | M3: The last two rows in each of country/region risk premium tables is set aside for your input to provide you with flexibility to enter some numbers directly. For instance, assume that you have a company that breaks its revenues down into three countries and then puts the rest into "Rest of the World". You can enter the "Rest of the World" in one of these two rows and enter an equity risk premium for the rest of the world. The easiest way to do that is to go into the country equity risk premium worksheet and change the GDP for the three countries that you have data for to zero and compute the global weighted average ERP for the remaining countries. With the regional worksheet, you can use the last two rows to enter the data for an individual country (usually the domestic country) that might be broken out though the rest of the revenues are broken down by region. You can look up the ERP for the country in the country ERP worksheet.
A4: Number of Shares outstanding = | B4: ='Input sheet'!B18 | G4: Germany | H4: 16951 | I4: =IF(H4=0,0,VLOOKUP(G4,'Country equity risk premiums'!$A$2:$D$187,4)) | J4: =IF(H4>0,H4/$H$16,) | K4: =IF(J4=0,0,I4*J4)
A5: Current Market Price per share = | B5: ='Input sheet'!B19 | G5: United Kingdom | H5: 11372 | I5: =IF(H5=0,0,VLOOKUP(G5,'Country equity risk premiums'!$A$2:$D$187,4)) | J5: =IF(H5>0,H5/$H$16,) | K5: =IF(J5=0,0,I5*J5)
G6: Japan | H6: 11907 | I6: =IF(H6=0,0,VLOOKUP(G6,'Country equity risk premiums'!$A$2:$D$187,4)) | J6: =IF(H6>0,H6/$H$16,) | K6: =IF(J6=0,0,I6*J6)
A7: Approach for estimating beta | B7: Multibusiness(Global) | I7: =IF(H7=0,0,VLOOKUP(G7,'Country equity risk premiums'!$A$2:$D$187,4)) | J7: =IF(H7>0,H7/$H$16,) | K7: =IF(J7=0,0,I7*J7)
A8: If direct input, enter levered beta (or regression beta) | B8: 1.2 | I8: =IF(H8=0,0,VLOOKUP(G8,'Country equity risk premiums'!$A$2:$D$187,4)) | J8: =IF(H8>0,H8/$H$16,) | K8: =IF(J8=0,0,I8*J8)
A9: Unlevered beta = | B9: =IF(B7="Single Business(US)",VLOOKUP('Input sheet'!B6,'Industry Averages(US)'!A2:G95,7),IF(B7="Multibusiness(US)",K46,IF(B7="Single Business(Global)",VLOOKUP('Input sheet'!B7,'Global industry averages'!A2:G95,7),'Cost of capital worksheet'!K62))) | I9: =IF(H9=0,0,VLOOKUP(G9,'Country equity risk premiums'!$A$2:$D$187,4)) | J9: =IF(H9>0,H9/$H$16,) | K9: =IF(J9=0,0,I9*J9)
A10: Riskfree Rate = | B10: ='Input sheet'!B28 | I10: =IF(H10=0,0,VLOOKUP(G10,'Country equity risk premiums'!$A$2:$D$187,4)) | J10: =IF(H10>0,H10/$H$16,) | K10: =IF(J10=0,0,I10*J10)
A11: What approach do you want to use to input ERP? | B11: Operating countries | I11: =IF(H11=0,0,VLOOKUP(G11,'Country equity risk premiums'!$A$2:$D$187,4)) | J11: =IF(H11>0,H11/$H$16,) | K11: =IF(J11=0,0,I11*J11)
A12: Direct input for ERP (if you choose "will input" | B12: 0.05 | I12: =IF(H12=0,0,VLOOKUP(G12,'Country equity risk premiums'!$A$2:$D$187,4)) | J12: =IF(H12>0,H12/$H$16,) | K12: =IF(J12=0,0,I12*J12)
A13: Equity Risk Premium used in cost of equity = | B13: =IF(B11="Will Input",B12,IF(B11="Country of Incorporation",VLOOKUP('Input sheet'!B5,'Country equity risk premiums'!A2:E187,4),IF(B11="Operating regions",'Cost of capital worksheet'!K30,'Cost of capital worksheet'!K16))) | I13: =IF(H13=0,0,VLOOKUP(G13,'Country equity risk premiums'!$A$2:$D$187,4)) | J13: =IF(H13>0,H13/$H$16,) | K13: =IF(J13=0,0,I13*J13)
J14: =IF(H14>0,H14/$H$16,) | K14: =IF(J14=0,0,I14*J14)
A15: Debt | G15: Rest of the World | H15: 17150 | I15: 0.0621 | J15: =IF(H15>0,H15/$H$16,) | K15: =IF(J15=0,0,I15*J15)
A16: Book Value of Straight Debt = | B16: ='Input sheet'!B12 | G16: Total | H16: =SUM(H3:H15) | J16: =SUM(J3:J15) | K16: =SUM(K3:K15)
A17: Interest Expense on Debt = | B17: ='Input sheet'!B10 | G17: Operating Regions ERP calculator
A18: Average Maturity = | B18: 3 | G18: Region | H18: Revenues | I18: ERP | J18: Weight | K18: Weighted ERP
A19: Approach for estimating pre-tax cost of debt | B19: Synthetic rating | G19: ='Country equity risk premiums'!A191 | H19: 0 | I19: ='Country equity risk premiums'!B191 | J19: =H19/$H$30 | K19: =I19*J19
A20: If direct input, input the pre-tax cost of debt | B20: 0.035 | G20: ='Country equity risk premiums'!A192 | H20: =3159+4281 | I20: ='Country equity risk premiums'!B192 | J20: =H20/$H$30 | K20: =I20*J20
A21: If actual rating, input the rating | B21: Aa2/AA | G21: ='Country equity risk premiums'!A193 | I21: ='Country equity risk premiums'!B193 | J21: =H21/$H$30 | K21: =I21*J21
A22: If synethetic rating, input the type of company | B22: 1 | G22: ='Country equity risk premiums'!A194 | H22: 0 | I22: ='Country equity risk premiums'!B194 | J22: =H22/$H$30 | K22: =I22*J22
A23: Pre-tax Cost of Debt = | B23: =IF(B19="Direct Input",B20,IF(B19="Synthetic Rating",'Synthetic rating'!D13,B10+VLOOKUP('Cost of capital worksheet'!B21,'Synthetic rating'!G39:H53,2))) | G23: ='Country equity risk premiums'!A195 | H23: 0 | I23: ='Country equity risk premiums'!B195 | J23: =H23/$H$30 | K23: =I23*J23
A24: Tax Rate = | B24: ='Input sheet'!B21 | G24: ='Country equity risk premiums'!A196 | I24: ='Country equity risk premiums'!B196 | J24: =H24/$H$30 | K24: =I24*J24
G25: ='Country equity risk premiums'!A197 | H25: 0 | I25: ='Country equity risk premiums'!B197 | J25: =H25/$H$30 | K25: =I25*J25
A26: Book Value of Convertible Debt = | B26: 0 | G26: ='Country equity risk premiums'!A198 | H26: 93864 | I26: ='Country equity risk premiums'!B198 | J26: =H26/$H$30 | K26: =I26*J26
A27: Interest Expense on Convertible = | B27: 0 | G27: ='Country equity risk premiums'!A199 | I27: ='Country equity risk premiums'!B199 | J27: =H27/$H$30 | K27: =I27*J27
A28: Maturity of Convertible Bond = | B28: 0 | J28: =H28/$H$30 | K28: =I28*J28
A29: Market Value of Convertible = | B29: 0 | J29: =H29/$H$30 | K29: =I29*J29
G30: Total | H30: =SUM(H19:H29) | J30: =SUM(J19:J29) | K30: =SUM(K19:K29)
A31: Debt value of operating leases = | B31: =IF('Input sheet'!B14="Yes",'Operating lease converter'!F33,0)
G32: Multi Business (US Industry Averages)
A33: Preferred Stock | G33: Business | H33: Revenues | I33: EV/Sales | J33: Estimated Value | K33: Unlevered Beta
A34: Number of Preferred Shares = | B34: 0 | G34: Advertising | H34: 70 | I34: =IF(G34=0,,VLOOKUP(G34,'Industry Averages(US)'!$A$2:$S$95,15)) | J34: =H34*I34 | K34: =IF(I34=0,0,VLOOKUP(G34,'Industry Averages(US)'!$A$2:$S$95,7))
A35: Current Market Price per Share= | B35: 70 | G35: Computer Services | H35: 30 | I35: =IF(G35=0,,VLOOKUP(G35,'Industry Averages(US)'!$A$2:$S$95,15)) | J35: =H35*I35 | K35: =IF(I35=0,0,VLOOKUP(G35,'Industry Averages(US)'!$A$2:$S$95,7))
A36: Annual Dividend per Share = | B36: 5 | I36: =IF(G36=0,,VLOOKUP(G36,'Industry Averages(US)'!$A$2:$S$95,15)) | J36: =H36*I36 | K36: =IF(I36=0,0,VLOOKUP(G36,'Industry Averages(US)'!$A$2:$S$95,7))
I37: =IF(G37=0,,VLOOKUP(G37,'Industry Averages(US)'!$A$2:$S$95,15)) | J37: =H37*I37 | K37: =IF(I37=0,0,VLOOKUP(G37,'Industry Averages(US)'!$A$2:$S$95,7))
A38: Output | I38: =IF(G38=0,,VLOOKUP(G38,'Industry Averages(US)'!$A$2:$S$95,15)) | J38: =H38*I38 | K38: =IF(I38=0,0,VLOOKUP(G38,'Industry Averages(US)'!$A$2:$S$95,7))
A39: Estimating Market Value of Straight Debt = | C39: =B17*(1-(1+B23)^(-B18))/B23+B16/(1+B23)^B18 | I39: =IF(G39=0,,VLOOKUP(G39,'Industry Averages(US)'!$A$2:$S$95,15)) | J39: =H39*I39 | K39: =IF(I39=0,0,VLOOKUP(G39,'Industry Averages(US)'!$A$2:$S$95,7))
A40: Estimated Value of Straight Debt in Convertible = | C40: =B27*(1-(1+B23)^(-B28))/B23+B26/(1+B23)^B28 | I40: =IF(G40=0,,VLOOKUP(G40,'Industry Averages(US)'!$A$2:$S$95,15)) | J40: =H40*I40 | K40: =IF(I40=0,0,VLOOKUP(G40,'Industry Averages(US)'!$A$2:$S$95,7))
...

Sheet Synthetic rating
A1: Inputs for synthetic rating estimation
A2: Please read the special cases worksheet (see below) before you use this spreadsheet.
A3: Before you use this spreadsheet, make sure that the iteration box (under calculation options in excel) is checked.
A4: Enter the type of firm = | C4: ='Cost of capital worksheet'!B22
A5: Enter current Earnings before interest and taxes (EBIT) = | F5: =IF('Input sheet'!B14="Yes",'Input sheet'!B9+'Operating lease converter'!F32,'Input sheet'!B9) | G5: (Add back only long term interest expense for financial firms)
A6: Enter current interest expenses = | F6: =IF('Input sheet'!B14="Yes",'Cost of capital worksheet'!B17+'Operating lease converter'!C28*'Operating lease converter'!C15,'Cost of capital worksheet'!B17) | G6: (Use only long term interest expense for financial firms)
A7: Enter long term risk free rate = | F7: ='Input sheet'!B28
A8: Output
A9: Interest coverage ratio = | D9: =IF(F6=0,1000000,IF(F5<0,-100000,F5/F6))
A10: Estimated Bond Rating = | D10: =IF(C4=1,VLOOKUP(D9,A19:D33,3),(IF(C4=2,VLOOKUP(D9,A38:D52,3),VLOOKUP(D9,F19:I33,3)))) | F10: Note: If you get REF! All over the place, set the operating lease commitment question in cell F5
A11: Estimated Company Default Spread = | D11: =IF(C4=1,VLOOKUP(D9,A19:D33,4),(IF(C4=2,VLOOKUP(D9,A38:D52,4),VLOOKUP(D9,F19:I33,4)))) | F11: to No, and then reset it to Yes. It should work.
A12: Estimated County Default Spread (if any) = | D12: =VLOOKUP('Input sheet'!B5,'Country equity risk premiums'!A2:C187,3)
A13: Estimated Cost of Debt = | D13: =F7+D11+D12
A15: If you want to update the spreads listed below, please visit http://www.bondsonline.com
A16: For large manufacturing firms
A17: If interest coverage ratio is
A18: > | B18: ≤ to | C18: Rating is | D18: Spread is
A19: -100000 | B19: 0.199999 | C19: D2/D | D19: 0.186
A20: 0.2 | B20: 0.649999 | C20: Caa/CCC | D20: 0.1395
A21: 0.65 | B21: 0.799999 | C21: Ca2/CC | D21: 0.1063
A22: 0.8 | B22: 1.249999 | C22: C2/C | D22: 0.0864
A23: 1.25 | B23: 1.499999 | C23: B3/B- | D23: 0.0437
A24: 1.5 | B24: 1.749999 | C24: B2/B | D24: 0.0357
A25: 1.75 | B25: 1.999999 | C25: B1/B+ | D25: 0.0298
A26: 2 | B26: 2.2499999 | C26: Ba2/BB | D26: 0.0238
A27: 2.25 | B27: 2.49999 | C27: Ba1/BB+ | D27: 0.0198
A28: 2.5 | B28: 2.999999 | C28: Baa2/BBB | D28: 0.0127
A29: 3 | B29: 4.249999 | C29: A3/A- | D29: 0.0113
A30: 4.25 | B30: 5.499999 | C30: A2/A | D30: 0.0099
... A33: 8.5 | B33: 100000 | C33: Aaa/AAA | D33: 0.0054
A35: For smaller and riskier firms
A36: If interest coverage ratio is
A37: greater than | B37: ≤ to | C37: Rating is | D37: Spread is
A38: -100000 | B38: 0.499999 | C38: D2/D | D38: 0.186 | G38: Rating is | H38: Spread is
A39: 0.5 | B39: 0.799999 | C39: Caa/CCC | D39: 0.1395 | G39: A1/A+ | H39: 0.01
A40: 0.8 | B40: 1.249999 | C40: Ca2/CC | D40: 0.1063 | G40: A2/A | H40: 0.011
A41: 1.25 | B41: 1.499999 | C41: C2/C | D41: 0.0864 | G41: A3/A- | H41: 0.0125
A42: 1.5 | B42: 1.999999 | C42: B3/B- | D42: 0.0437 | G42: Aa2/AA | H42: 0.008
A43: 2 | B43: 2.499999 | C43: B2/B | D43: 0.0357 | G43: Aaa/AAA | H43: 0.006
A44: 2.5 | B44: 2.999999 | C44: B1/B+ | D44: 0.0298 | G44: B1/B+ | H44: 0.0375
...

Sheet Industry Averages(US)
A1: Industry Name | B1: Number of firms | C1: Annual Average Revenue growth - Last 5 years | D1: Pre-tax Operating Margin (Lease & R&D adjusted) | E1: After-tax ROC | F1: Average effective tax rate | G1: Unlevered Beta | H1: Equity (Levered) Beta | I1: Cost of equity | J1: Std deviation in stock prices | K1: Pre-tax cost of debt | L1: Market Debt/Capital | M1: Cost of capital | N1: Sales/Capital | O1: EV/Sales | P1: EV/EBITDA | Q1: EV/EBIT | R1: Price/Book | S1: Trailing PE | T1: Non-cash WC as % of Revenues | U1: Cap Ex as % of Revenues | V1: Net Cap Ex as % of Revenues | W1: Reinvestment Rate | X1: ROE | Y1: Dividend Payout Ratio | Z1: Equity Reinvestment Rate
A2: Advertising | B2: 40 | C2: 0.11766353 | D2: 0.12408515 | E2: 0.77565051 | F2: 0.30392514 | G2: 0.78427897 | H2: 1.1535561 | I2: 0.082700651 | J2: 0.80950932 | K2: 0.0691 | L2: 0.42486145 | M2: 0.069876357 | N2: 6.6765069 | O2: 1.6638697 | P2: 8.3505373 | Q2: 13.149476 | R2: 9.1587623 | S2: 57.180661 | T2: -0.016538856 | U2: 0.023229015 | V2: -0.0026332734 | W2: 0.21519056 | X2: -0.0087986452 | Y2: 0.52845904 | Z2: 0.52845904
A3: Aerospace/Defense | B3: 87 | C3: 0.033537083 | D3: 0.11626118 | E3: 0.37051124 | F3: 0.29150382 | G3: 0.99233232 | H3: 1.082606 | I3: 0.079096385 | J3: 0.49061635 | K3: 0.0391 | L3: 0.15583595 | M3: 0.071401146 | N3: 3.6123522 | O3: 2.0885532 | P3: 13.962257 | Q3: 17.674829 | R3: 6.4263146 | S3: 29.341971 | T3: 0.27710404 | U3: 0.027124933 | V3: 0.020827228 | W3: 0.4016893 | X3: 0.29028585 | Y3: 0.39516823 | Z3: 0.39516823
A4: Air Transport | B4: 17 | C4: 0.0619875 | D4: 0.12840331 | E4: 0.13501065 | F4: 0.37149945 | G4: 0.67328042 | H4: 1.0088835 | I4: 0.075351282 | J4: 0.40200793 | K4: 0.0391 | L4: 0.41520146 | M4: 0.056403446 | N4: 1.3939105 | O4: 1.5580208 | P4: 6.5646386 | Q4: 12.135671 | R4: 3.0618413 | S4: 14.101198 | T4: 0.011868605 | U4: 0.12557975 | V4: 0.08566834 | W4: 1.0167244 | X4: 0.24781682 | Y4: 0.15274743 | Z4: 0.15274743
A5: Apparel | B5: 51 | C5: 0.20665733 | D5: 0.10975583 | E5: 0.14180982 | F5: 0.18584589 | G5: 0.85095727 | H5: 1.0167737 | I5: 0.075752103 | J5: 0.59710824 | K5: 0.0391 | L5: 0.25475946 | M5: 0.064023971 | N5: 1.4407435 | O5: 1.9882822 | P5: 10.973313 | Q5: 17.903533 | R5: 3.5814118 | S5: 34.875996 | T5: 0.2575637 | U5: 0.027043898 | V5: 0.059398572 | W5: 0.61793361 | X5: 0.076234161 | Y5: 0.77532499 | Z5: 0.77532499
A6: Auto & Truck | B6: 18 | C6: 0.22605429 | D6: 0.042080382 | E6: 0.039691311 | F6: 0.27715583 | G6: 0.592262 | H6: 1.1974171 | I6: 0.084928787 | J6: 0.38590283 | K6: 0.0361 | L6: 0.59691746 | M6: 0.050610338 | N6: 1.0215641 | O6: 1.2216369 | P6: 10.615768 | Q6: 30.818883 | R6: 2.0540407 | S6: 17.293466 | T6: -0.020621804 | U6: 0.1169276 | V6: 0.04639462 | W6: 1.4732719 | X6: 0.086358259 | Y6: 0.69488543 | Z6: 0.69488543
A7: Auto Parts | B7: 62 | C7: 0.076424828 | D7: 0.09548248 | E7: 0.23785516 | F7: 0.20110399 | G7: 0.92004456 | H7: 1.0375354 | I7: 0.0768068 | J7: 0.56736904 | K7: 0.0391 | L7: 0.2205866 | M7: 0.066419201 | N7: 2.6880898 | O7: 0.97880002 | P7: 7.5875088 | Q7: 10.690393 | R7: 2.9184201 | S7: 20.029194 | T7: 0.11202404 | U7: 0.045380817 | V7: 0.073866428 | W7: 1.03792 | X7: 0.24139027 | Y7: 0.13853703 | Z7: 0.13853703
A8: Bank (Money Center) | B8: 11 | C8: 0.052188889 | D8: -0.00068663456 | E8: -6.7827396e-05 | F8: 0.28353699 | G8: 0.32250416 | H8: 0.63754545 | I8: 0.056487309 | J8: 0.3337467 | K8: 0.0361 | L8: 0.61128398 | M8: 0.038728709 | N8: 0.13589982 | O8: 8.4502109 | P8: NA | Q8: NA | R8: 1.2438299 | S8: 15.755901 | T8: NA | U8: 0.009147247 | V8: 0.011484866 | W8: NA | X8: 0.099329692 | Y8: 0.24572802 | Z8: 0.24572802
A9: Banks (Regional) | B9: 612 | C9: 0.089641978 | D9: -0.0016135432 | E9: -0.00031426511 | F9: 0.2930678 | G9: 0.38572641 | H9: 0.50171127 | I9: 0.049586932 | J9: 0.32075657 | K9: 0.0361 | L9: 0.36978252 | M9: 0.041395905 | N9: 0.26166276 | O9: 6.2700837 | P9: NA | Q9: NA | R9: 1.5005733 | S9: 23.14689 | T9: NA | U9: 0.044406694 | V9: 0.04757999 | W9: NA | X9: 0.090282785 | Y9: 0.3091185 | Z9: 0.3091185
A10: Beverage (Alcoholic) | B10: 28 | C10: 0.11327273 | D10: 0.23414123 | E10: 0.24322235 | F10: 0.30015704 | G10: 1.1198147 | H10: 1.3261962 | I10: 0.091470766 | J10: 0.50136995 | K10: 0.0391 | L10: 0.20726073 | M10: 0.078671428 | N10: 1.1557147 | O10: 5.0480833 | P10: 17.261492 | Q10: 21.546072 | R10: 4.0050641 | S10: 49.288945 | T10: 0.16509674 | U10: 0.082720791 | V10: 0.67316789 | W10: 3.984283 | X10: 0.25156411 | Y10: 0.20374757 | Z10: 0.20374757
A11: Beverage (Soft) | B11: 35 | C11: 0.094812143 | D11: 0.19326807 | E11: 0.24915365 | F11: 0.26194011 | G11: 0.62680558 | H11: 0.70379615 | I11: 0.059852844 | J11: 0.45334168 | K11: 0.0391 | L11: 0.18739523 | M11: 0.054205343 | N11: 1.3774551 | O11: 4.2021129 | P11: 17.924877 | Q11: 21.727845 | R11: 9.9509384 | S11: 39.43773 | T11: -0.034454493 | U11: 0.046023651 | V11: 0.051108697 | W11: 0.41268111 | X11: 0.28388873 | Y11: 0.84899312 | Z11: 0.84899312
A12: Broadcasting | B12: 27 | C12: 0.081164286 | D12: 0.23454273 | E12: 0.21378655 | F12: 0.2858275 | G12: 0.65097821 | H12: 1.1196445 | I12: 0.08097794 | J12: 0.52300832 | K12: 0.0391 | L12: 0.52868829 | M12: 0.053876353 | N12: 1.1005046 | O12: 2.8336461 | P12: 9.1853991 | Q12: 12.081861 | R12: 7.3378902 | S12: 27.840394 | T12: 0.22956184 | U12: 0.026785462 | V12: 0.054938112 | W12: 0.43574185 | X12: 0.18105355 | Y12: 0.40584288 | Z12: 0.40584288
A13: Brokerage & Investment Banking | B13: 42 | C13: 0.078212609 | D13: 0.0010986436 | E13: 0.00018221573 | F13: 0.28540771 | G13: 0.54417467 | H13: 1.2379533 | I13: 0.086988028 | J13: 0.42480671 | K13: 0.0391 | L13: 0.68742549 | M13: 0.047617776 | N13: 0.19332465 | O13: 6.7457728 | P13: NA | Q13: NA | R13: 1.5583717 | S13: 47.562089 | T13: NA | U13: 0.04081499 | V13: 0.062576786 | W13: 453.97063 | X13: 0.11412665 | Y13: 0.20625382 | Z13: 0.20625382
A14: Building Materials | B14: 39 | C14: 0.12734107 | D14: 0.10326168 | E14: 0.18274341 | F14: 0.30032001 | G14: 0.98593417 | H14: 1.1089115 | I14: 0.080432706 | J14: 0.41014736 | K14: 0.0391 | L14: 0.17666856 | M14: 0.071472659 | N14: 2.3076896 | O14: 1.7781238 | P14: 12.797715 | Q14: 17.224678 | R14: 4.7670485 | S14: 26.552312 | T14: 0.15598884 | U14: 0.029032456 | V14: 0.030570522 | W14: 0.54485796 | X14: 0.23812242 | Y14: 0.15291339 | Z14: 0.15291339
A15: Business & Consumer Services | B15: 169 | C15: 0.051456849 | D15: 0.10525275 | E15: 0.26366136 | F15: 0.30962182 | G15: 1.0067304 | H15: 1.1687212 | I15: 0.083471035 | J15: 0.49449375 | K15: 0.0391 | L15: 0.21529718 | M15: 0.071897728 | N15: 2.8163257 | O15: 1.9431738 | P15: 12.400481 | Q15: 18.292236 | R15: 4.9491192 | S15: 51.595932 | T15: 0.16322114 | U15: 0.024867815 | V15: 0.034798925 | W15: 0.64086754 | X15: 0.1831593 | Y15: 0.2633303 | Z15: 0.2633303
A16: Cable TV | B16: 14 | C16: 0.11788125 | D16: 0.18246762 | E16: 0.12722064 | F16: 0.33563872 | G16: 0.66746834 | H16: 0.9209032 | I16: 0.070881883 | J16: 0.36325755 | K16: 0.0361 | L16: 0.34662154 | M16: 0.055822604 | N16: 0.89651645 | O16: 3.4373538 | P16: 9.6808597 | Q16: 18.262457 | R16: 2.8042665 | S16: 111.31451 | T16: -0.011222086 | U16: 0.12305375 | V16: -0.023988045 | W16: -0.21328263 | X16: 0.11054787 | Y16: 0.33212023 | Z16: 0.33212023
A17: Chemical (Basic) | B17: 38 | C17: 0.016253333 | D17: 0.10936001 | E17: 0.14431255 | F17: 0.23556839 | G17: 0.96489989 | H17: 1.1976211 | I17: 0.084939149 | J17: 0.59390184 | K17: 0.0391 | L17: 0.2921627 | M17: 0.068805005 | N17: 1.4619566 | O17: 1.7593938 | P17: 9.6669982 | Q17: 16.062965 | R17: 3.4676332 | S17: 38.304548 | T17: 0.20269614 | U17: 0.054937422 | V17: 0.031258405 | W17: 0.47816613 | X17: 0.18602096 | Y17: 0.27287812 | Z17: 0.27287812
A18: Chemical (Diversified) | B18: 7 | C18: -0.02543 | D18: 0.12242868 | E18: 0.165906 | F18: 0.22257157 | G18: 1.794686 | H18: 2.033952 | I18: 0.12742476 | J18: 0.68622838 | K18: 0.0466 | L18: 0.21374721 | M18: 0.10775815 | N18: 1.5304583 | O18: 2.899391 | P18: 15.832288 | Q18: 24.092802 | R18: 1.7377402 | S18: 30.215487 | T18: 0.34354391 | U18: 0.059958213 | V18: -0.012108457 | W18: -0.014461805 | X18: 0.14201117 | Y18: 0.58061389 | Z18: 0.58061389
A19: Chemical (Specialty) | B19: 99 | C19: 0.014687059 | D19: 0.13556745 | E19: 0.1674006 | F19: 0.2286681 | G19: 0.94849956 | H19: 1.1145863 | I19: 0.080720984 | J19: 0.59686773 | K19: 0.0391 | L19: 0.22482999 | M19: 0.069253534 | N19: 1.3659769 | O19: 2.7905594 | P19: 13.893471 | Q19: 20.59583 | R19: 4.1536923 | S19: 165.87771 | T19: 0.21485868 | U19: 0.050428111 | V19: 0.10439771 | W19: 1.058397 | X19: 0.16995624 | Y19: 0.39785274 | Z19: 0.39785274
A20: Coal & Related Energy | B20: 30 | C20: -0.040905714 | D20: 0.087114766 | E20: 0.085314376 | F20: 0.048345834 | G20: 1.0423911 | H20: 1.248786 | I20: 0.087538329 | J20: 0.90614735 | K20: 0.0816 | L20: 0.31231195 | M20: 0.079567401 | N20: 1.0312085 | O20: 1.0124232 | P20: 3.9282909 | Q20: 9.2366476 | R20: 2.0262335 | S20: 1276.0219 | T20: 0.04344611 | U20: 0.032597547 | V20: -0.064574555 | W20: -0.49883541 | X20: -6.4638687 | Y20: 0.15728551 | Z20: 0.15728551
A21: Computer Services | B21: 111 | C21: 0.15305093 | D21: 0.083480737 | E21: 0.27960738 | F21: 0.14346588 | G21: 0.94403177 | H21: 1.1013092 | I21: 0.08004651 | J21: 0.48530569 | K21: 0.0391 | L21: 0.23565212 | M21: 0.068186018 | N21: 3.6946039 | O21: 1.3377809 | P21: 11.099666 | Q21: 16.092621 | R21: 4.0372569 | S21: 40.329457 | T21: 0.12648663 | U21: 0.019687815 | V21: 0.01440334 | W21: 0.22996248 | X21: 0.28662241 | Y21: 0.38552173 | Z21: 0.38552173
A22: Computers/Peripherals | B22: 58 | C22: -0.026733333 | D22: 0.20009081 | E22: 0.23859785 | F22: 0.2400921 | G22: 0.92832563 | H22: 1.0096551 | I22: 0.075390478 | J22: 0.61378483 | K22: 0.0391 | L22: 0.15375451 | M22: 0.068367821 | N22: 1.2548328 | O22: 3.0332971 | P22: 12.011415 | Q22: 15.232652 | R22: 5.4205301 | S22: 108.61448 | T22: -0.026207138 | U22: 0.046883851 | V22: 0.019926098 | W22: 0.030424577 | X22: 0.28549481 | Y22: 0.28943953 | Z22: 0.28943953
A23: Construction Supplies | B23: 49 | C23: 0.069450294 | D23: 0.0961771 | E23: 0.10588151 | F23: 0.30820513 | G23: 0.95257769 | H23: 1.1206966 | I23: 0.081031386 | J23: 0.45667986 | K23: 0.0391 | L23: 0.24509215 | M23: 0.068454387 | N23: 1.3322953 | O23: 2.1425436 | P23: 14.508544 | Q23: 22.182858 | R23: 4.2103763 | S23: 41.997047 | T23: 0.15832179 | U23: 0.055692687 | V23: 0.035426738 | W23: 0.67824625 | X23: 0.13232904 | Y23: 0.57629202 | Z23: 0.57629202
A24: Diversified | B24: 24 | C24: 0.028673333 | D24: 0.13006937 | E24: 0.10977638 | F24: 0.24049249 | G24: 1.013544 | H24: 1.1944711 | I24: 0.08477913 | J24: 0.26823043 | K24: 0.0361 | L24: 0.24520856 | M24: 0.070718104 | N24: 0.95944435 | O24: 2.6230194 | P24: 14.685698 | Q24: 20.256102 | R24: 2.0356364 | S24: 25.95998 | T24: 0.14412883 | U24: 0.048417405 | V24: 0.038843876 | W24: 0.4167483 | X24: 0.095888757 | Y24: 0.35252719 | Z24: 0.35252719
A25: Drugs (Biotechnology) | B25: 459 | C25: 0.32284352 | D25: 0.26170414 | E25: 0.11597452 | F25: 0.20664395 | G25: 1.3565309 | H25: 1.4397417 | I25: 0.09723888 | J25: 0.94780627 | K25: 0.0816 | L25: 0.13668677 | M25: 0.092424378 | N25: 0.44897852 | O25: 7.6978721 | P25: 13.051547 | Q25: 24.218972 | R25: 6.2006091 | S25: 69.610535 | T25: 0.14849926 | U25: 0.039386459 | V25: 0.009900259 | W25: 0.098279408 | X25: 0.13445969 | Y25: 0.60255149 | Z25: 0.60255149
