Workbook

Sheet Readme
A1: Long Term Growth Model (LTGM) Spreadsheet
A2: V4.42
A3: 44546
A4: Spreadsheet developed by Steven Pennings, Leonardo Garrido and Jorge Luis Guzman
F5: (with guidance from Norman Loayza and input from Rishabh Sinha)
A6: DECMG, World Bank
A8: Comments and suggestions welcome, please email Steven Pennings (spennings@worldbank.org) or LTGM@worldbank.org
A9: The spreadsheet updated regularly, please check back LTGM website (below) for the last version:
A10: http://www.worldbank.org/LTGM
A11: Based on the model by Hevia and Loayza (2012) "Savings and Growth in Egypt" Middle East Development Journal 4 (1)
A12: Thanks to Vinaya Swaroop for project overview and Diego Barrot for assistance with data
A14: See the pdf "Long Term Growth Model V4_3" for a list of model equations, and an explanation of the drivers of growth in the LTGM.
A15: System Requirements: | C15: if using Excel 2010 or later all features work as planned*
C16: if using earlier versions of Excel, dropdown menus are not supported; but there is an easy fix - see instruction (7) below
C17: There are no macros in this spreadsheet
A18: New in v4 - poverty extension. Now users can see the implications of growth fundamentals for poverty rates. See Model description Section 5 for a description
A20: 1) General Instructions
A21: Worksheet "InputDataA_GeneralAssumptions" controls most simulation parameters and assumptions that affect all three models
A22: Choose your country from the drop down menu at the top left of "InputDataA_GeneralAssumptions" (select the cell first).
A23: Data from that country will automatically be populated, but you can specify most of the parameters yourself if you choose (see Worksheet "GraphsA" figures of general assumptions).
A24: Worksheet "InputDataB_ModelSpecAssumptions" controls model-specific parameters
A25: If you want to calculate growth for a given investment-to-GDP profile, use Model 1
A26: If you want to calculate required investment to achieve a target growth path, use Model 2
A27: If you want to calculate growth for a given savings-to-GDP profile, use Model 3
A28: (This this last case also requires some assumption on external balance, described below)
A29: See Worksheet "GrapshB" for graphs of model-specific inputs and outputs
A30: Color coding: | B30: Yellow= can edit | D30: Grey=not active (don’t edit) | G30: Red = formulas/populated data (don't edit)
A32: 2) Entering General Parameter Assumptions (use InputDataA_GeneralAssumptions)
A33: In most cases you can choose "automatic" or "manual" version of each series from a drop-down menu
A34: - if automatic, select a target value and the year it is achieved and the spreadsheet automatically generates a smooth path to get there
A35: - if manual, you must type the values manually into the ""Manual" [user defined year by year]" yellow cells to the right in InputDataA and InputDataB (they become yellow when you select manual from the drop down menu)
A36: Model 1, 2 and 3 uses the same general parameters as each other; Model 1s, 2s and 3s uses the same general parameters as each other("s" is for scenarios - see below)
A37: The parameters which actually go into the calculations are listed in "Summary of Inputs based on User's choice" in the Model 1(s), Model 2(s) and Model 3(s) spreadsheets
A39: 3) Entering Model 1-, Model 2- or Model 3-specific parameters - Use InputDataB sheet
A40: For Model 1, choose either "automated" or "manual" values for a path of I/Y (as above), these will not affect Model 2 or 3
A41: For Model 2, choose between the types of growth target: a GDP per capita growth target, a headline GDP growth target, a GDP per capita levels target (does not affect Model 1 or 3)
A42: - Then choose between "automated" or "manual" values for a path of the growth target. If automatic, you also need to choose an end date as above and the model generates a smooth path
A43: - If choose "manual" then you need to enter the values corresponding to the type of growth target in InputDataB on the RHS row 13 and 19. Eg 5000 (for a GDP per capita levels target) or 0.06 (for a growth target)
A44: - The model automatically interprets the "type" of these numbers, and converts them to an implied GDP per capita growth target the Model 2 and Model 2s sheets
... A69: Scenarios allows you to easily compare two outputs given different assumptions in the "GraphsA" and "GraphsB" worksheet
...

Sheet InputDataA_GeneralAssumptions
B1: General Assumptions and Parameters for all Sub-models | G1: Key | AN1: ="35 hidden columns for years "&AN19+1&" to "&AN19+35&" -->"
B2: Country (World Bank Name): | G2: Fields in yellow are for the user to edit | H2: Field in grey are inactive (do not edit)
B3: Zambia | C3: <-- Select from list | G3: Initial data/generated output, user is NOT able to edit | H3: Interpolated data
G4: Note: If choosing "manual" from the drop down menu for universal parameters (grey), please enter values for that series by hand in the yellow field "User defined, year by year" on right
B6: Initial and Final years | C6: units
B7: Initial year for estimation--> | C7: (YYYY) | D7: 2019
B8: Final year for estimation --> | C8: (YYYY) | D8: 2050
B10: Parameters | C10: =""&DataSummary!D142&" for "&B3&"" | D10: =DataSummary!N4 | E10: =DataSummary!N5 | H10: =""&DataSummary!D191&"" | I10: =DataSummary!N4 | J10: =DataSummary!N5
B11: Depreciation rate, user defined --> | C11: (e.g. 0.07) | D11: 0.049 | E11: 0.049 | G11: Initial K/Y ratio (user defined) --> | H11: (e.g. 0.40) | I11: 2.42 | J11: 2.42
B12: Depreciation rate, pre-loaded based on | C12: PWT 8.1 | D12: =IF(ISNUMBER(DataSummary!B142)=TRUE(),DataSummary!B142,".") | G12: Initial K/Y ratio, (pre-loaded) --> | H12: MFMOD | I12: =IF(ISNUMBER(DataSummary!B191)=TRUE(),DataSummary!B191,".")
B13: Depreciation rate is / are (if cells D11:E11 are blank, uses D12): --> | C13: (e.g. 0.07) | D13: =IF(ISBLANK(D11)=TRUE(),D12,D11) | E13: =IF(ISBLANK(E11)=TRUE(),D12,E11) | G13: Initial is (if cell I11:J11 is blank uses pre-loaded) --> | H13: (e.g. 0.40) | I13: =IF(ISBLANK(I11)=TRUE(),I12,I11) | J13: =IF(ISBLANK(J11)=TRUE(),I12,J11)
B14: Labor Shares, user defined --> | C14: =""&DataSummary!D161&" for "&B3&"" | D14: 0.618 | E14: 0.618 | G14: Initial GDP per capita (user defined) --> | H14: (Unit defined by user)
B15: ="Labor Shares, pre-loaded (Based on "&DataSummary!D161&")" | C15: Default (PWT 8.1 / GTAP / Interpolated) | D15: =IF(ISNUMBER(DataSummary!B161)=TRUE(),DataSummary!B161,".") | G15: ="Initial GDP per capita, "&DataSummary!D286&", pre-loaded -->" | H15: WDI 2019 | I15: =IF(ISNUMBER(DataSummary!B286)=TRUE(),DataSummary!B286,".")
B16: Labor Share is / are (if cells D14:E14 are blank, uses D15): --> | C16: (e.g. 0.40) | D16: =IF(ISBLANK(D14)=TRUE(),D15,D14) | E16: =IF(ISBLANK(E14)=TRUE(),D15,E14) | G16: Initial is: (if cell I14:J14 is blank uses pre-loaded) --> | H16: =IF(ISBLANK(I14)=TRUE(),H15,H14) | I16: =IF(ISBLANK(I14)=TRUE(),I15,I14) | J16: =IF(ISBLANK(J14)=TRUE(),I15,J14)
B18: Assumptions
B19: Human Capital (HK) (applies to all models) | C19: =""&DataSummary!D182&"" | D19: =DataSummary!N4 | E19: =DataSummary!N5 | F19: =D24 | G19: Human Capital Index Annual Growth Rate | H19: Chart | I19: =InputDataA_GeneralAssumptions!$D$7 | J19: =I19+1 | K19: =J19+1 | L19: =K19+1 | M19: =L19+1 | N19: =M19+1 | O19: =N19+1 | P19: =O19+1 | Q19: =P19+1 | ... BW19: =BV19+1
B20: Initial Human Capital Index annual growth rate (user defined) --> | C20: (e.g. 0.01) | D20: 0.006 | E20: 0.006 | F20: =DataSummary!N4 | G20: "Manual" [user defined year by year] | H20: (e.g. 0.02) | I20: =I21 | J20: 0.01 | K20: 0.01 | L20: 0.01 | M20: 0.01 | N20: 0.01 | O20: 0.01 | P20: 0.01 | Q20: 0.01 | R20: 0.01 | S20: 0.01 | T20: 0.01 | U20: 0.01 | V20: 0.01 | W20: 0.01 | X20: 0.01 | Y20: 0.01 | Z20: 0.01 | AA20: 0.01 | AB20: 0.01 | AC20: 0.01 | AD20: 0.01 | AE20: 0.01 | AF20: 0.01 | AG20: 0.01 | AH20: 0.01 | AI20: 0.01 | AJ20: 0.01 | AK20: 0.01 | AL20: 0.01 | AM20: 0.01 | AN20: 0.01 | AO20: 0.01 | AP20: 0.01 | AQ20: 0.01 | AR20: 0.01 | AS20: 0.01 | AT20: =AS20 | AU20: =AT20 | AV20: =AU20 | AW20: =AV20 | AX20: =AW20 | AY20: =AX20 | AZ20: =AY20 | BA20: =AZ20 | ... BW20: =BV20
B21: Initial Human Capital Index, pre-loaded based on | C21: PWT 9.1 15yr avg | D21: =IF(ISNUMBER(DataSummary!B182)=TRUE(),DataSummary!B182,".") | G21: "Automatic" [reach target by year] | H21: =H20 | I21: =InputDataA_GeneralAssumptions!D22 | J21: =IF(J19>InputDataA_GeneralAssumptions!$D$26,InputDataA_GeneralAssumptions!$D$25,I21+(InputDataA_GeneralAssumptions!$D$25-$I$21)/(InputDataA_GeneralAssumptions!$D$26-InputDataA_GeneralAssumptions!$D$7)) | K21: =IF(K19>InputDataA_GeneralAssumptions!$D$26,InputDataA_GeneralAssumptions!$D$25,J21+(InputDataA_GeneralAssumptions!$D$25-$I$21)/(InputDataA_GeneralAssumptions!$D$26-InputDataA_GeneralAssumptions!$D$7)) | L21: =IF(L19>InputDataA_GeneralAssumptions!$D$26,InputDataA_GeneralAssumptions!$D$25,K21+(InputDataA_GeneralAssumptions!$D$25-$I$21)/(InputDataA_GeneralAssumptions!$D$26-InputDataA_GeneralAssumptions!$D$7)) | M21: =IF(M19>InputDataA_GeneralAssumptions!$D$26,InputDataA_GeneralAssumptions!$D$25,L21+(InputDataA_GeneralAssumptions!$D$25-$I$21)/(InputDataA_GeneralAssumptions!$D$26-InputDataA_GeneralAssumptions!$D$7)) | N21: =IF(N19>InputDataA_GeneralAssumptions!$D$26,InputDataA_GeneralAssumptions!$D$25,M21+(InputDataA_GeneralAssumptions!$D$25-$I$21)/(InputDataA_GeneralAssumptions!$D$26-InputDataA_GeneralAssumptions!$D$7)) | O21: =IF(O19>InputDataA_GeneralAssumptions!$D$26,InputDataA_GeneralAssumptions!$D$25,N21+(InputDataA_GeneralAssumptions!$D$25-$I$21)/(InputDataA_GeneralAssumptions!$D$26-InputDataA_GeneralAssumptions!$D$7)) | P21: =IF(P19>InputDataA_GeneralAssumptions!$D$26,InputDataA_GeneralAssumptions!$D$25,O21+(InputDataA_GeneralAssumptions!$D$25-$I$21)/(InputDataA_GeneralAssumptions!$D$26-InputDataA_GeneralAssumptions!$D$7)) | Q21: =IF(Q19>InputDataA_GeneralAssumptions!$D$26,InputDataA_GeneralAssumptions!$D$25,P21+(InputDataA_GeneralAssumptions!$D$25-$I$21)/(InputDataA_GeneralAssumptions!$D$26-InputDataA_GeneralAssumptions!$D$7)) | ... BW21: =IF(BW19>InputDataA_GeneralAssumptions!$D$26,InputDataA_GeneralAssumptions!$D$25,BV21+(InputDataA_GeneralAssumptions!$D$25-$I$21)/(InputDataA_GeneralAssumptions!$D$26-InputDataA_GeneralAssumptions!$D$7))
B22: Initial is: (if cell D20:E20 -yellow- is blank uses pre-loaded) --> | C22: (e.g. 0.01) | D22: =IF(ISBLANK(D20)=TRUE(),D21,D20) | E22: =IF(ISBLANK(E20)=TRUE(),D21,E20) | G22: Used in "baseline" simulation | H22: =H21 | I22: =IF(VLOOKUP(InputDataA_GeneralAssumptions!$D$24,DataSummary!$A$110:$B$112,2,FALSE())=1,InputDataA_GeneralAssumptions!I20,InputDataA_GeneralAssumptions!I21) | J22: =IF(VLOOKUP(InputDataA_GeneralAssumptions!$D$24,DataSummary!$A$110:$B$112,2,FALSE())=1,InputDataA_GeneralAssumptions!J20,InputDataA_GeneralAssumptions!J21) | K22: =IF(VLOOKUP(InputDataA_GeneralAssumptions!$D$24,DataSummary!$A$110:$B$112,2,FALSE())=1,InputDataA_GeneralAssumptions!K20,InputDataA_GeneralAssumptions!K21) | L22: =IF(VLOOKUP(InputDataA_GeneralAssumptions!$D$24,DataSummary!$A$110:$B$112,2,FALSE())=1,InputDataA_GeneralAssumptions!L20,InputDataA_GeneralAssumptions!L21) | M22: =IF(VLOOKUP(InputDataA_GeneralAssumptions!$D$24,DataSummary!$A$110:$B$112,2,FALSE())=1,InputDataA_GeneralAssumptions!M20,InputDataA_GeneralAssumptions!M21) | N22: =IF(VLOOKUP(InputDataA_GeneralAssumptions!$D$24,DataSummary!$A$110:$B$112,2,FALSE())=1,InputDataA_GeneralAssumptions!N20,InputDataA_GeneralAssumptions!N21) | O22: =IF(VLOOKUP(InputDataA_GeneralAssumptions!$D$24,DataSummary!$A$110:$B$112,2,FALSE())=1,InputDataA_GeneralAssumptions!O20,InputDataA_GeneralAssumptions!O21) | P22: =IF(VLOOKUP(InputDataA_GeneralAssumptions!$D$24,DataSummary!$A$110:$B$112,2,FALSE())=1,InputDataA_GeneralAssumptions!P20,InputDataA_GeneralAssumptions!P21) | ... BW22: =IF(VLOOKUP(InputDataA_GeneralAssumptions!$D$24,DataSummary!$A$110:$B$112,2,FALSE())=1,InputDataA_GeneralAssumptions!BW20,InputDataA_GeneralAssumptions!BW21)
B24: Choice for future growth rate of HK: | C24: Select from list --> | D24: Automatic | F24: =DataSummary!N5 | G24: "Manual" [user defined year by year] | H24: (e.g. 0.02) | I24: =I25 | J24: 0.01 | K24: 0.01 | L24: 0.01 | M24: 0.01 | N24: 0.01 | O24: 0.01 | P24: 0.01 | Q24: 0.01 | R24: 0.01 | S24: 0.01 | T24: 0.01 | U24: 0.01 | V24: 0.01 | W24: 0.01 | X24: 0.01 | Y24: 0.01 | Z24: 0.01 | AA24: 0.01 | AB24: 0.01 | AC24: 0.01 | AD24: 0.01 | AE24: 0.01 | AF24: 0.01 | AG24: 0.01 | AH24: 0.01 | AI24: 0.01 | AJ24: 0.01 | AK24: 0.01 | AL24: 0.01 | AM24: 0.01 | AN24: 0.01 | AO24: 0.01 | AP24: 0.01 | AQ24: 0.01 | AR24: 0.01 | AS24: 0.01 | AT24: 0.01 | AU24: 0.01 | AV24: 0.01 | AW24: 0.01 | AX24: 0.01 | AY24: 0.01 | AZ24: 0.01 | BA24: 0.01 | BB24: 0.01 | BC24: 0.01 | BD24: 0.01 | BE24: 0.01 | BF24: 0.01 | BG24: 0.01 | BH24: 0.01 | BI24: 0.01 | BJ24: 0.01 | BK24: 0.01 | BL24: 0.01 | BM24: 0.01 | BN24: 0.01 | BO24: 0.01 | BP24: 0.01 | BQ24: 0.01 | BR24: 0.01 | BS24: 0.01 | BT24: 0.01 | BU24: 0.01 | BV24: 0.01 | BW24: 0.01
B25: Target Human Capital Index annual growth rate --> | C25: (e.g. 0.01) | D25: =D22 | E25: =E22 | G25: "Automatic" [reach target by year] | H25: =H24 | I25: =InputDataA_GeneralAssumptions!E22 | J25: =IF(J19>InputDataA_GeneralAssumptions!$E$26,InputDataA_GeneralAssumptions!$E$25,I25+(InputDataA_GeneralAssumptions!$E$25-$I$25)/(InputDataA_GeneralAssumptions!$E$26-InputDataA_GeneralAssumptions!$D$7)) | K25: =IF(K19>InputDataA_GeneralAssumptions!$E$26,InputDataA_GeneralAssumptions!$E$25,J25+(InputDataA_GeneralAssumptions!$E$25-$I$25)/(InputDataA_GeneralAssumptions!$E$26-InputDataA_GeneralAssumptions!$D$7)) | L25: =IF(L19>InputDataA_GeneralAssumptions!$E$26,InputDataA_GeneralAssumptions!$E$25,K25+(InputDataA_GeneralAssumptions!$E$25-$I$25)/(InputDataA_GeneralAssumptions!$E$26-InputDataA_GeneralAssumptions!$D$7)) | M25: =IF(M19>InputDataA_GeneralAssumptions!$E$26,InputDataA_GeneralAssumptions!$E$25,L25+(InputDataA_GeneralAssumptions!$E$25-$I$25)/(InputDataA_GeneralAssumptions!$E$26-InputDataA_GeneralAssumptions!$D$7)) | N25: =IF(N19>InputDataA_GeneralAssumptions!$E$26,InputDataA_GeneralAssumptions!$E$25,M25+(InputDataA_GeneralAssumptions!$E$25-$I$25)/(InputDataA_GeneralAssumptions!$E$26-InputDataA_GeneralAssumptions!$D$7)) | O25: =IF(O19>InputDataA_GeneralAssumptions!$E$26,InputDataA_GeneralAssumptions!$E$25,N25+(InputDataA_GeneralAssumptions!$E$25-$I$25)/(InputDataA_GeneralAssumptions!$E$26-InputDataA_GeneralAssumptions!$D$7)) | P25: =IF(P19>InputDataA_GeneralAssumptions!$E$26,InputDataA_GeneralAssumptions!$E$25,O25+(InputDataA_GeneralAssumptions!$E$25-$I$25)/(InputDataA_GeneralAssumptions!$E$26-InputDataA_GeneralAssumptions!$D$7)) | Q25: =IF(Q19>InputDataA_GeneralAssumptions!$E$26,InputDataA_GeneralAssumptions!$E$25,P25+(InputDataA_GeneralAssumptions!$E$25-$I$25)/(InputDataA_GeneralAssumptions!$E$26-InputDataA_GeneralAssumptions!$D$7)) | ... BW25: =IF(BW19>InputDataA_GeneralAssumptions!$E$26,InputDataA_GeneralAssumptions!$E$25,BV25+(InputDataA_GeneralAssumptions!$E$25-$I$25)/(InputDataA_GeneralAssumptions!$E$26-InputDataA_GeneralAssumptions!$D$7))
B26: Reach Target HK annual growth rate by year --> | C26: (YYYY) | D26: 2030 | E26: =D26 | G26: Used in "scenario" simulation | H26: =H25 | I26: =IF(VLOOKUP(InputDataA_GeneralAssumptions!$D$24,DataSummary!$A$110:$B$112,2,FALSE())=1,InputDataA_GeneralAssumptions!I24,InputDataA_GeneralAssumptions!I25) | J26: =IF(VLOOKUP(InputDataA_GeneralAssumptions!$D$24,DataSummary!$A$110:$B$112,2,FALSE())=1,InputDataA_GeneralAssumptions!J24,InputDataA_GeneralAssumptions!J25) | K26: =IF(VLOOKUP(InputDataA_GeneralAssumptions!$D$24,DataSummary!$A$110:$B$112,2,FALSE())=1,InputDataA_GeneralAssumptions!K24,InputDataA_GeneralAssumptions!K25) | L26: =IF(VLOOKUP(InputDataA_GeneralAssumptions!$D$24,DataSummary!$A$110:$B$112,2,FALSE())=1,InputDataA_GeneralAssumptions!L24,InputDataA_GeneralAssumptions!L25) | M26: =IF(VLOOKUP(InputDataA_GeneralAssumptions!$D$24,DataSummary!$A$110:$B$112,2,FALSE())=1,InputDataA_GeneralAssumptions!M24,InputDataA_GeneralAssumptions!M25) | N26: =IF(VLOOKUP(InputDataA_GeneralAssumptions!$D$24,DataSummary!$A$110:$B$112,2,FALSE())=1,InputDataA_GeneralAssumptions!N24,InputDataA_GeneralAssumptions!N25) | O26: =IF(VLOOKUP(InputDataA_GeneralAssumptions!$D$24,DataSummary!$A$110:$B$112,2,FALSE())=1,InputDataA_GeneralAssumptions!O24,InputDataA_GeneralAssumptions!O25) | P26: =IF(VLOOKUP(InputDataA_GeneralAssumptions!$D$24,DataSummary!$A$110:$B$112,2,FALSE())=1,InputDataA_GeneralAssumptions!P24,InputDataA_GeneralAssumptions!P25) | ... BW26: =IF(VLOOKUP(InputDataA_GeneralAssumptions!$D$24,DataSummary!$A$110:$B$112,2,FALSE())=1,InputDataA_GeneralAssumptions!BW24,InputDataA_GeneralAssumptions!BW25)
B28: Total Factor Productivity (TFP) (applies to all models) | C28: =""&DataSummary!D211&"" | D28: =DataSummary!N4 | E28: =DataSummary!N5 | F28: =D33 | G28: Total Factor Productivity Annual Growth Rate | H28: Chart | I28: =InputDataA_GeneralAssumptions!$D$7 | J28: =I28+1 | K28: =J28+1 | L28: =K28+1 | M28: =L28+1 | N28: =M28+1 | O28: =N28+1 | P28: =O28+1 | Q28: =P28+1 | ... BW28: =BV28+1
B29: Initial TFP annual growth rate (user defined) --> | C29: (e.g. 0.01) | D29: 0.01 | E29: 0.01 | F29: =DataSummary!N4 | G29: "Manual" [user defined year by year] | H29: (e.g. 0.02) | I29: =I30 | J29: 0.01 | K29: 0.01 | L29: 0.01 | M29: 0.01 | N29: 0.01 | O29: 0.01 | P29: 0.01 | Q29: 0.01 | R29: 0.01 | S29: 0.01 | T29: 0.01 | U29: 0.01 | V29: 0.01 | W29: 0.01 | X29: 0.01 | Y29: 0.01 | Z29: 0.01 | AA29: 0.01 | AB29: 0.01 | AC29: 0.01 | AD29: 0.01 | AE29: 0.01 | AF29: 0.01 | AG29: 0.01 | AH29: 0.01 | AI29: 0.01 | AJ29: 0.01 | AK29: 0.01 | AL29: 0.01 | AM29: 0.01 | AN29: 0.01 | AO29: 0.01 | AP29: 0.01 | AQ29: 0.01 | AR29: 0.01 | AS29: 0.01 | AT29: =AS29 | AU29: =AT29 | AV29: =AU29 | AW29: =AV29 | AX29: =AW29 | AY29: =AX29 | AZ29: =AY29 | BA29: =AZ29 | ... BW29: =BV29
B30: ="Initial TFP based on " | C30: PWT 9.1 15yr avg | D30: =IF(ISNUMBER(DataSummary!B211)=TRUE(),DataSummary!B211,".") | G30: "Automatic" [reach target by year] | H30: =H29 | I30: =InputDataA_GeneralAssumptions!D31 | J30: =IF(J28>InputDataA_GeneralAssumptions!$D$35,InputDataA_GeneralAssumptions!$D$34,I30+(InputDataA_GeneralAssumptions!$D$34-$I$30)/(InputDataA_GeneralAssumptions!$D$35-InputDataA_GeneralAssumptions!$D$7)) | K30: =IF(K28>InputDataA_GeneralAssumptions!$D$35,InputDataA_GeneralAssumptions!$D$34,J30+(InputDataA_GeneralAssumptions!$D$34-$I$30)/(InputDataA_GeneralAssumptions!$D$35-InputDataA_GeneralAssumptions!$D$7)) | L30: =IF(L28>InputDataA_GeneralAssumptions!$D$35,InputDataA_GeneralAssumptions!$D$34,K30+(InputDataA_GeneralAssumptions!$D$34-$I$30)/(InputDataA_GeneralAssumptions!$D$35-InputDataA_GeneralAssumptions!$D$7)) | M30: =IF(M28>InputDataA_GeneralAssumptions!$D$35,InputDataA_GeneralAssumptions!$D$34,L30+(InputDataA_GeneralAssumptions!$D$34-$I$30)/(InputDataA_GeneralAssumptions!$D$35-InputDataA_GeneralAssumptions!$D$7)) | N30: =IF(N28>InputDataA_GeneralAssumptions!$D$35,InputDataA_GeneralAssumptions!$D$34,M30+(InputDataA_GeneralAssumptions!$D$34-$I$30)/(InputDataA_GeneralAssumptions!$D$35-InputDataA_GeneralAssumptions!$D$7)) | O30: =IF(O28>InputDataA_GeneralAssumptions!$D$35,InputDataA_GeneralAssumptions!$D$34,N30+(InputDataA_GeneralAssumptions!$D$34-$I$30)/(InputDataA_GeneralAssumptions!$D$35-InputDataA_GeneralAssumptions!$D$7)) | P30: =IF(P28>InputDataA_GeneralAssumptions!$D$35,InputDataA_GeneralAssumptions!$D$34,O30+(InputDataA_GeneralAssumptions!$D$34-$I$30)/(InputDataA_GeneralAssumptions!$D$35-InputDataA_GeneralAssumptions!$D$7)) | Q30: =IF(Q28>InputDataA_GeneralAssumptions!$D$35,InputDataA_GeneralAssumptions!$D$34,P30+(InputDataA_GeneralAssumptions!$D$34-$I$30)/(InputDataA_GeneralAssumptions!$D$35-InputDataA_GeneralAssumptions!$D$7)) | ... BW30: =IF(BW28>InputDataA_GeneralAssumptions!$D$35,InputDataA_GeneralAssumptions!$D$34,BV30+(InputDataA_GeneralAssumptions!$D$34-$I$30)/(InputDataA_GeneralAssumptions!$D$35-InputDataA_GeneralAssumptions!$D$7))
B31: Initial is: (if cell D29:E29 -yellow- is blank uses pre-loaded) --> | C31: (e.g. 0.01) | D31: =IF(ISBLANK(D29)=TRUE(),D30,D29) | E31: =IF(ISBLANK(E29)=TRUE(),D30,E29) | G31: Used in "baseline" simulation | H31: =H30 | I31: =IF(VLOOKUP(InputDataA_GeneralAssumptions!$D$33,DataSummary!$A$110:$B$112,2,FALSE())=1,InputDataA_GeneralAssumptions!I29,InputDataA_GeneralAssumptions!I30) | J31: =IF(VLOOKUP(InputDataA_GeneralAssumptions!$D$33,DataSummary!$A$110:$B$112,2,FALSE())=1,InputDataA_GeneralAssumptions!J29,InputDataA_GeneralAssumptions!J30) | K31: =IF(VLOOKUP(InputDataA_GeneralAssumptions!$D$33,DataSummary!$A$110:$B$112,2,FALSE())=1,InputDataA_GeneralAssumptions!K29,InputDataA_GeneralAssumptions!K30) | L31: =IF(VLOOKUP(InputDataA_GeneralAssumptions!$D$33,DataSummary!$A$110:$B$112,2,FALSE())=1,InputDataA_GeneralAssumptions!L29,InputDataA_GeneralAssumptions!L30) | M31: =IF(VLOOKUP(InputDataA_GeneralAssumptions!$D$33,DataSummary!$A$110:$B$112,2,FALSE())=1,InputDataA_GeneralAssumptions!M29,InputDataA_GeneralAssumptions!M30) | N31: =IF(VLOOKUP(InputDataA_GeneralAssumptions!$D$33,DataSummary!$A$110:$B$112,2,FALSE())=1,InputDataA_GeneralAssumptions!N29,InputDataA_GeneralAssumptions!N30) | O31: =IF(VLOOKUP(InputDataA_GeneralAssumptions!$D$33,DataSummary!$A$110:$B$112,2,FALSE())=1,InputDataA_GeneralAssumptions!O29,InputDataA_GeneralAssumptions!O30) | P31: =IF(VLOOKUP(InputDataA_GeneralAssumptions!$D$33,DataSummary!$A$110:$B$112,2,FALSE())=1,InputDataA_GeneralAssumptions!P29,InputDataA_GeneralAssumptions!P30) | ... BW31: =IF(VLOOKUP(InputDataA_GeneralAssumptions!$D$33,DataSummary!$A$110:$B$112,2,FALSE())=1,InputDataA_GeneralAssumptions!BW29,InputDataA_GeneralAssumptions!BW30)
B33: Choice for future growth rate of TFP: | C33: Select from list --> | D33: Automatic | F33: =DataSummary!N5 | G33: "Manual" [user defined year by year] | H33: (e.g. 0.02) | I33: =I34 | J33: 0.01 | K33: 0.01 | L33: 0.01 | M33: 0.01 | N33: 0.01 | O33: 0.01 | P33: 0.01 | Q33: 0.01 | R33: 0.01 | S33: 0.01 | T33: 0.01 | U33: 0.01 | V33: 0.01 | W33: 0.01 | X33: 0.01 | Y33: 0.01 | Z33: 0.01 | AA33: 0.01 | AB33: 0.01 | AC33: 0.01 | AD33: 0.01 | AE33: 0.01 | AF33: 0.01 | AG33: 0.01 | AH33: 0.01 | AI33: 0.01 | AJ33: 0.01 | AK33: 0.01 | AL33: 0.01 | AM33: 0.01 | AN33: 0.01 | AO33: 0.01 | AP33: 0.01 | AQ33: 0.01 | AR33: 0.01 | AS33: 0.01 | AT33: 0.01 | AU33: 0.01 | AV33: 0.01 | AW33: 0.01 | AX33: 0.01 | AY33: 0.01 | AZ33: 0.01 | BA33: 0.01 | BB33: 0.01 | BC33: 0.01 | BD33: 0.01 | BE33: 0.01 | BF33: 0.01 | BG33: 0.01 | BH33: 0.01 | BI33: 0.01 | BJ33: 0.01 | BK33: 0.01 | BL33: 0.01 | BM33: 0.01 | BN33: 0.01 | BO33: 0.01 | BP33: 0.01 | BQ33: 0.01 | BR33: 0.01 | BS33: 0.01 | BT33: 0.01 | BU33: 0.01 | BV33: 0.01 | BW33: 0.01
B34: Target TFP annual growth rate --> | C34: (e.g. 0.01) | D34: =D31 | E34: =D34 | G34: "Automatic" [reach target by year] | H34: =H33 | I34: =InputDataA_GeneralAssumptions!E31 | J34: =IF(J28>InputDataA_GeneralAssumptions!$E$35,InputDataA_GeneralAssumptions!$E$34,I34+(InputDataA_GeneralAssumptions!$E$34-InputDataA_GeneralAssumptions!$I$34)/(InputDataA_GeneralAssumptions!$E$35-InputDataA_GeneralAssumptions!$D$7)) | K34: =IF(K28>InputDataA_GeneralAssumptions!$E$35,InputDataA_GeneralAssumptions!$E$34,J34+(InputDataA_GeneralAssumptions!$E$34-InputDataA_GeneralAssumptions!$I$34)/(InputDataA_GeneralAssumptions!$E$35-InputDataA_GeneralAssumptions!$D$7)) | L34: =IF(L28>InputDataA_GeneralAssumptions!$E$35,InputDataA_GeneralAssumptions!$E$34,K34+(InputDataA_GeneralAssumptions!$E$34-InputDataA_GeneralAssumptions!$I$34)/(InputDataA_GeneralAssumptions!$E$35-InputDataA_GeneralAssumptions!$D$7)) | M34: =IF(M28>InputDataA_GeneralAssumptions!$E$35,InputDataA_GeneralAssumptions!$E$34,L34+(InputDataA_GeneralAssumptions!$E$34-InputDataA_GeneralAssumptions!$I$34)/(InputDataA_GeneralAssumptions!$E$35-InputDataA_GeneralAssumptions!$D$7)) | N34: =IF(N28>InputDataA_GeneralAssumptions!$E$35,InputDataA_GeneralAssumptions!$E$34,M34+(InputDataA_GeneralAssumptions!$E$34-InputDataA_GeneralAssumptions!$I$34)/(InputDataA_GeneralAssumptions!$E$35-InputDataA_GeneralAssumptions!$D$7)) | O34: =IF(O28>InputDataA_GeneralAssumptions!$E$35,InputDataA_GeneralAssumptions!$E$34,N34+(InputDataA_GeneralAssumptions!$E$34-InputDataA_GeneralAssumptions!$I$34)/(InputDataA_GeneralAssumptions!$E$35-InputDataA_GeneralAssumptions!$D$7)) | P34: =IF(P28>InputDataA_GeneralAssumptions!$E$35,InputDataA_GeneralAssumptions!$E$34,O34+(InputDataA_GeneralAssumptions!$E$34-InputDataA_GeneralAssumptions!$I$34)/(InputDataA_GeneralAssumptions!$E$35-InputDataA_GeneralAssumptions!$D$7)) | Q34: =IF(Q28>InputDataA_GeneralAssumptions!$E$35,InputDataA_GeneralAssumptions!$E$34,P34+(InputDataA_GeneralAssumptions!$E$34-InputDataA_GeneralAssumptions!$I$34)/(InputDataA_GeneralAssumptions!$E$35-InputDataA_GeneralAssumptions!$D$7)) | ... BW34: =IF(BW28>InputDataA_GeneralAssumptions!$E$35,InputDataA_GeneralAssumptions!$E$34,BV34+(InputDataA_GeneralAssumptions!$E$34-InputDataA_GeneralAssumptions!$I$34)/(InputDataA_GeneralAssumptions!$E$35-InputDataA_GeneralAssumptions!$D$7))
B35: Reach target TFP annual growth rate by year --> | C35: (YYYY) | D35: 2030 | E35: =D35 | G35: Used in "scenario" simulation | H35: =H34 | I35: =IF(VLOOKUP(InputDataA_GeneralAssumptions!$D$33,DataSummary!$A$110:$B$112,2,FALSE())=1,InputDataA_GeneralAssumptions!I33,InputDataA_GeneralAssumptions!I34) | J35: =IF(VLOOKUP(InputDataA_GeneralAssumptions!$D$33,DataSummary!$A$110:$B$112,2,FALSE())=1,InputDataA_GeneralAssumptions!J33,InputDataA_GeneralAssumptions!J34) | K35: =IF(VLOOKUP(InputDataA_GeneralAssumptions!$D$33,DataSummary!$A$110:$B$112,2,FALSE())=1,InputDataA_GeneralAssumptions!K33,InputDataA_GeneralAssumptions!K34) | L35: =IF(VLOOKUP(InputDataA_GeneralAssumptions!$D$33,DataSummary!$A$110:$B$112,2,FALSE())=1,InputDataA_GeneralAssumptions!L33,InputDataA_GeneralAssumptions!L34) | M35: =IF(VLOOKUP(InputDataA_GeneralAssumptions!$D$33,DataSummary!$A$110:$B$112,2,FALSE())=1,InputDataA_GeneralAssumptions!M33,InputDataA_GeneralAssumptions!M34) | N35: =IF(VLOOKUP(InputDataA_GeneralAssumptions!$D$33,DataSummary!$A$110:$B$112,2,FALSE())=1,InputDataA_GeneralAssumptions!N33,InputDataA_GeneralAssumptions!N34) | O35: =IF(VLOOKUP(InputDataA_GeneralAssumptions!$D$33,DataSummary!$A$110:$B$112,2,FALSE())=1,InputDataA_GeneralAssumptions!O33,InputDataA_GeneralAssumptions!O34) | P35: =IF(VLOOKUP(InputDataA_GeneralAssumptions!$D$33,DataSummary!$A$110:$B$112,2,FALSE())=1,InputDataA_GeneralAssumptions!P33,InputDataA_GeneralAssumptions!P34) | ... BW35: =IF(VLOOKUP(InputDataA_GeneralAssumptions!$D$33,DataSummary!$A$110:$B$112,2,FALSE())=1,InputDataA_GeneralAssumptions!BW33,InputDataA_GeneralAssumptions!BW34)
B38: Labor Market Participation | F38: =D39 | G38: Participation rate, male | H38: Chart | I38: =InputDataA_GeneralAssumptions!$D$7 | J38: =I38+1 | K38: =J38+1 | L38: =K38+1 | M38: =L38+1 | N38: =M38+1 | O38: =N38+1 | P38: =O38+1 | Q38: =P38+1 | ... BW38: =BV38+1
B39: Choice for Future Labor Participation: | C39: Select from list --> | D39: Automatic | F39: =DataSummary!N4 | G39: "Manual" [user defined year by year] | H39: (e.g. 0.40) | I39: =I40 | J39: 0.86728206 | K39: 0.86753571 | L39: 0.86782619 | M39: 0.86815595 | N39: 0.86852709 | O39: 0.86894124 | P39: 0.86939952 | Q39: 0.86990245 | R39: 0.87044993 | S39: 0.8710412 | T39: 0.87167486 | U39: 0.87234885 | V39: 0.87306054 | W39: 0.87380676 | X39: 0.87458387 | Y39: 0.87538787 | Z39: 0.87621445 | AA39: 0.87705914 | AB39: 0.87791734 | AC39: 0.87878448 | AD39: 0.87965603 | AE39: 0.88052764 | AF39: 0.88139516 | AG39: 0.88225471 | AH39: 0.88310273 | AI39: 0.88393598 | AJ39: 0.88475159 | AK39: 0.88554707 | AL39: 0.88632025 | AM39: 0.88706938 | AN39: 0.887793 | AO39: 0.88849002 | AP39: 0.88915962 | AQ39: 0.8898013 | AR39: 0.89041477 | AS39: 0.891 | AT39: =AS39 | AU39: =AT39 | AV39: =AU39 | AW39: =AV39 | AX39: =AW39 | AY39: =AX39 | AZ39: =AY39 | BA39: =AZ39 | ... BW39: =BV39
B40: Initial participation rate --> | C40: (e.g. 0.40) | D40: =IF(ISNUMBER(DataSummary!D35)=TRUE(),DataSummary!D35,".") | G40: "Automatic" [reach target by year] | H40: =H39 | I40: =InputDataA_GeneralAssumptions!D44 | J40: =IF(J38>InputDataA_GeneralAssumptions!$D$47,InputDataA_GeneralAssumptions!$D$46,I40+(InputDataA_GeneralAssumptions!$D$46-$I$40)/(InputDataA_GeneralAssumptions!$D$47-InputDataA_GeneralAssumptions!$D$7)) | K40: =IF(K38>InputDataA_GeneralAssumptions!$D$47,InputDataA_GeneralAssumptions!$D$46,J40+(InputDataA_GeneralAssumptions!$D$46-$I$40)/(InputDataA_GeneralAssumptions!$D$47-InputDataA_GeneralAssumptions!$D$7)) | L40: =IF(L38>InputDataA_GeneralAssumptions!$D$47,InputDataA_GeneralAssumptions!$D$46,K40+(InputDataA_GeneralAssumptions!$D$46-$I$40)/(InputDataA_GeneralAssumptions!$D$47-InputDataA_GeneralAssumptions!$D$7)) | M40: =IF(M38>InputDataA_GeneralAssumptions!$D$47,InputDataA_GeneralAssumptions!$D$46,L40+(InputDataA_GeneralAssumptions!$D$46-$I$40)/(InputDataA_GeneralAssumptions!$D$47-InputDataA_GeneralAssumptions!$D$7)) | N40: =IF(N38>InputDataA_GeneralAssumptions!$D$47,InputDataA_GeneralAssumptions!$D$46,M40+(InputDataA_GeneralAssumptions!$D$46-$I$40)/(InputDataA_GeneralAssumptions!$D$47-InputDataA_GeneralAssumptions!$D$7)) | O40: =IF(O38>InputDataA_GeneralAssumptions!$D$47,InputDataA_GeneralAssumptions!$D$46,N40+(InputDataA_GeneralAssumptions!$D$46-$I$40)/(InputDataA_GeneralAssumptions!$D$47-InputDataA_GeneralAssumptions!$D$7)) | P40: =IF(P38>InputDataA_GeneralAssumptions!$D$47,InputDataA_GeneralAssumptions!$D$46,O40+(InputDataA_GeneralAssumptions!$D$46-$I$40)/(InputDataA_GeneralAssumptions!$D$47-InputDataA_GeneralAssumptions!$D$7)) | Q40: =IF(Q38>InputDataA_GeneralAssumptions!$D$47,InputDataA_GeneralAssumptions!$D$46,P40+(InputDataA_GeneralAssumptions!$D$46-$I$40)/(InputDataA_GeneralAssumptions!$D$47-InputDataA_GeneralAssumptions!$D$7)) | ... BW40: =IF(BW38>InputDataA_GeneralAssumptions!$D$47,InputDataA_GeneralAssumptions!$D$46,BV40+(InputDataA_GeneralAssumptions!$D$46-$I$40)/(InputDataA_GeneralAssumptions!$D$47-InputDataA_GeneralAssumptions!$D$7))
B41: Participation rate, male | G41: Used in "baseline" simulation | H41: (e.g. 0.40) | I41: =IF(VLOOKUP(InputDataA_GeneralAssumptions!$D$39,DataSummary!$A$110:$B$112,2,FALSE())=1,InputDataA_GeneralAssumptions!I39,InputDataA_GeneralAssumptions!I40) | J41: =IF(VLOOKUP(InputDataA_GeneralAssumptions!$D$39,DataSummary!$A$110:$B$112,2,FALSE())=1,InputDataA_GeneralAssumptions!J39,InputDataA_GeneralAssumptions!J40) | K41: =IF(VLOOKUP(InputDataA_GeneralAssumptions!$D$39,DataSummary!$A$110:$B$112,2,FALSE())=1,InputDataA_GeneralAssumptions!K39,InputDataA_GeneralAssumptions!K40) | L41: =IF(VLOOKUP(InputDataA_GeneralAssumptions!$D$39,DataSummary!$A$110:$B$112,2,FALSE())=1,InputDataA_GeneralAssumptions!L39,InputDataA_GeneralAssumptions!L40) | M41: =IF(VLOOKUP(InputDataA_GeneralAssumptions!$D$39,DataSummary!$A$110:$B$112,2,FALSE())=1,InputDataA_GeneralAssumptions!M39,InputDataA_GeneralAssumptions!M40) | N41: =IF(VLOOKUP(InputDataA_GeneralAssumptions!$D$39,DataSummary!$A$110:$B$112,2,FALSE())=1,InputDataA_GeneralAssumptions!N39,InputDataA_GeneralAssumptions!N40) | O41: =IF(VLOOKUP(InputDataA_GeneralAssumptions!$D$39,DataSummary!$A$110:$B$112,2,FALSE())=1,InputDataA_GeneralAssumptions!O39,InputDataA_GeneralAssumptions!O40) | P41: =IF(VLOOKUP(InputDataA_GeneralAssumptions!$D$39,DataSummary!$A$110:$B$112,2,FALSE())=1,InputDataA_GeneralAssumptions!P39,InputDataA_GeneralAssumptions!P40) | ... BW41: =IF(VLOOKUP(InputDataA_GeneralAssumptions!$D$39,DataSummary!$A$110:$B$112,2,FALSE())=1,InputDataA_GeneralAssumptions!BW39,InputDataA_GeneralAssumptions!BW40)
B42: Initial participation rate, male (user defined) --> | C42: (e.g. 0.40)
B43: ="Init partic rate male, pre-loaded (Avail. "&D7&") -->" | C43: (e.g. 0.40) | D43: =IF(ISNUMBER(DataSummary!D36)=TRUE(),DataSummary!D36,".") | F43: =DataSummary!N5 | G43: "Manual" [user defined year by year] | H43: (e.g. 0.40) | I43: =I44 | J43: 0.86728206 | K43: 0.86753571 | L43: 0.86782619 | M43: 0.86815595 | N43: 0.86852709 | O43: 0.86894124 | P43: 0.86939952 | Q43: 0.86990245 | R43: 0.87044993 | S43: 0.8710412 | T43: 0.87167486 | U43: 0.87234885 | V43: 0.87306054 | W43: 0.87380676 | X43: 0.87458387 | Y43: 0.87538787 | Z43: 0.87621445 | AA43: 0.87705914 | AB43: 0.87791734 | AC43: 0.87878448 | AD43: 0.87965603 | AE43: 0.88052764 | AF43: 0.88139516 | AG43: 0.88225471 | AH43: 0.88310273 | AI43: 0.88393598 | AJ43: 0.88475159 | AK43: 0.88554707 | AL43: 0.88632025 | AM43: 0.88706938 | AN43: 0.887793 | AO43: 0.88849002 | AP43: 0.88915962 | AQ43: 0.8898013 | AR43: 0.89041477 | AS43: 0.891 | AT43: 0.891 | AU43: 0.891 | AV43: 0.891 | AW43: 0.891 | AX43: 0.891 | AY43: 0.891 | AZ43: 0.891 | BA43: 0.891 | BB43: 0.891 | BC43: 0.891 | BD43: 0.891 | BE43: 0.891 | BF43: 0.891 | BG43: 0.891 | BH43: 0.891 | BI43: 0.891 | BJ43: 0.891 | BK43: 0.891 | BL43: 0.891 | BM43: 0.891 | BN43: 0.891 | BO43: 0.891 | BP43: 0.891 | BQ43: 0.891 | BR43: 0.891 | BS43: 0.891 | BT43: 0.891 | BU43: 0.891 | BV43: 0.891 | BW43: 0.891
B44: Initial is: (if cell D42:E42 -yellow- is blank uses pre-loaded) --> | C44: (e.g. 0.40) | D44: =IF(ISBLANK(D42)=TRUE(),D43,D42) | E44: =IF(ISBLANK(E42)=TRUE(),D43,E42) | G44: "Automatic" [reach target by year] | H44: (e.g. 0.40) | I44: =InputDataA_GeneralAssumptions!E44 | J44: =IF(J38>InputDataA_GeneralAssumptions!$E$47,InputDataA_GeneralAssumptions!$E$46,I44+(InputDataA_GeneralAssumptions!$E$46-$I$44)/(InputDataA_GeneralAssumptions!$E$47-InputDataA_GeneralAssumptions!$D$7)) | K44: =IF(K38>InputDataA_GeneralAssumptions!$E$47,InputDataA_GeneralAssumptions!$E$46,J44+(InputDataA_GeneralAssumptions!$E$46-$I$44)/(InputDataA_GeneralAssumptions!$E$47-InputDataA_GeneralAssumptions!$D$7)) | L44: =IF(L38>InputDataA_GeneralAssumptions!$E$47,InputDataA_GeneralAssumptions!$E$46,K44+(InputDataA_GeneralAssumptions!$E$46-$I$44)/(InputDataA_GeneralAssumptions!$E$47-InputDataA_GeneralAssumptions!$D$7)) | M44: =IF(M38>InputDataA_GeneralAssumptions!$E$47,InputDataA_GeneralAssumptions!$E$46,L44+(InputDataA_GeneralAssumptions!$E$46-$I$44)/(InputDataA_GeneralAssumptions!$E$47-InputDataA_GeneralAssumptions!$D$7)) | N44: =IF(N38>InputDataA_GeneralAssumptions!$E$47,InputDataA_GeneralAssumptions!$E$46,M44+(InputDataA_GeneralAssumptions!$E$46-$I$44)/(InputDataA_GeneralAssumptions!$E$47-InputDataA_GeneralAssumptions!$D$7)) | O44: =IF(O38>InputDataA_GeneralAssumptions!$E$47,InputDataA_GeneralAssumptions!$E$46,N44+(InputDataA_GeneralAssumptions!$E$46-$I$44)/(InputDataA_GeneralAssumptions!$E$47-InputDataA_GeneralAssumptions!$D$7)) | P44: =IF(P38>InputDataA_GeneralAssumptions!$E$47,InputDataA_GeneralAssumptions!$E$46,O44+(InputDataA_GeneralAssumptions!$E$46-$I$44)/(InputDataA_GeneralAssumptions!$E$47-InputDataA_GeneralAssumptions!$D$7)) | Q44: =IF(Q38>InputDataA_GeneralAssumptions!$E$47,InputDataA_GeneralAssumptions!$E$46,P44+(InputDataA_GeneralAssumptions!$E$46-$I$44)/(InputDataA_GeneralAssumptions!$E$47-InputDataA_GeneralAssumptions!$D$7)) | ... BW44: =IF(BW38>InputDataA_GeneralAssumptions!$E$47,InputDataA_GeneralAssumptions!$E$46,BV44+(InputDataA_GeneralAssumptions!$E$46-$I$44)/(InputDataA_GeneralAssumptions!$E$47-InputDataA_GeneralAssumptions!$D$7))
G45: Used in "scenario" simulation | H45: (e.g. 0.40) | I45: =IF(VLOOKUP(InputDataA_GeneralAssumptions!$D$39,DataSummary!$A$110:$B$112,2,FALSE())=1,InputDataA_GeneralAssumptions!I43,InputDataA_GeneralAssumptions!I44) | J45: =IF(VLOOKUP(InputDataA_GeneralAssumptions!$D$39,DataSummary!$A$110:$B$112,2,FALSE())=1,InputDataA_GeneralAssumptions!J43,InputDataA_GeneralAssumptions!J44) | K45: =IF(VLOOKUP(InputDataA_GeneralAssumptions!$D$39,DataSummary!$A$110:$B$112,2,FALSE())=1,InputDataA_GeneralAssumptions!K43,InputDataA_GeneralAssumptions!K44) | L45: =IF(VLOOKUP(InputDataA_GeneralAssumptions!$D$39,DataSummary!$A$110:$B$112,2,FALSE())=1,InputDataA_GeneralAssumptions!L43,InputDataA_GeneralAssumptions!L44) | M45: =IF(VLOOKUP(InputDataA_GeneralAssumptions!$D$39,DataSummary!$A$110:$B$112,2,FALSE())=1,InputDataA_GeneralAssumptions!M43,InputDataA_GeneralAssumptions!M44) | N45: =IF(VLOOKUP(InputDataA_GeneralAssumptions!$D$39,DataSummary!$A$110:$B$112,2,FALSE())=1,InputDataA_GeneralAssumptions!N43,InputDataA_GeneralAssumptions!N44) | O45: =IF(VLOOKUP(InputDataA_GeneralAssumptions!$D$39,DataSummary!$A$110:$B$112,2,FALSE())=1,InputDataA_GeneralAssumptions!O43,InputDataA_GeneralAssumptions!O44) | P45: =IF(VLOOKUP(InputDataA_GeneralAssumptions!$D$39,DataSummary!$A$110:$B$112,2,FALSE())=1,InputDataA_GeneralAssumptions!P43,InputDataA_GeneralAssumptions!P44) | ... BW45: =IF(VLOOKUP(InputDataA_GeneralAssumptions!$D$39,DataSummary!$A$110:$B$112,2,FALSE())=1,InputDataA_GeneralAssumptions!BW43,InputDataA_GeneralAssumptions!BW44)
B46: Target participation rate, male --> | C46: (e.g. 0.40) | D46: =D44 | E46: =E44
B47: Reach target Participation Rate Male by year --> | C47: (YYYY) | D47: 2030 | E47: 2030 | G47: Participation rate, female | H47: Chart | I47: =InputDataA_GeneralAssumptions!$D$7 | J47: =I47+1 | K47: =J47+1 | L47: =K47+1 | M47: =L47+1 | N47: =M47+1 | O47: =N47+1 | P47: =O47+1 | Q47: =P47+1 | ... BW47: =BV47+1
F48: =DataSummary!N4 | G48: "Manual" [user defined year by year] | H48: (e.g. 0.40) | I48: =I49 | J48: 0.61435265 | K48: 0.61725912 | L48: 0.62085306 | M48: 0.6251849 | N48: 0.63027769 | O48: 0.63612271 | P48: 0.64267805 | Q48: 0.64987035 | R48: 0.65759959 | S48: 0.66574585 | T48: 0.67417742 | U48: 0.68275899 | V48: 0.69135918 | W48: 0.69985674 | X48: 0.70814506 | Y48: 0.71613494 | Z48: 0.72375576 | AA48: 0.73095535 | AB48: 0.73769873 | AC48: 0.74396634 | AD48: 0.74975179 | AE48: 0.75505949 | AF48: 0.75990237 | AG48: 0.76429978 | AH48: 0.76827556 | AI48: 0.77185648 | AJ48: 0.77507092 | AK48: 0.77794784 | AL48: 0.78051593 | AM48: 0.78280305 | AN48: 0.7848358 | AO48: 0.78663923 | AP48: 0.7882367 | AQ48: 0.78964977 | AR48: 0.7908982 | AS48: 0.792 | AT48: =AS48 | AU48: =AT48 | AV48: =AU48 | AW48: =AV48 | AX48: =AW48 | AY48: =AX48 | AZ48: =AY48 | BA48: =AZ48 | ... BW48: =BV48
...

Sheet GraphsA
B1: Graphs of assumptons which affect all model
A3: Main growth drivers (Human Capital and TFP)
F18: Back | O18: Back
A19: Labor force Participation Rate (by Gender)
G34: Back | O34: Back | W34: Back
A35: External balance variables (either CAB or debt & FDI are active)
G50: Back | O50: Back | W50: Back
A51: Demographic variables
G66: Back | O66: Back | W66: Back | AD66: Back
B67: Poverty and Income Distribution

Sheet InputDataB_ModelSpecAssumptions
B1: Assumption Specific to Model 1, Model 2 or Model 3 | AN1: ="35 hidden columns for years "&AO3&" to "&BW3&" -->"
B3: Model 1: Calculating growth implied by investment | C3: =DataSummary!D278 | D3: =DataSummary!N4 | E3: =DataSummary!N5 | F3: =D8 | G3: Investment to GDP Ratio | H3: Chart | I3: =InputDataA_GeneralAssumptions!$D$7 | J3: =I3+1 | K3: =J3+1 | L3: =K3+1 | M3: =L3+1 | N3: =M3+1 | O3: =N3+1 | P3: =O3+1 | Q3: =P3+1 | ... BW3: =BV3+1
B4: Initial Investment Ratio (I/Y) (User defined) --> | C4: (e.g. 0.40) | D4: 0.31 | E4: 0.31 | F4: =DataSummary!N4 | G4: "Manual" [user defined year by year] | H4: (e.g. 0.40) | I4: =I5 | J4: 0.25 | K4: 0.25 | L4: 0.25 | M4: 0.25 | N4: 0.25 | O4: 0.25 | P4: 0.25 | Q4: 0.25 | R4: 0.25 | S4: 0.25 | T4: 0.25 | U4: 0.25 | V4: 0.25 | W4: 0.25 | X4: 0.25 | Y4: 0.25 | Z4: 0.25 | AA4: 0.25 | AB4: 0.25 | AC4: 0.25 | AD4: 0.25 | AE4: 0.25 | AF4: 0.25 | AG4: 0.25 | AH4: 0.25 | AI4: 0.25 | AJ4: 0.25 | AK4: 0.25 | AL4: 0.25 | AM4: 0.25 | AN4: 0.25 | AO4: 0.25 | AP4: 0.25 | AQ4: 0.25 | AR4: 0.25 | AS4: 0.25 | AT4: =AS4 | AU4: =AT4 | AV4: =AU4 | AW4: =AV4 | AX4: =AW4 | AY4: =AX4 | AZ4: =AY4 | BA4: =AZ4 | ... BW4: =BV4
B5: ="Initial Investment Ratio, pre-loaded from "&DataSummary!D278&" -->" | C5: WDI 2019 | D5: =IF(ISNUMBER(IF(InputDataA_GeneralAssumptions!D7>202020,".",DataSummary!B278))=TRUE(),IF(InputDataA_GeneralAssumptions!D7>2020,".",DataSummary!B278),".") | G5: "Automatic" [reach target by year] | H5: =H4 | I5: =D6 | J5: =IF(Submodel1!F4>InputDataB_ModelSpecAssumptions!$D$10,InputDataB_ModelSpecAssumptions!$D$9,I5+(InputDataB_ModelSpecAssumptions!$D$9-$I$5)/(InputDataB_ModelSpecAssumptions!$D$10-InputDataA_GeneralAssumptions!$D$7)) | K5: =IF(Submodel1!G4>InputDataB_ModelSpecAssumptions!$D$10,InputDataB_ModelSpecAssumptions!$D$9,J5+(InputDataB_ModelSpecAssumptions!$D$9-$I$5)/(InputDataB_ModelSpecAssumptions!$D$10-InputDataA_GeneralAssumptions!$D$7)) | L5: =IF(Submodel1!H4>InputDataB_ModelSpecAssumptions!$D$10,InputDataB_ModelSpecAssumptions!$D$9,K5+(InputDataB_ModelSpecAssumptions!$D$9-$I$5)/(InputDataB_ModelSpecAssumptions!$D$10-InputDataA_GeneralAssumptions!$D$7)) | M5: =IF(Submodel1!I4>InputDataB_ModelSpecAssumptions!$D$10,InputDataB_ModelSpecAssumptions!$D$9,L5+(InputDataB_ModelSpecAssumptions!$D$9-$I$5)/(InputDataB_ModelSpecAssumptions!$D$10-InputDataA_GeneralAssumptions!$D$7)) | N5: =IF(Submodel1!J4>InputDataB_ModelSpecAssumptions!$D$10,InputDataB_ModelSpecAssumptions!$D$9,M5+(InputDataB_ModelSpecAssumptions!$D$9-$I$5)/(InputDataB_ModelSpecAssumptions!$D$10-InputDataA_GeneralAssumptions!$D$7)) | O5: =IF(Submodel1!K4>InputDataB_ModelSpecAssumptions!$D$10,InputDataB_ModelSpecAssumptions!$D$9,N5+(InputDataB_ModelSpecAssumptions!$D$9-$I$5)/(InputDataB_ModelSpecAssumptions!$D$10-InputDataA_GeneralAssumptions!$D$7)) | P5: =IF(Submodel1!L4>InputDataB_ModelSpecAssumptions!$D$10,InputDataB_ModelSpecAssumptions!$D$9,O5+(InputDataB_ModelSpecAssumptions!$D$9-$I$5)/(InputDataB_ModelSpecAssumptions!$D$10-InputDataA_GeneralAssumptions!$D$7)) | Q5: =IF(Submodel1!M4>InputDataB_ModelSpecAssumptions!$D$10,InputDataB_ModelSpecAssumptions!$D$9,P5+(InputDataB_ModelSpecAssumptions!$D$9-$I$5)/(InputDataB_ModelSpecAssumptions!$D$10-InputDataA_GeneralAssumptions!$D$7)) | ... BW5: =IF(Submodel1!BS4>InputDataB_ModelSpecAssumptions!$D$10,InputDataB_ModelSpecAssumptions!$D$9,BV5+(InputDataB_ModelSpecAssumptions!$D$9-$I$5)/(InputDataB_ModelSpecAssumptions!$D$10-InputDataA_GeneralAssumptions!$D$7))
B6: Initial is: (if cell D4:E4 -yellow- is blank uses pre-loaded) --> | C6: (e.g. 0.40) | D6: =IF(ISBLANK(D4)=TRUE(),D5,D4) | E6: =IF(ISBLANK(E4)=TRUE(),D5,E4) | G6: Used in "baseline" simulation | H6: (e.g. 0.40) | I6: =IF(VLOOKUP(InputDataB_ModelSpecAssumptions!$D$8,DataSummary!$A$111:$B$112,2,FALSE())=1,InputDataB_ModelSpecAssumptions!I4,InputDataB_ModelSpecAssumptions!I5) | J6: =IF(VLOOKUP(InputDataB_ModelSpecAssumptions!$D$8,DataSummary!$A$111:$B$112,2,FALSE())=1,InputDataB_ModelSpecAssumptions!J4,InputDataB_ModelSpecAssumptions!J5) | K6: =IF(VLOOKUP(InputDataB_ModelSpecAssumptions!$D$8,DataSummary!$A$111:$B$112,2,FALSE())=1,InputDataB_ModelSpecAssumptions!K4,InputDataB_ModelSpecAssumptions!K5) | L6: =IF(VLOOKUP(InputDataB_ModelSpecAssumptions!$D$8,DataSummary!$A$111:$B$112,2,FALSE())=1,InputDataB_ModelSpecAssumptions!L4,InputDataB_ModelSpecAssumptions!L5) | M6: =IF(VLOOKUP(InputDataB_ModelSpecAssumptions!$D$8,DataSummary!$A$111:$B$112,2,FALSE())=1,InputDataB_ModelSpecAssumptions!M4,InputDataB_ModelSpecAssumptions!M5) | N6: =IF(VLOOKUP(InputDataB_ModelSpecAssumptions!$D$8,DataSummary!$A$111:$B$112,2,FALSE())=1,InputDataB_ModelSpecAssumptions!N4,InputDataB_ModelSpecAssumptions!N5) | O6: =IF(VLOOKUP(InputDataB_ModelSpecAssumptions!$D$8,DataSummary!$A$111:$B$112,2,FALSE())=1,InputDataB_ModelSpecAssumptions!O4,InputDataB_ModelSpecAssumptions!O5) | P6: =IF(VLOOKUP(InputDataB_ModelSpecAssumptions!$D$8,DataSummary!$A$111:$B$112,2,FALSE())=1,InputDataB_ModelSpecAssumptions!P4,InputDataB_ModelSpecAssumptions!P5) | ... BW6: =IF(VLOOKUP(InputDataB_ModelSpecAssumptions!$D$8,DataSummary!$A$111:$B$112,2,FALSE())=1,InputDataB_ModelSpecAssumptions!BW4,InputDataB_ModelSpecAssumptions!BW5)
B8: Choice for future Capital Formation: | C8: Select from list --> | D8: Automatic | F8: =DataSummary!N5 | G8: "Manual" [user defined year by year] | H8: (e.g. 0.40) | I8: =I9 | J8: 0.25 | K8: 0.25 | L8: 0.25 | M8: 0.25 | N8: 0.25 | O8: 0.25 | P8: 0.25 | Q8: 0.25 | R8: 0.25 | S8: 0.25 | T8: 0.25 | U8: 0.25 | V8: 0.25 | W8: 0.25 | X8: 0.25 | Y8: 0.25 | Z8: 0.25 | AA8: 0.25 | AB8: 0.25 | AC8: 0.25 | AD8: 0.25 | AE8: 0.25 | AF8: 0.25 | AG8: 0.25 | AH8: 0.25 | AI8: 0.25 | AJ8: 0.25 | AK8: 0.25 | AL8: 0.25 | AM8: 0.25 | AN8: 0.25 | AO8: 0.25 | AP8: 0.25 | AQ8: 0.25 | AR8: 0.25 | AS8: 0.25 | AT8: 0.25 | AU8: 0.25 | AV8: 0.25 | AW8: 0.25 | AX8: 0.25 | AY8: 0.25 | AZ8: 0.25 | BA8: 0.25 | BB8: 0.25 | BC8: 0.25 | BD8: 0.25 | BE8: 0.25 | BF8: 0.25 | BG8: 0.25 | BH8: 0.25 | BI8: 0.25 | BJ8: 0.25 | BK8: 0.25 | BL8: 0.25 | BM8: 0.25 | BN8: 0.25 | BO8: 0.25 | BP8: 0.25 | BQ8: 0.25 | BR8: 0.25 | BS8: 0.25 | BT8: 0.25 | BU8: 0.25 | BV8: 0.25 | BW8: 0.25
B9: Target Investment Ratio (I/Y) --> | C9: (e.g. 0.40) | D9: 0.31 | E9: 0.24 | G9: "Automatic" [reach target by year] | H9: (e.g. 0.40) | I9: =E6 | J9: =IF(Submodel1s!F4>InputDataB_ModelSpecAssumptions!$E$10,InputDataB_ModelSpecAssumptions!$E$9,I9+(InputDataB_ModelSpecAssumptions!$E$9-$I$9)/(InputDataB_ModelSpecAssumptions!$E$10-InputDataA_GeneralAssumptions!$D$7)) | K9: =IF(Submodel1s!G4>InputDataB_ModelSpecAssumptions!$E$10,InputDataB_ModelSpecAssumptions!$E$9,J9+(InputDataB_ModelSpecAssumptions!$E$9-$I$9)/(InputDataB_ModelSpecAssumptions!$E$10-InputDataA_GeneralAssumptions!$D$7)) | L9: =IF(Submodel1s!H4>InputDataB_ModelSpecAssumptions!$E$10,InputDataB_ModelSpecAssumptions!$E$9,K9+(InputDataB_ModelSpecAssumptions!$E$9-$I$9)/(InputDataB_ModelSpecAssumptions!$E$10-InputDataA_GeneralAssumptions!$D$7)) | M9: =IF(Submodel1s!I4>InputDataB_ModelSpecAssumptions!$E$10,InputDataB_ModelSpecAssumptions!$E$9,L9+(InputDataB_ModelSpecAssumptions!$E$9-$I$9)/(InputDataB_ModelSpecAssumptions!$E$10-InputDataA_GeneralAssumptions!$D$7)) | N9: =IF(Submodel1s!J4>InputDataB_ModelSpecAssumptions!$E$10,InputDataB_ModelSpecAssumptions!$E$9,M9+(InputDataB_ModelSpecAssumptions!$E$9-$I$9)/(InputDataB_ModelSpecAssumptions!$E$10-InputDataA_GeneralAssumptions!$D$7)) | O9: =IF(Submodel1s!K4>InputDataB_ModelSpecAssumptions!$E$10,InputDataB_ModelSpecAssumptions!$E$9,N9+(InputDataB_ModelSpecAssumptions!$E$9-$I$9)/(InputDataB_ModelSpecAssumptions!$E$10-InputDataA_GeneralAssumptions!$D$7)) | P9: =IF(Submodel1s!L4>InputDataB_ModelSpecAssumptions!$E$10,InputDataB_ModelSpecAssumptions!$E$9,O9+(InputDataB_ModelSpecAssumptions!$E$9-$I$9)/(InputDataB_ModelSpecAssumptions!$E$10-InputDataA_GeneralAssumptions!$D$7)) | Q9: =IF(Submodel1s!M4>InputDataB_ModelSpecAssumptions!$E$10,InputDataB_ModelSpecAssumptions!$E$9,P9+(InputDataB_ModelSpecAssumptions!$E$9-$I$9)/(InputDataB_ModelSpecAssumptions!$E$10-InputDataA_GeneralAssumptions!$D$7)) | ... BW9: =IF(Submodel1s!BS4>InputDataB_ModelSpecAssumptions!$E$10,InputDataB_ModelSpecAssumptions!$E$9,BV9+(InputDataB_ModelSpecAssumptions!$E$9-$I$9)/(InputDataB_ModelSpecAssumptions!$E$10-InputDataA_GeneralAssumptions!$D$7))
B10: Reach target I/Y rate by year --> | C10: (YYYY) | D10: 2025 | E10: 2025 | G10: Used in "scenario" simulation | H10: (e.g. 0.40) | I10: =IF(VLOOKUP(InputDataB_ModelSpecAssumptions!$D$8,DataSummary!$A$111:$B$112,2,FALSE())=1,InputDataB_ModelSpecAssumptions!I8,InputDataB_ModelSpecAssumptions!I9) | J10: =IF(VLOOKUP(InputDataB_ModelSpecAssumptions!$D$8,DataSummary!$A$111:$B$112,2,FALSE())=1,InputDataB_ModelSpecAssumptions!J8,InputDataB_ModelSpecAssumptions!J9) | K10: =IF(VLOOKUP(InputDataB_ModelSpecAssumptions!$D$8,DataSummary!$A$111:$B$112,2,FALSE())=1,InputDataB_ModelSpecAssumptions!K8,InputDataB_ModelSpecAssumptions!K9) | L10: =IF(VLOOKUP(InputDataB_ModelSpecAssumptions!$D$8,DataSummary!$A$111:$B$112,2,FALSE())=1,InputDataB_ModelSpecAssumptions!L8,InputDataB_ModelSpecAssumptions!L9) | M10: =IF(VLOOKUP(InputDataB_ModelSpecAssumptions!$D$8,DataSummary!$A$111:$B$112,2,FALSE())=1,InputDataB_ModelSpecAssumptions!M8,InputDataB_ModelSpecAssumptions!M9) | N10: =IF(VLOOKUP(InputDataB_ModelSpecAssumptions!$D$8,DataSummary!$A$111:$B$112,2,FALSE())=1,InputDataB_ModelSpecAssumptions!N8,InputDataB_ModelSpecAssumptions!N9) | O10: =IF(VLOOKUP(InputDataB_ModelSpecAssumptions!$D$8,DataSummary!$A$111:$B$112,2,FALSE())=1,InputDataB_ModelSpecAssumptions!O8,InputDataB_ModelSpecAssumptions!O9) | P10: =IF(VLOOKUP(InputDataB_ModelSpecAssumptions!$D$8,DataSummary!$A$111:$B$112,2,FALSE())=1,InputDataB_ModelSpecAssumptions!P8,InputDataB_ModelSpecAssumptions!P9) | ... BW10: =IF(VLOOKUP(InputDataB_ModelSpecAssumptions!$D$8,DataSummary!$A$111:$B$112,2,FALSE())=1,InputDataB_ModelSpecAssumptions!BW8,InputDataB_ModelSpecAssumptions!BW9)
B12: Model 2: Calculating Investment Ratio to Achieve Output Target | F12: =D21 | G12: =VLOOKUP(InputDataB_ModelSpecAssumptions!D20,DataSummary!A122:C125,3,FALSE()) | H12: Chart | I12: =InputDataA_GeneralAssumptions!$D$7 | J12: =I12+1 | K12: =J12+1 | L12: =K12+1 | M12: =L12+1 | N12: =M12+1 | O12: =N12+1 | P12: =O12+1 | Q12: =P12+1 | ... BW12: =BV12+1
B13: Initial Value of user defined Output Target --> | C13: =C22 | F13: =DataSummary!N4 | G13: "Manual" [user defined year by year] | H13: (e.g. 0.40) | I13: =I14 | J13: =I13 | K13: =J13 | L13: =K13 | M13: =L13 | N13: =M13 | O13: =N13 | P13: =O13 | Q13: =P13 | ... BW13: =BV13
B14: ="Pre-loaded initial value of user-defined Output Target from:" | C14: WDI | D14: =DataSummary!E134 | G14: "Automatic" [reach target by year] | H14: =H13 | I14: =D15 | J14: =IF(VLOOKUP(InputDataB_ModelSpecAssumptions!$D$20,DataSummary!$A$122:$B$125,2,FALSE())=3,J17,IF(J12>=InputDataB_ModelSpecAssumptions!$D$23,InputDataB_ModelSpecAssumptions!$D$22,I14+(InputDataB_ModelSpecAssumptions!$D$22-$I$14)/(InputDataB_ModelSpecAssumptions!$D$23-InputDataA_GeneralAssumptions!$D$7))) | K14: =IF(VLOOKUP(InputDataB_ModelSpecAssumptions!$D$20,DataSummary!$A$122:$B$125,2,FALSE())=3,K17,IF(K12>=InputDataB_ModelSpecAssumptions!$D$23,InputDataB_ModelSpecAssumptions!$D$22,J14+(InputDataB_ModelSpecAssumptions!$D$22-$I$14)/(InputDataB_ModelSpecAssumptions!$D$23-InputDataA_GeneralAssumptions!$D$7))) | L14: =IF(VLOOKUP(InputDataB_ModelSpecAssumptions!$D$20,DataSummary!$A$122:$B$125,2,FALSE())=3,L17,IF(L12>=InputDataB_ModelSpecAssumptions!$D$23,InputDataB_ModelSpecAssumptions!$D$22,K14+(InputDataB_ModelSpecAssumptions!$D$22-$I$14)/(InputDataB_ModelSpecAssumptions!$D$23-InputDataA_GeneralAssumptions!$D$7))) | M14: =IF(VLOOKUP(InputDataB_ModelSpecAssumptions!$D$20,DataSummary!$A$122:$B$125,2,FALSE())=3,M17,IF(M12>=InputDataB_ModelSpecAssumptions!$D$23,InputDataB_ModelSpecAssumptions!$D$22,L14+(InputDataB_ModelSpecAssumptions!$D$22-$I$14)/(InputDataB_ModelSpecAssumptions!$D$23-InputDataA_GeneralAssumptions!$D$7))) | N14: =IF(VLOOKUP(InputDataB_ModelSpecAssumptions!$D$20,DataSummary!$A$122:$B$125,2,FALSE())=3,N17,IF(N12>=InputDataB_ModelSpecAssumptions!$D$23,InputDataB_ModelSpecAssumptions!$D$22,M14+(InputDataB_ModelSpecAssumptions!$D$22-$I$14)/(InputDataB_ModelSpecAssumptions!$D$23-InputDataA_GeneralAssumptions!$D$7))) | O14: =IF(VLOOKUP(InputDataB_ModelSpecAssumptions!$D$20,DataSummary!$A$122:$B$125,2,FALSE())=3,O17,IF(O12>=InputDataB_ModelSpecAssumptions!$D$23,InputDataB_ModelSpecAssumptions!$D$22,N14+(InputDataB_ModelSpecAssumptions!$D$22-$I$14)/(InputDataB_ModelSpecAssumptions!$D$23-InputDataA_GeneralAssumptions!$D$7))) | P14: =IF(VLOOKUP(InputDataB_ModelSpecAssumptions!$D$20,DataSummary!$A$122:$B$125,2,FALSE())=3,P17,IF(P12>=InputDataB_ModelSpecAssumptions!$D$23,InputDataB_ModelSpecAssumptions!$D$22,O14+(InputDataB_ModelSpecAssumptions!$D$22-$I$14)/(InputDataB_ModelSpecAssumptions!$D$23-InputDataA_GeneralAssumptions!$D$7))) | Q14: =IF(VLOOKUP(InputDataB_ModelSpecAssumptions!$D$20,DataSummary!$A$122:$B$125,2,FALSE())=3,Q17,IF(Q12>=InputDataB_ModelSpecAssumptions!$D$23,InputDataB_ModelSpecAssumptions!$D$22,P14+(InputDataB_ModelSpecAssumptions!$D$22-$I$14)/(InputDataB_ModelSpecAssumptions!$D$23-InputDataA_GeneralAssumptions!$D$7))) | ... BW14: =IF(VLOOKUP(InputDataB_ModelSpecAssumptions!$D$20,DataSummary!$A$122:$B$125,2,FALSE())=3,BW17,IF(BW12>=InputDataB_ModelSpecAssumptions!$D$23,InputDataB_ModelSpecAssumptions!$D$22,BV14+(InputDataB_ModelSpecAssumptions!$D$22-$I$14)/(InputDataB_ModelSpecAssumptions!$D$23-InputDataA_GeneralAssumptions!$D$7)))
B15: Initial is (if cell D13:E13 -yellow- is blank uses pre-loaded)--> | C15: =IF(DataSummary!B133=1,"(e.g. 0.01)",IF(DataSummary!B133=2,"(e.g. 0.01)","Real US$")) | D15: =IF(ISBLANK(D13)=TRUE(),D14,D13) | E15: =IF(ISBLANK(E13)=TRUE(),D14,E13) | G15: Used in "baseline" simulation | H15: (e.g. 0.40) | I15: =IF(VLOOKUP(InputDataB_ModelSpecAssumptions!$D$21,DataSummary!$A$111:$B$112,2,FALSE())=1,InputDataB_ModelSpecAssumptions!I13,InputDataB_ModelSpecAssumptions!I14) | J15: =IF(VLOOKUP(InputDataB_ModelSpecAssumptions!$D$21,DataSummary!$A$111:$B$112,2,FALSE())=1,InputDataB_ModelSpecAssumptions!J13,InputDataB_ModelSpecAssumptions!J14) | K15: =IF(VLOOKUP(InputDataB_ModelSpecAssumptions!$D$21,DataSummary!$A$111:$B$112,2,FALSE())=1,InputDataB_ModelSpecAssumptions!K13,InputDataB_ModelSpecAssumptions!K14) | L15: =IF(VLOOKUP(InputDataB_ModelSpecAssumptions!$D$21,DataSummary!$A$111:$B$112,2,FALSE())=1,InputDataB_ModelSpecAssumptions!L13,InputDataB_ModelSpecAssumptions!L14) | M15: =IF(VLOOKUP(InputDataB_ModelSpecAssumptions!$D$21,DataSummary!$A$111:$B$112,2,FALSE())=1,InputDataB_ModelSpecAssumptions!M13,InputDataB_ModelSpecAssumptions!M14) | N15: =IF(VLOOKUP(InputDataB_ModelSpecAssumptions!$D$21,DataSummary!$A$111:$B$112,2,FALSE())=1,InputDataB_ModelSpecAssumptions!N13,InputDataB_ModelSpecAssumptions!N14) | O15: =IF(VLOOKUP(InputDataB_ModelSpecAssumptions!$D$21,DataSummary!$A$111:$B$112,2,FALSE())=1,InputDataB_ModelSpecAssumptions!O13,InputDataB_ModelSpecAssumptions!O14) | P15: =IF(VLOOKUP(InputDataB_ModelSpecAssumptions!$D$21,DataSummary!$A$111:$B$112,2,FALSE())=1,InputDataB_ModelSpecAssumptions!P13,InputDataB_ModelSpecAssumptions!P14) | ... BW15: =IF(VLOOKUP(InputDataB_ModelSpecAssumptions!$D$21,DataSummary!$A$111:$B$112,2,FALSE())=1,InputDataB_ModelSpecAssumptions!BW13,InputDataB_ModelSpecAssumptions!BW14)
B16: Growth rate average (historical or target)* | C16: 15yr avg | D16: =(InputDataB_ModelSpecAssumptions!D22/InputDataB_ModelSpecAssumptions!D15)^(1/(InputDataB_ModelSpecAssumptions!D23-InputDataA_GeneralAssumptions!D7))-1 | E16: =(InputDataB_ModelSpecAssumptions!E22/InputDataB_ModelSpecAssumptions!E15)^(1/(InputDataB_ModelSpecAssumptions!E23-InputDataA_GeneralAssumptions!D7))-1
I17: =InputDataB_ModelSpecAssumptions!D15 | J17: =IF(J12>=InputDataB_ModelSpecAssumptions!$D$23,InputDataB_ModelSpecAssumptions!$D$22,I14*(1+$D$16)) | K17: =IF(K12>=InputDataB_ModelSpecAssumptions!$D$23,InputDataB_ModelSpecAssumptions!$D$22,J14*(1+$D$16)) | L17: =IF(L12>=InputDataB_ModelSpecAssumptions!$D$23,InputDataB_ModelSpecAssumptions!$D$22,K14*(1+$D$16)) | M17: =IF(M12>=InputDataB_ModelSpecAssumptions!$D$23,InputDataB_ModelSpecAssumptions!$D$22,L14*(1+$D$16)) | N17: =IF(N12>=InputDataB_ModelSpecAssumptions!$D$23,InputDataB_ModelSpecAssumptions!$D$22,M14*(1+$D$16)) | O17: =IF(O12>=InputDataB_ModelSpecAssumptions!$D$23,InputDataB_ModelSpecAssumptions!$D$22,N14*(1+$D$16)) | P17: =IF(P12>=InputDataB_ModelSpecAssumptions!$D$23,InputDataB_ModelSpecAssumptions!$D$22,O14*(1+$D$16)) | Q17: =IF(Q12>=InputDataB_ModelSpecAssumptions!$D$23,InputDataB_ModelSpecAssumptions!$D$22,P14*(1+$D$16)) | ... BW17: =IF(BW12>=InputDataB_ModelSpecAssumptions!$D$23,InputDataB_ModelSpecAssumptions!$D$22,BV14*(1+$D$16))
I18: =InputDataB_ModelSpecAssumptions!E15 | J18: =IF(J12>=InputDataB_ModelSpecAssumptions!$E$23,InputDataB_ModelSpecAssumptions!$E$22,I20*(1+$E$16)) | K18: =IF(K12>=InputDataB_ModelSpecAssumptions!$E$23,InputDataB_ModelSpecAssumptions!$E$22,J20*(1+$E$16)) | L18: =IF(L12>=InputDataB_ModelSpecAssumptions!$E$23,InputDataB_ModelSpecAssumptions!$E$22,K20*(1+$E$16)) | M18: =IF(M12>=InputDataB_ModelSpecAssumptions!$E$23,InputDataB_ModelSpecAssumptions!$E$22,L20*(1+$E$16)) | N18: =IF(N12>=InputDataB_ModelSpecAssumptions!$E$23,InputDataB_ModelSpecAssumptions!$E$22,M20*(1+$E$16)) | O18: =IF(O12>=InputDataB_ModelSpecAssumptions!$E$23,InputDataB_ModelSpecAssumptions!$E$22,N20*(1+$E$16)) | P18: =IF(P12>=InputDataB_ModelSpecAssumptions!$E$23,InputDataB_ModelSpecAssumptions!$E$22,O20*(1+$E$16)) | Q18: =IF(Q12>=InputDataB_ModelSpecAssumptions!$E$23,InputDataB_ModelSpecAssumptions!$E$22,P20*(1+$E$16)) | ... BW18: =IF(BW12>=InputDataB_ModelSpecAssumptions!$E$23,InputDataB_ModelSpecAssumptions!$E$22,BV20*(1+$E$16))
B19: *Only applies to growth rates, not GDP PC levels | C19: ="Most recent year is "&DataSummary!Q129 | D19: =VLOOKUP(D20,DataSummary!A122:C125,3,FALSE()) | F19: =DataSummary!N5 | G19: "Manual" [user defined year by year] | H19: (e.g. 0.40) | I19: =I20 | J19: =I19 | K19: =J19 | L19: =K19 | M19: =L19 | N19: =M19 | O19: =N19 | P19: =O19 | Q19: =P19 | ... BW19: =BV19
B20: ="Select Output Target Variable, period "&InputDataA_GeneralAssumptions!D7&"-"&InputDataA_GeneralAssumptions!D8&":" | C20: Select from list --> | D20: GDP Growth | G20: "Automatic" [reach target by year] | H20: (e.g. 0.40) | I20: =E15 | J20: =IF(VLOOKUP(InputDataB_ModelSpecAssumptions!$D$20,DataSummary!$A$122:$B$125,2,FALSE())=3,J18,IF(J12>=InputDataB_ModelSpecAssumptions!$E$23,InputDataB_ModelSpecAssumptions!$E$22,I20+(InputDataB_ModelSpecAssumptions!$E$22-$I$20)/(InputDataB_ModelSpecAssumptions!$E$23-InputDataA_GeneralAssumptions!$D$7))) | K20: =IF(VLOOKUP(InputDataB_ModelSpecAssumptions!$D$20,DataSummary!$A$122:$B$125,2,FALSE())=3,K18,IF(K12>=InputDataB_ModelSpecAssumptions!$E$23,InputDataB_ModelSpecAssumptions!$E$22,J20+(InputDataB_ModelSpecAssumptions!$E$22-$I$20)/(InputDataB_ModelSpecAssumptions!$E$23-InputDataA_GeneralAssumptions!$D$7))) | L20: =IF(VLOOKUP(InputDataB_ModelSpecAssumptions!$D$20,DataSummary!$A$122:$B$125,2,FALSE())=3,L18,IF(L12>=InputDataB_ModelSpecAssumptions!$E$23,InputDataB_ModelSpecAssumptions!$E$22,K20+(InputDataB_ModelSpecAssumptions!$E$22-$I$20)/(InputDataB_ModelSpecAssumptions!$E$23-InputDataA_GeneralAssumptions!$D$7))) | M20: =IF(VLOOKUP(InputDataB_ModelSpecAssumptions!$D$20,DataSummary!$A$122:$B$125,2,FALSE())=3,M18,IF(M12>=InputDataB_ModelSpecAssumptions!$E$23,InputDataB_ModelSpecAssumptions!$E$22,L20+(InputDataB_ModelSpecAssumptions!$E$22-$I$20)/(InputDataB_ModelSpecAssumptions!$E$23-InputDataA_GeneralAssumptions!$D$7))) | N20: =IF(VLOOKUP(InputDataB_ModelSpecAssumptions!$D$20,DataSummary!$A$122:$B$125,2,FALSE())=3,N18,IF(N12>=InputDataB_ModelSpecAssumptions!$E$23,InputDataB_ModelSpecAssumptions!$E$22,M20+(InputDataB_ModelSpecAssumptions!$E$22-$I$20)/(InputDataB_ModelSpecAssumptions!$E$23-InputDataA_GeneralAssumptions!$D$7))) | O20: =IF(VLOOKUP(InputDataB_ModelSpecAssumptions!$D$20,DataSummary!$A$122:$B$125,2,FALSE())=3,O18,IF(O12>=InputDataB_ModelSpecAssumptions!$E$23,InputDataB_ModelSpecAssumptions!$E$22,N20+(InputDataB_ModelSpecAssumptions!$E$22-$I$20)/(InputDataB_ModelSpecAssumptions!$E$23-InputDataA_GeneralAssumptions!$D$7))) | P20: =IF(VLOOKUP(InputDataB_ModelSpecAssumptions!$D$20,DataSummary!$A$122:$B$125,2,FALSE())=3,P18,IF(P12>=InputDataB_ModelSpecAssumptions!$E$23,InputDataB_ModelSpecAssumptions!$E$22,O20+(InputDataB_ModelSpecAssumptions!$E$22-$I$20)/(InputDataB_ModelSpecAssumptions!$E$23-InputDataA_GeneralAssumptions!$D$7))) | Q20: =IF(VLOOKUP(InputDataB_ModelSpecAssumptions!$D$20,DataSummary!$A$122:$B$125,2,FALSE())=3,Q18,IF(Q12>=InputDataB_ModelSpecAssumptions!$E$23,InputDataB_ModelSpecAssumptions!$E$22,P20+(InputDataB_ModelSpecAssumptions!$E$22-$I$20)/(InputDataB_ModelSpecAssumptions!$E$23-InputDataA_GeneralAssumptions!$D$7))) | ... BW20: =IF(VLOOKUP(InputDataB_ModelSpecAssumptions!$D$20,DataSummary!$A$122:$B$125,2,FALSE())=3,BW18,IF(BW12>=InputDataB_ModelSpecAssumptions!$E$23,InputDataB_ModelSpecAssumptions!$E$22,BV20+(InputDataB_ModelSpecAssumptions!$E$22-$I$20)/(InputDataB_ModelSpecAssumptions!$E$23-InputDataA_GeneralAssumptions!$D$7)))
